Workbook
Name \4: #REF!
Name \4: #REF!
Name \6: #REF!
Name \6: #REF!
Name \A: #REF!
Name \A: #REF!
Name \E: #REF!
Name \I: #REF!
Name \M: #REF!
Name \N: #REF!
Name \O: #REF!
Name \U: #REF!
Name __DAT1: #REF!
Name __DAT10: #REF!
Name __DAT11: #REF!
Name __DAT12: #REF!
Name __DAT13: #REF!
Name __DAT14: #REF!
Name __DAT2: #REF!
Name __DAT3: #REF!
Name __DAT4: #REF!
Name __DAT5: #REF!
Name __DAT6: #REF!
Name __DAT7: #REF!
Name __DAT8: #REF!
Name __DAT9: #REF!
Name _DAT1: #REF!
Name _DAT10: #REF!
Name _DAT11: #REF!
Name _DAT12: #REF!
Name _DAT13: #REF!
Name _DAT14: #REF!
Name _DAT15: #REF!
Name _DAT16: #REF!
Name _DAT17: #REF!
Name _DAT18: #REF!
Name _DAT19: #REF!
Name _DAT2: #REF!
Name _DAT20: #REF!
Name _DAT21: #REF!
Name _DAT3: #REF!
Name _DAT4: #REF!
Name _DAT5: #REF!
Name _DAT6: #REF!
Name _DAT7: #REF!
Name _DAT8: #REF!
Name _DAT9: #REF!
Name ACERO: #REF!
Name ACERO: #REF!
Name adegas: [2]PP!#REF!
Name adegpressão: [2]PP!#REF!
Name AGUA: #REF!
Name AGUA: #REF!
Name ALAMBRE: #REF!
Name ana_bajante_pluvial_3pulg: [3]ANA!$F$536
Name ana_caja_inspeccion: [3]ANA!$F$907
Name ana_codo_pvc_drenaje_2pulgx45: [3]ANA!$F$324
Name ana_codo_pvc_drenaje_3pulgx45: [3]ANA!$F$331
Name ana_codo_pvc_drenaje_4pulgx45: [3]ANA!$F$338
Name ana_codo_pvc_presion_1.5pulg: [3]ANA!$F$275

Sheet Consideraciones 
A3: Conograma de Insumos de Hispanoamerica
A4: Fecha | B4: Detalles
B5: Presupuesto levantando segun plano de Veron
B6: Hispano America No se posee plano
B7: Se considero revestimiento para baños y asistido
B8: Se considero pisos para baños
B9: Se considero 250 mts pisos antideslizante
B10: Generadores electricos de 500 kW 2 unidades
B11: Neveras nuevo lineamiento Arneg
B12: Muebles IMS nuevo modelos
B13: Bomper igual a las americas
B14: Se considero UN horno Rational
B15: Monto de la gondola, tomado de la Forteza segun MC05
B16: Visual M esta evauando los maniqui (puede que cambie el monto)
B17: Bomba contra incendio considerada de 1,500 vertical

Sheet Plan OI
C1: Presupuesto Detallado - Propuesta para Sirena Compacta Hispanoamerica
C2: Area de Compras de Activos
C4: Fecha Version: | D4: Alto Nivel | E4: Alto Nivel Rev III | I4: Plan Detallado DOP | L4: Plan Detallado USD
D5: Total Presupuesto [USD] | E5: Total Presupuesto [USD] | G5: Ppto OI [DOP] | H5: Ppto Capex [DOP] | I5: Total Iniciativa [DOP] | J5: Ppto OI [USD] | K5: Ppto Capex [USD] | L5: Total Iniciativa [USD]
C6: TOTAL GENERAL ESTIMADO | D6: =D9+D10+D11 -> 3179486.8 | E6: =E9+E10+E11 -> 2530056.7 | G6: =SUM(G9:G11) -> 2.1075093e+08 | H6: =SUM(H9:H11) -> 0 | I6: =H6+G6 -> 2.1075093e+08 | J6: =SUM(J9:J11) -> 3472008.8 | K6: =SUM(K9:K11) -> 0 | L6: =K6+J6 -> 3472008.8
C8: Resumen de Partidas
C9: EQUIPAMIENTO | D9: =SUMIF(PPto[Gran Part.],$C9,PPto[Total '[USD']]) -> 2901152.5 | E9: =SUMIF(PPto[Gran Part.],$C9,PPto[Total '[USD']3]) -> 2391748.5 | G9: =SUMIF(PPto[Gran Part.],$C9,PPto[Ppto. OI '[DOP']2]) -> 1.9535958e+08 | H9: =SUMIF(PPto[Gran Part.],$C9,PPto[Ppto. Capex '[DOP']]) -> 0 | I9: =SUMIF(PPto[Gran Part.],$C9,PPto[Total '[DOP']]) -> 1.9535958e+08 | J9: =SUMIF(PPto[Gran Part.],C9,PPto[Ppto. OI '[USD']]) -> 3218444.5 | K9: =SUMIF(PPto[Gran Part.],C9,PPto[Ppto. Capex '[USD']]) -> 0 | L9: =K9+J9 -> 3218444.5
C10: EDIFICACIÓN | D10: =SUMIF(PPto[Gran Part.],$C10,PPto[Total '[USD']]) -> 278334.38 | E10: =SUMIF(PPto[Gran Part.],$C10,PPto[Total '[USD']3]) -> 138308.14 | G10: =SUMIF(PPto[Gran Part.],$C10,PPto[Ppto. OI '[DOP']2]) -> 15391355 | H10: =SUMIF(PPto[Gran Part.],$C10,PPto[Ppto. Capex '[DOP']]) -> 0 | I10: =SUMIF(PPto[Gran Part.],$C10,PPto[Total '[DOP']]) -> 15391355 | J10: =SUMIF(PPto[Gran Part.],C10,PPto[Ppto. OI '[USD']]) -> 253564.32 | K10: =SUMIF(PPto[Gran Part.],C10,PPto[Ppto. Capex '[USD']]) -> 0 | L10: =K10+J10 -> 253564.32
C11: TERRENO | D11: 0 | E11: 0 | G11: =SUMIF(PPto[Gran Part.],$C11,PPto[Ppto. OI '[DOP']2]) -> 0 | H11: =SUMIF(PPto[Gran Part.],$C11,PPto[Ppto. Capex '[DOP']]) -> 0 | I11: =H11+G11 -> 0 | J11: =SUMIF(PPto[Gran Part.],C11,PPto[Ppto. OI '[USD']]) -> 0 | K11: =SUMIF(PPto[Gran Part.],C11,PPto[Ppto. Capex '[USD']]) -> 0 | L11: =K11+J11 -> 0
C12: Gasto | D12: 0 | E12: 0 | G12: =SUMIF(PPto[Gran Part.],$C12,PPto[Ppto. OI '[DOP']2]) -> 0 | H12: =SUMIF(PPto[Gran Part.],$C12,PPto[Ppto. Capex '[DOP']]) -> 0 | I12: =H12+G12 -> 0 | J12: =SUMIF(PPto[Gran Part.],C12,PPto[Ppto. OI '[USD']]) -> 0 | K12: =SUMIF(PPto[Gran Part.],C12,PPto[Ppto. Capex '[USD']]) -> 0 | L12: =K12+J12 -> 0 | P12: 753760
C14: Área de la Localidad | P14: 85000
C15: M² Construcción | P15: =+P12+P14 -> 838760
C16: M² Sala de Ventas
C17: M² Terreno
G18: OI | H18: Capex | J18: OI | K18: Capex
A19: Part. | B19: Gran Part. | C19: Edificación, Instalaciones y Equipamientos | D19: Total [USD] | E19: Total [USD]3 | F19: Columna2 | G19: Ppto. OI [DOP]2 | H19: Ppto. Capex [DOP] | I19: Total [DOP] | J19: Ppto. OI [USD] | K19: Ppto. Capex [USD] | L19: Total [USD]2 | M19: Total [USD]22
A20: 1 | C20: 1.00 Estudios Preliminares | D20: =SUM(D21:D27) -> 0 | E20: =SUM(E21:E27) -> 0 | G20: =SUM(G21:G29) -> 0 | H20: =SUM(H21:H29) -> 0 | I20: =PPto[[#This Row],[Ppto. Capex '[DOP']]]+PPto[[#This Row],[Ppto. OI '[DOP']2]] -> 0 | J20: =SUM(J21:J29) -> 0 | K20: =SUM(K21:K29) -> 0 | L20: =PPto[[#This Row],[Ppto. Capex '[USD']]]+PPto[[#This Row],[Ppto. OI '[USD']]] -> 0
A21: 1.01 | B21: Edificación | C21: 1.01 Diseño arquitectónico | D21: 0 | E21: 0 | G21: =SUMIFS(BD.PD[Ppto. Orden Interna '[DOP']],BD.PD[Pos],PPto[[#This Row],[Part.]],BD.PD[Tipo Ppto],G$18) -> 0 | H21: =SUMIFS(BD.PD[Ppto. Orden Interna '[DOP']],BD.PD[Pos],PPto[[#This Row],[Part.]],BD.PD[Tipo Ppto],H$18) -> 0 | I21: =PPto[[#This Row],[Ppto. Capex '[DOP']]]+PPto[[#This Row],[Ppto. OI '[DOP']2]] -> 0 | J21: =SUMIFS(BD.PD[Ppto. Orden Interna '[USD']],BD.PD[Pos],PPto[[#This Row],[Part.]],BD.PD[Tipo Ppto],J$18) -> 0 | K21: =SUMIFS(BD.PD[Ppto. Orden Interna '[USD']],BD.PD[Pos],PPto[[#This Row],[Part.]],BD.PD[Tipo Ppto],K$18) -> 0 | L21: =PPto[[#This Row],[Ppto. Capex '[USD']]]+PPto[[#This Row],[Ppto. OI '[USD']]] -> 0
A22: 1.02 | B22: Edificación | C22: 1.02 Diseño estructural | D22: 0 | E22: 0 | G22: =SUMIFS(BD.PD[Ppto. Orden Interna '[DOP']],BD.PD[Pos],PPto[[#This Row],[Part.]],BD.PD[Tipo Ppto],G$18) -> 0 | H22: =SUMIFS(BD.PD[Ppto. Orden Interna '[DOP']],BD.PD[Pos],PPto[[#This Row],[Part.]],BD.PD[Tipo Ppto],H$18) -> 0 | I22: =PPto[[#This Row],[Ppto. Capex '[DOP']]]+PPto[[#This Row],[Ppto. OI '[DOP']2]] -> 0 | J22: =SUMIFS(BD.PD[Ppto. Orden Interna '[USD']],BD.PD[Pos],PPto[[#This Row],[Part.]],BD.PD[Tipo Ppto],J$18) -> 0 | K22: =SUMIFS(BD.PD[Ppto. Orden Interna '[USD']],BD.PD[Pos],PPto[[#This Row],[Part.]],BD.PD[Tipo Ppto],K$18) -> 0 | L22: =PPto[[#This Row],[Ppto. Capex '[USD']]]+PPto[[#This Row],[Ppto. OI '[USD']]] -> 0
A23: 1.03 | B23: Edificación | C23: 1.03 Diseño electromecánico | D23: 0 | E23: 0 | G23: =SUMIFS(BD.PD[Ppto. Orden Interna '[DOP']],BD.PD[Pos],PPto[[#This Row],[Part.]],BD.PD[Tipo Ppto],G$18) -> 0 | H23: =SUMIFS(BD.PD[Ppto. Orden Interna '[DOP']],BD.PD[Pos],PPto[[#This Row],[Part.]],BD.PD[Tipo Ppto],H$18) -> 0 | I23: =PPto[[#This Row],[Ppto. Capex '[DOP']]]+PPto[[#This Row],[Ppto. OI '[DOP']2]] -> 0 | J23: =SUMIFS(BD.PD[Ppto. Orden Interna '[USD']],BD.PD[Pos],PPto[[#This Row],[Part.]],BD.PD[Tipo Ppto],J$18) -> 0 | K23: =SUMIFS(BD.PD[Ppto. Orden Interna '[USD']],BD.PD[Pos],PPto[[#This Row],[Part.]],BD.PD[Tipo Ppto],K$18) -> 0 | L23: =PPto[[#This Row],[Ppto. Capex '[USD']]]+PPto[[#This Row],[Ppto. OI '[USD']]] -> 0
A24: 1.04 | B24: Edificación | C24: 1.04 Diseño sanitario | D24: 0 | E24: 0 | G24: =SUMIFS(BD.PD[Ppto. Orden Interna '[DOP']],BD.PD[Pos],PPto[[#This Row],[Part.]],BD.PD[Tipo Ppto],G$18) -> 0 | H24: =SUMIFS(BD.PD[Ppto. Orden Interna '[DOP']],BD.PD[Pos],PPto[[#This Row],[Part.]],BD.PD[Tipo Ppto],H$18) -> 0 | I24: =PPto[[#This Row],[Ppto. Capex '[DOP']]]+PPto[[#This Row],[Ppto. OI '[DOP']2]] -> 0 | J24: =SUMIFS(BD.PD[Ppto. Orden Interna '[USD']],BD.PD[Pos],PPto[[#This Row],[Part.]],BD.PD[Tipo Ppto],J$18) -> 0 | K24: =SUMIFS(BD.PD[Ppto. Orden Interna '[USD']],BD.PD[Pos],PPto[[#This Row],[Part.]],BD.PD[Tipo Ppto],K$18) -> 0 | L24: =PPto[[#This Row],[Ppto. Capex '[USD']]]+PPto[[#This Row],[Ppto. OI '[USD']]] -> 0
A25: 1.05 | B25: Edificación | C25: 1.05 Estudio Geotécnico | D25: 0 | E25: 0 | G25: =SUMIFS(BD.PD[Ppto. Orden Interna '[DOP']],BD.PD[Pos],PPto[[#This Row],[Part.]],BD.PD[Tipo Ppto],G$18) -> 0 | H25: =SUMIFS(BD.PD[Ppto. Orden Interna '[DOP']],BD.PD[Pos],PPto[[#This Row],[Part.]],BD.PD[Tipo Ppto],H$18) -> 0 | I25: =PPto[[#This Row],[Ppto. Capex '[DOP']]]+PPto[[#This Row],[Ppto. OI '[DOP']2]] -> 0 | J25: =SUMIFS(BD.PD[Ppto. Orden Interna '[USD']],BD.PD[Pos],PPto[[#This Row],[Part.]],BD.PD[Tipo Ppto],J$18) -> 0 | K25: =SUMIFS(BD.PD[Ppto. Orden Interna '[USD']],BD.PD[Pos],PPto[[#This Row],[Part.]],BD.PD[Tipo Ppto],K$18) -> 0 | L25: =PPto[[#This Row],[Ppto. Capex '[USD']]]+PPto[[#This Row],[Ppto. OI '[USD']]] -> 0
A26: 1.06 | B26: Edificación | C26: 1.06 Levantamiento topográfico | D26: 0 | E26: 0 | G26: =SUMIFS(BD.PD[Ppto. Orden Interna '[DOP']],BD.PD[Pos],PPto[[#This Row],[Part.]],BD.PD[Tipo Ppto],G$18) -> 0 | H26: =SUMIFS(BD.PD[Ppto. Orden Interna '[DOP']],BD.PD[Pos],PPto[[#This Row],[Part.]],BD.PD[Tipo Ppto],H$18) -> 0 | I26: =PPto[[#This Row],[Ppto. Capex '[DOP']]]+PPto[[#This Row],[Ppto. OI '[DOP']2]] -> 0 | J26: =SUMIFS(BD.PD[Ppto. Orden Interna '[USD']],BD.PD[Pos],PPto[[#This Row],[Part.]],BD.PD[Tipo Ppto],J$18) -> 0 | K26: =SUMIFS(BD.PD[Ppto. Orden Interna '[USD']],BD.PD[Pos],PPto[[#This Row],[Part.]],BD.PD[Tipo Ppto],K$18) -> 0 | L26: =PPto[[#This Row],[Ppto. Capex '[USD']]]+PPto[[#This Row],[Ppto. OI '[USD']]] -> 0
A27: 1.07 | B27: Edificación | C27: 1.07 Permisos | D27: 0 | E27: 0 | G27: =SUMIFS(BD.PD[Ppto. Orden Interna '[DOP']],BD.PD[Pos],PPto[[#This Row],[Part.]],BD.PD[Tipo Ppto],G$18) -> 0 | H27: =SUMIFS(BD.PD[Ppto. Orden Interna '[DOP']],BD.PD[Pos],PPto[[#This Row],[Part.]],BD.PD[Tipo Ppto],H$18) -> 0 | I27: =PPto[[#This Row],[Ppto. Capex '[DOP']]]+PPto[[#This Row],[Ppto. OI '[DOP']2]] -> 0 | J27: =SUMIFS(BD.PD[Ppto. Orden Interna '[USD']],BD.PD[Pos],PPto[[#This Row],[Part.]],BD.PD[Tipo Ppto],J$18) -> 0 | K27: =SUMIFS(BD.PD[Ppto. Orden Interna '[USD']],BD.PD[Pos],PPto[[#This Row],[Part.]],BD.PD[Tipo Ppto],K$18) -> 0 | L27: =PPto[[#This Row],[Ppto. Capex '[USD']]]+PPto[[#This Row],[Ppto. OI '[USD']]] -> 0
A28: 1.08 | B28: Edificación | C28: 1.08 Diseño sistema contra incendios | D28: 0 | E28: 0 | G28: =SUMIFS(BD.PD[Ppto. Orden Interna '[DOP']],BD.PD[Pos],PPto[[#This Row],[Part.]],BD.PD[Tipo Ppto],G$18) -> 0 | H28: =SUMIFS(BD.PD[Ppto. Orden Interna '[DOP']],BD.PD[Pos],PPto[[#This Row],[Part.]],BD.PD[Tipo Ppto],H$18) -> 0 | I28: =PPto[[#This Row],[Ppto. Capex '[DOP']]]+PPto[[#This Row],[Ppto. OI '[DOP']2]] -> 0 | J28: =SUMIFS(BD.PD[Ppto. Orden Interna '[USD']],BD.PD[Pos],PPto[[#This Row],[Part.]],BD.PD[Tipo Ppto],J$18) -> 0 | K28: =SUMIFS(BD.PD[Ppto. Orden Interna '[USD']],BD.PD[Pos],PPto[[#This Row],[Part.]],BD.PD[Tipo Ppto],K$18) -> 0 | L28: =PPto[[#This Row],[Ppto. Capex '[USD']]]+PPto[[#This Row],[Ppto. OI '[USD']]] -> 0
A29: 1.09 | B29: Edificación | C29: 1.09 Diseño sistema gas | D29: 0 | E29: 0 | G29: =SUMIFS(BD.PD[Ppto. Orden Interna '[DOP']],BD.PD[Pos],PPto[[#This Row],[Part.]],BD.PD[Tipo Ppto],G$18) -> 0 | H29: =SUMIFS(BD.PD[Ppto. Orden Interna '[DOP']],BD.PD[Pos],PPto[[#This Row],[Part.]],BD.PD[Tipo Ppto],H$18) -> 0 | I29: =PPto[[#This Row],[Ppto. Capex '[DOP']]]+PPto[[#This Row],[Ppto. OI '[DOP']2]] -> 0 | J29: =SUMIFS(BD.PD[Ppto. Orden Interna '[USD']],BD.PD[Pos],PPto[[#This Row],[Part.]],BD.PD[Tipo Ppto],J$18) -> 0 | K29: =SUMIFS(BD.PD[Ppto. Orden Interna '[USD']],BD.PD[Pos],PPto[[#This Row],[Part.]],BD.PD[Tipo Ppto],K$18) -> 0 | L29: =PPto[[#This Row],[Ppto. Capex '[USD']]]+PPto[[#This Row],[Ppto. OI '[USD']]] -> 0
A30: 2 | C30: 2.00 Obra Civil | D30: =SUM(D31:D41) -> 278334.38 | E30: =SUM(E31:E41) -> 138308.14 | G30: =SUM(G31:G41) -> 15391355 | H30: =SUM(H31:H41) -> 0 | I30: =PPto[[#This Row],[Ppto. Capex '[DOP']]]+PPto[[#This Row],[Ppto. OI '[DOP']2]] -> 15391355 | J30: =SUM(J31:J41) -> 253564.32 | K30: =SUM(K31:K41) -> 0 | L30: =PPto[[#This Row],[Ppto. Capex '[USD']]]+PPto[[#This Row],[Ppto. OI '[USD']]] -> 253564.32 | M30: Adicionales
A31: 2.01 | B31: Edificación | C31: 2.01 Edificación - Obra Civil | D31: 161119.6 | E31: 8428.7 | G31: =SUMIFS(BD.PD[Ppto. Orden Interna '[DOP']],BD.PD[Pos],PPto[[#This Row],[Part.]],BD.PD[Tipo Ppto],G$18) -> 1073527 | H31: =SUMIFS(BD.PD[Ppto. Orden Interna '[DOP']],BD.PD[Pos],PPto[[#This Row],[Part.]],BD.PD[Tipo Ppto],H$18) -> 0 | I31: =PPto[[#This Row],[Ppto. Capex '[DOP']]]+PPto[[#This Row],[Ppto. OI '[DOP']2]] -> 1073527 | J31: =SUMIFS(BD.PD[Ppto. Orden Interna '[USD']],BD.PD[Pos],PPto[[#This Row],[Part.]],BD.PD[Tipo Ppto],J$18) -> 17685.782 | K31: =SUMIFS(BD.PD[Ppto. Orden Interna '[USD']],BD.PD[Pos],PPto[[#This Row],[Part.]],BD.PD[Tipo Ppto],K$18) -> 0 | L31: =PPto[[#This Row],[Ppto. Capex '[USD']]]+PPto[[#This Row],[Ppto. OI '[USD']]] -> 17685.782
A32: 2.02 | B32: Edificación | C32: 2.02 Edificación - Estructura Metálica | D32: 0 | E32: 0 | G32: =SUMIFS(BD.PD[Ppto. Orden Interna '[DOP']],BD.PD[Pos],PPto[[#This Row],[Part.]],BD.PD[Tipo Ppto],G$18) -> 0 | H32: =SUMIFS(BD.PD[Ppto. Orden Interna '[DOP']],BD.PD[Pos],PPto[[#This Row],[Part.]],BD.PD[Tipo Ppto],H$18) -> 0 | I32: =PPto[[#This Row],[Ppto. Capex '[DOP']]]+PPto[[#This Row],[Ppto. OI '[DOP']2]] -> 0 | J32: =SUMIFS(BD.PD[Ppto. Orden Interna '[USD']],BD.PD[Pos],PPto[[#This Row],[Part.]],BD.PD[Tipo Ppto],J$18) -> 0 | K32: =SUMIFS(BD.PD[Ppto. Orden Interna '[USD']],BD.PD[Pos],PPto[[#This Row],[Part.]],BD.PD[Tipo Ppto],K$18) -> 0 | L32: =PPto[[#This Row],[Ppto. Capex '[USD']]]+PPto[[#This Row],[Ppto. OI '[USD']]] -> 0
A33: 2.03 | B33: Edificación | C33: 2.03 Edificación - Techo S.S. y Cerramientos Multipanel | D33: 0 | E33: 0 | G33: =SUMIFS(BD.PD[Ppto. Orden Interna '[DOP']],BD.PD[Pos],PPto[[#This Row],[Part.]],BD.PD[Tipo Ppto],G$18) -> 0 | H33: =SUMIFS(BD.PD[Ppto. Orden Interna '[DOP']],BD.PD[Pos],PPto[[#This Row],[Part.]],BD.PD[Tipo Ppto],H$18) -> 0 | I33: =PPto[[#This Row],[Ppto. Capex '[DOP']]]+PPto[[#This Row],[Ppto. OI '[DOP']2]] -> 0 | J33: =SUMIFS(BD.PD[Ppto. Orden Interna '[USD']],BD.PD[Pos],PPto[[#This Row],[Part.]],BD.PD[Tipo Ppto],J$18) -> 0 | K33: =SUMIFS(BD.PD[Ppto. Orden Interna '[USD']],BD.PD[Pos],PPto[[#This Row],[Part.]],BD.PD[Tipo Ppto],K$18) -> 0 | L33: =PPto[[#This Row],[Ppto. Capex '[USD']]]+PPto[[#This Row],[Ppto. OI '[USD']]] -> 0
A34: 2.04 | B34: Edificación | C34: 2.04 Edificación - Tragaluces "Skylights" | D34: 0 | E34: 0 | G34: =SUMIFS(BD.PD[Ppto. Orden Interna '[DOP']],BD.PD[Pos],PPto[[#This Row],[Part.]],BD.PD[Tipo Ppto],G$18) -> 0 | H34: =SUMIFS(BD.PD[Ppto. Orden Interna '[DOP']],BD.PD[Pos],PPto[[#This Row],[Part.]],BD.PD[Tipo Ppto],H$18) -> 0 | I34: =PPto[[#This Row],[Ppto. Capex '[DOP']]]+PPto[[#This Row],[Ppto. OI '[DOP']2]] -> 0 | J34: =SUMIFS(BD.PD[Ppto. Orden Interna '[USD']],BD.PD[Pos],PPto[[#This Row],[Part.]],BD.PD[Tipo Ppto],J$18) -> 0 | K34: =SUMIFS(BD.PD[Ppto. Orden Interna '[USD']],BD.PD[Pos],PPto[[#This Row],[Part.]],BD.PD[Tipo Ppto],K$18) -> 0 | L34: =PPto[[#This Row],[Ppto. Capex '[USD']]]+PPto[[#This Row],[Ppto. OI '[USD']]] -> 0
A35: 2.05 | B35: Edificación | C35: 2.05 Instalaciones Sanitarias | D35: 25100 | E35: 24520 | G35: =SUMIFS(BD.PD[Ppto. Orden Interna '[DOP']],BD.PD[Pos],PPto[[#This Row],[Part.]],BD.PD[Tipo Ppto],G$18) -> 1523570 | H35: =SUMIFS(BD.PD[Ppto. Orden Interna '[DOP']],BD.PD[Pos],PPto[[#This Row],[Part.]],BD.PD[Tipo Ppto],H$18) -> 0 | I35: =PPto[[#This Row],[Ppto. Capex '[DOP']]]+PPto[[#This Row],[Ppto. OI '[DOP']2]] -> 1523570 | J35: =SUMIFS(BD.PD[Ppto. Orden Interna '[USD']],BD.PD[Pos],PPto[[#This Row],[Part.]],BD.PD[Tipo Ppto],J$18) -> 25100 | K35: =SUMIFS(BD.PD[Ppto. Orden Interna '[USD']],BD.PD[Pos],PPto[[#This Row],[Part.]],BD.PD[Tipo Ppto],K$18) -> 0 | L35: =PPto[[#This Row],[Ppto. Capex '[USD']]]+PPto[[#This Row],[Ppto. OI '[USD']]] -> 25100
A36: 2.06 | B36: Edificación | C36: 2.06 Instalación de Gas | D36: 0 | E36: 0 | G36: =SUMIFS(BD.PD[Ppto. Orden Interna '[DOP']],BD.PD[Pos],PPto[[#This Row],[Part.]],BD.PD[Tipo Ppto],G$18) -> 454500 | H36: =SUMIFS(BD.PD[Ppto. Orden Interna '[DOP']],BD.PD[Pos],PPto[[#This Row],[Part.]],BD.PD[Tipo Ppto],H$18) -> 0 | I36: =PPto[[#This Row],[Ppto. Capex '[DOP']]]+PPto[[#This Row],[Ppto. OI '[DOP']2]] -> 454500 | J36: =SUMIFS(BD.PD[Ppto. Orden Interna '[USD']],BD.PD[Pos],PPto[[#This Row],[Part.]],BD.PD[Tipo Ppto],J$18) -> 7487.6442 | K36: =SUMIFS(BD.PD[Ppto. Orden Interna '[USD']],BD.PD[Pos],PPto[[#This Row],[Part.]],BD.PD[Tipo Ppto],K$18) -> 0 | L36: =PPto[[#This Row],[Ppto. Capex '[USD']]]+PPto[[#This Row],[Ppto. OI '[USD']]] -> 7487.6442
A37: 2.07 | B37: Edificación | C37: 2.07 Sistema Contra Incendios | D37: 8266.7758 | E37: 6432.69 | G37: =SUMIFS(BD.PD[Ppto. Orden Interna '[DOP']],BD.PD[Pos],PPto[[#This Row],[Part.]],BD.PD[Tipo Ppto],G$18) -> 6105348.6 | H37: =SUMIFS(BD.PD[Ppto. Orden Interna '[DOP']],BD.PD[Pos],PPto[[#This Row],[Part.]],BD.PD[Tipo Ppto],H$18) -> 0 | I37: =PPto[[#This Row],[Ppto. Capex '[DOP']]]+PPto[[#This Row],[Ppto. OI '[DOP']2]] -> 6105348.6 | J37: =SUMIFS(BD.PD[Ppto. Orden Interna '[USD']],BD.PD[Pos],PPto[[#This Row],[Part.]],BD.PD[Tipo Ppto],J$18) -> 100582.35 | K37: =SUMIFS(BD.PD[Ppto. Orden Interna '[USD']],BD.PD[Pos],PPto[[#This Row],[Part.]],BD.PD[Tipo Ppto],K$18) -> 0 | L37: =PPto[[#This Row],[Ppto. Capex '[USD']]]+PPto[[#This Row],[Ppto. OI '[USD']]] -> 100582.35
A38: 2.08 | B38: Edificación | C38: 2.08 Instalaciones Mecánicas | D38: 83848 | E38: 88350 | G38: =SUMIFS(BD.PD[Ppto. Orden Interna '[DOP']],BD.PD[Pos],PPto[[#This Row],[Part.]],BD.PD[Tipo Ppto],G$18) -> 5334408.9 | H38: =SUMIFS(BD.PD[Ppto. Orden Interna '[DOP']],BD.PD[Pos],PPto[[#This Row],[Part.]],BD.PD[Tipo Ppto],H$18) -> 0 | I38: =PPto[[#This Row],[Ppto. Capex '[DOP']]]+PPto[[#This Row],[Ppto. OI '[DOP']2]] -> 5334408.9 | J38: =SUMIFS(BD.PD[Ppto. Orden Interna '[USD']],BD.PD[Pos],PPto[[#This Row],[Part.]],BD.PD[Tipo Ppto],J$18) -> 87881.531 | K38: =SUMIFS(BD.PD[Ppto. Orden Interna '[USD']],BD.PD[Pos],PPto[[#This Row],[Part.]],BD.PD[Tipo Ppto],K$18) -> 0 | L38: =PPto[[#This Row],[Ppto. Capex '[USD']]]+PPto[[#This Row],[Ppto. OI '[USD']]] -> 87881.531
A39: 2.09 | B39: Edificación | C39: 2.09 Rejillas y Sumideros | D39: 0 | E39: 10576.75 | G39: =SUMIFS(BD.PD[Ppto. Orden Interna '[DOP']],BD.PD[Pos],PPto[[#This Row],[Part.]],BD.PD[Tipo Ppto],G$18) -> 900000 | H39: =SUMIFS(BD.PD[Ppto. Orden Interna '[DOP']],BD.PD[Pos],PPto[[#This Row],[Part.]],BD.PD[Tipo Ppto],H$18) -> 0 | I39: =PPto[[#This Row],[Ppto. Capex '[DOP']]]+PPto[[#This Row],[Ppto. OI '[DOP']2]] -> 900000 | J39: =SUMIFS(BD.PD[Ppto. Orden Interna '[USD']],BD.PD[Pos],PPto[[#This Row],[Part.]],BD.PD[Tipo Ppto],J$18) -> 14827.018 | K39: =SUMIFS(BD.PD[Ppto. Orden Interna '[USD']],BD.PD[Pos],PPto[[#This Row],[Part.]],BD.PD[Tipo Ppto],K$18) -> 0 | L39: =PPto[[#This Row],[Ppto. Capex '[USD']]]+PPto[[#This Row],[Ppto. OI '[USD']]] -> 14827.018 | M39: Rejillas y sumideros del nuevo proveedor
A40: 2.1 | B40: Edificación | C40: 2.10 Supervisión Civil y Sanitaria | D40: 0 | E40: 0 | G40: =SUMIFS(BD.PD[Ppto. Orden Interna '[DOP']],BD.PD[Pos],PPto[[#This Row],[Part.]],BD.PD[Tipo Ppto],G$18) -> 0 | H40: =SUMIFS(BD.PD[Ppto. Orden Interna '[DOP']],BD.PD[Pos],PPto[[#This Row],[Part.]],BD.PD[Tipo Ppto],H$18) -> 0 | I40: =PPto[[#This Row],[Ppto. Capex '[DOP']]]+PPto[[#This Row],[Ppto. OI '[DOP']2]] -> 0 | J40: =SUMIFS(BD.PD[Ppto. Orden Interna '[USD']],BD.PD[Pos],PPto[[#This Row],[Part.]],BD.PD[Tipo Ppto],J$18) -> 0 | K40: =SUMIFS(BD.PD[Ppto. Orden Interna '[USD']],BD.PD[Pos],PPto[[#This Row],[Part.]],BD.PD[Tipo Ppto],K$18) -> 0 | L40: =PPto[[#This Row],[Ppto. Capex '[USD']]]+PPto[[#This Row],[Ppto. OI '[USD']]] -> 0
A41: 2.11 | B41: Edificación | C41: 2.11 Supervisión Arquitectónica | D41: 0 | E41: 0 | G41: =SUMIFS(BD.PD[Ppto. Orden Interna '[DOP']],BD.PD[Pos],PPto[[#This Row],[Part.]],BD.PD[Tipo Ppto],G$18) -> 0 | H41: =SUMIFS(BD.PD[Ppto. Orden Interna '[DOP']],BD.PD[Pos],PPto[[#This Row],[Part.]],BD.PD[Tipo Ppto],H$18) -> 0 | I41: =PPto[[#This Row],[Ppto. Capex '[DOP']]]+PPto[[#This Row],[Ppto. OI '[DOP']2]] -> 0 | J41: =SUMIFS(BD.PD[Ppto. Orden Interna '[USD']],BD.PD[Pos],PPto[[#This Row],[Part.]],BD.PD[Tipo Ppto],J$18) -> 0 | K41: =SUMIFS(BD.PD[Ppto. Orden Interna '[USD']],BD.PD[Pos],PPto[[#This Row],[Part.]],BD.PD[Tipo Ppto],K$18) -> 0 | L41: =PPto[[#This Row],[Ppto. Capex '[USD']]]+PPto[[#This Row],[Ppto. OI '[USD']]] -> 0
A42: 3 | C42: 3.00 Sistema Eléctrico | D42: =SUM(D43:D46) -> 146108.56 | E42: =SUM(E43:E46) -> 146562.4 | G42: =SUM(G43:G46) -> 30715852 | H42: =SUM(H43:H46) -> 0 | I42: =PPto[[#This Row],[Ppto. Capex '[DOP']]]+PPto[[#This Row],[Ppto. OI '[DOP']2]] -> 30715852 | J42: =SUM(J43:J46) -> 506027.22 | K42: =SUM(K43:K46) -> 0 | L42: =PPto[[#This Row],[Ppto. Capex '[USD']]]+PPto[[#This Row],[Ppto. OI '[USD']]] -> 506027.22
A43: 3.01 | B43: Equipamiento | C43: 3.01 Instalaciones Eléctricas | D43: 0 | E43: 0 | G43: =SUMIFS(BD.PD[Ppto. Orden Interna '[DOP']],BD.PD[Pos],PPto[[#This Row],[Part.]],BD.PD[Tipo Ppto],G$18) -> 19624310 | H43: =SUMIFS(BD.PD[Ppto. Orden Interna '[DOP']],BD.PD[Pos],PPto[[#This Row],[Part.]],BD.PD[Tipo Ppto],H$18) -> 0 | I43: =PPto[[#This Row],[Ppto. Capex '[DOP']]]+PPto[[#This Row],[Ppto. OI '[DOP']2]] -> 19624310 | J43: =SUMIFS(BD.PD[Ppto. Orden Interna '[USD']],BD.PD[Pos],PPto[[#This Row],[Part.]],BD.PD[Tipo Ppto],J$18) -> 323300 | K43: =SUMIFS(BD.PD[Ppto. Orden Interna '[USD']],BD.PD[Pos],PPto[[#This Row],[Part.]],BD.PD[Tipo Ppto],K$18) -> 0 | L43: =PPto[[#This Row],[Ppto. Capex '[USD']]]+PPto[[#This Row],[Ppto. OI '[USD']]] -> 323300
...

Sheet Flujo de Caja
D1: 1 | E1: 2 | F1: 3 | G1: 4 | H1: 5 | I1: 6 | J1: 7 | K1: 8 | L1: 9 | M1: 10 | N1: 11 | O1: 12 | P1: 13 | Q1: 14 | R1: 15 | S1: 16 | T1: 17 | U1: 18 | V1: 19 | W1: 20 | X1: 21 | Y1: 22 | Z1: 23 | AA1: 24
AB2: Rojo: La sumatoria de pagos no coincide con Ppto.
B3: Apertura Diciembre 2026 | D3: Flujo de Caja Iniciativa
B4: ='Plan OI'!C1 -> Presupuesto Detallado - Propuesta para Sirena Compacta Hispanoamerica | D4: Enero | E4: Febrero | F4: Marzo | G4: Abril | H4: Mayo | I4: Junio | J4: Julio | K4: Agosto | L4: Septiembre | M4: Octubre | N4: Noviembre | O4: Diciembre | P4: Enero | Q4: Febrero | R4: Marzo | S4: Abril | T4: Mayo | U4: Junio | V4: Julio | W4: Agosto | X4: Septiembre | Y4: Octubre | Z4: Noviembre | AA4: Diciembre
A5: Part. | B5: Edificación, Instalaciones y Equipamientos | C5: Ppto OI [DOP] | D5: P1 | E5: P2 | F5: P3 | G5: P4 | H5: P5 | I5: P6 | J5: P7 | K5: P8 | L5: P9 | M5: P10 | N5: P11 | O5: P12 | P5: P13 | Q5: P14 | R5: P15 | S5: P16 | T5: P17 | U5: P18 | V5: P19 | W5: P20 | X5: P21 | Y5: P22 | Z5: P23 | AA5: P24 | AB5: Total Ppto.
A6: 1 | B6: =VLOOKUP(Tabla3[[#This Row],[Part.]],PPto[],3,FALSE) -> 1.00 Estudios Preliminares | C6: =SUM(C7:C15) -> 0 | D6: =SUM(D7:D15) -> 0 | E6: =SUM(E7:E15) -> 0 | F6: =SUM(F7:F15) -> 0 | G6: =SUM(G7:G15) -> 0 | H6: =SUM(H7:H15) -> 0 | I6: =SUM(I7:I15) -> 0 | J6: =SUM(J7:J15) -> 0 | ... AA6: =SUM(AA7:AA15) -> 0 | AB6: =SUM(Tabla3[[#This Row],[P1]:[P24]]) -> 0
A7: 1.01 | B7: =VLOOKUP(Tabla3[[#This Row],[Part.]],PPto[],3,FALSE) -> 1.01 Diseño arquitectónico | C7: =SUMIF(BD.PD[Pos],Tabla3[[#This Row],[Part.]],BD.PD[Ppto. Orden Interna '[DOP']]) -> 0 | D7: =SUMIFS(BD.PD[Pago 1],BD.PD[Per.P1],D$1,BD.PD[Pos],Tabla3[[#This Row],[Part.]])+SUMIFS(BD.PD[Pago 2],BD.PD[Per.P2],D$1,BD.PD[Pos],Tabla3[[#This Row],[Part.]])+SUMIFS(BD.PD[Pago 3],BD.PD[Per.P3],D$1,BD.PD[Pos],Tabla3[[#This Row],[Part.]])+SUMIFS(BD.PD[Pago 4],BD.PD[Per.P4],D$1,BD.PD[Pos],Tabla3[[#This Row],[Part.]])+SUMIFS(BD.PD[Pago 5],BD.PD[Per.P5],D$1,BD.PD[Pos],Tabla3[[#This Row],[Part.]]) -> 0 | E7: =SUMIFS(BD.PD[Pago 1],BD.PD[Per.P1],E$1,BD.PD[Pos],Tabla3[[#This Row],[Part.]])+SUMIFS(BD.PD[Pago 2],BD.PD[Per.P2],E$1,BD.PD[Pos],Tabla3[[#This Row],[Part.]])+SUMIFS(BD.PD[Pago 3],BD.PD[Per.P3],E$1,BD.PD[Pos],Tabla3[[#This Row],[Part.]])+SUMIFS(BD.PD[Pago 4],BD.PD[Per.P4],E$1,BD.PD[Pos],Tabla3[[#This Row],[Part.]])+SUMIFS(BD.PD[Pago 5],BD.PD[Per.P5],E$1,BD.PD[Pos],Tabla3[[#This Row],[Part.]]) -> 0 | F7: =SUMIFS(BD.PD[Pago 1],BD.PD[Per.P1],F$1,BD.PD[Pos],Tabla3[[#This Row],[Part.]])+SUMIFS(BD.PD[Pago 2],BD.PD[Per.P2],F$1,BD.PD[Pos],Tabla3[[#This Row],[Part.]])+SUMIFS(BD.PD[Pago 3],BD.PD[Per.P3],F$1,BD.PD[Pos],Tabla3[[#This Row],[Part.]])+SUMIFS(BD.PD[Pago 4],BD.PD[Per.P4],F$1,BD.PD[Pos],Tabla3[[#This Row],[Part.]])+SUMIFS(BD.PD[Pago 5],BD.PD[Per.P5],F$1,BD.PD[Pos],Tabla3[[#This Row],[Part.]]) -> 0 | G7: =SUMIFS(BD.PD[Pago 1],BD.PD[Per.P1],G$1,BD.PD[Pos],Tabla3[[#This Row],[Part.]])+SUMIFS(BD.PD[Pago 2],BD.PD[Per.P2],G$1,BD.PD[Pos],Tabla3[[#This Row],[Part.]])+SUMIFS(BD.PD[Pago 3],BD.PD[Per.P3],G$1,BD.PD[Pos],Tabla3[[#This Row],[Part.]])+SUMIFS(BD.PD[Pago 4],BD.PD[Per.P4],G$1,BD.PD[Pos],Tabla3[[#This Row],[Part.]])+SUMIFS(BD.PD[Pago 5],BD.PD[Per.P5],G$1,BD.PD[Pos],Tabla3[[#This Row],[Part.]]) -> 0 | H7: =SUMIFS(BD.PD[Pago 1],BD.PD[Per.P1],H$1,BD.PD[Pos],Tabla3[[#This Row],[Part.]])+SUMIFS(BD.PD[Pago 2],BD.PD[Per.P2],H$1,BD.PD[Pos],Tabla3[[#This Row],[Part.]])+SUMIFS(BD.PD[Pago 3],BD.PD[Per.P3],H$1,BD.PD[Pos],Tabla3[[#This Row],[Part.]])+SUMIFS(BD.PD[Pago 4],BD.PD[Per.P4],H$1,BD.PD[Pos],Tabla3[[#This Row],[Part.]])+SUMIFS(BD.PD[Pago 5],BD.PD[Per.P5],H$1,BD.PD[Pos],Tabla3[[#This Row],[Part.]]) -> 0 | I7: =SUMIFS(BD.PD[Pago 1],BD.PD[Per.P1],I$1,BD.PD[Pos],Tabla3[[#This Row],[Part.]])+SUMIFS(BD.PD[Pago 2],BD.PD[Per.P2],I$1,BD.PD[Pos],Tabla3[[#This Row],[Part.]])+SUMIFS(BD.PD[Pago 3],BD.PD[Per.P3],I$1,BD.PD[Pos],Tabla3[[#This Row],[Part.]])+SUMIFS(BD.PD[Pago 4],BD.PD[Per.P4],I$1,BD.PD[Pos],Tabla3[[#This Row],[Part.]])+SUMIFS(BD.PD[Pago 5],BD.PD[Per.P5],I$1,BD.PD[Pos],Tabla3[[#This Row],[Part.]]) -> 0 | J7: =SUMIFS(BD.PD[Pago 1],BD.PD[Per.P1],J$1,BD.PD[Pos],Tabla3[[#This Row],[Part.]])+SUMIFS(BD.PD[Pago 2],BD.PD[Per.P2],J$1,BD.PD[Pos],Tabla3[[#This Row],[Part.]])+SUMIFS(BD.PD[Pago 3],BD.PD[Per.P3],J$1,BD.PD[Pos],Tabla3[[#This Row],[Part.]])+SUMIFS(BD.PD[Pago 4],BD.PD[Per.P4],J$1,BD.PD[Pos],Tabla3[[#This Row],[Part.]])+SUMIFS(BD.PD[Pago 5],BD.PD[Per.P5],J$1,BD.PD[Pos],Tabla3[[#This Row],[Part.]]) -> 0 | K7: =SUMIFS(BD.PD[Pago 1],BD.PD[Per.P1],K$1,BD.PD[Pos],Tabla3[[#This Row],[Part.]])+SUMIFS(BD.PD[Pago 2],BD.PD[Per.P2],K$1,BD.PD[Pos],Tabla3[[#This Row],[Part.]])+SUMIFS(BD.PD[Pago 3],BD.PD[Per.P3],K$1,BD.PD[Pos],Tabla3[[#This Row],[Part.]])+SUMIFS(BD.PD[Pago 4],BD.PD[Per.P4],K$1,BD.PD[Pos],Tabla3[[#This Row],[Part.]])+SUMIFS(BD.PD[Pago 5],BD.PD[Per.P5],K$1,BD.PD[Pos],Tabla3[[#This Row],[Part.]]) -> 0 | ... AA7: =SUMIFS(BD.PD[Pago 1],BD.PD[Per.P1],AA$1,BD.PD[Pos],Tabla3[[#This Row],[Part.]])+SUMIFS(BD.PD[Pago 2],BD.PD[Per.P2],AA$1,BD.PD[Pos],Tabla3[[#This Row],[Part.]])+SUMIFS(BD.PD[Pago 3],BD.PD[Per.P3],AA$1,BD.PD[Pos],Tabla3[[#This Row],[Part.]])+SUMIFS(BD.PD[Pago 4],BD.PD[Per.P4],AA$1,BD.PD[Pos],Tabla3[[#This Row],[Part.]])+SUMIFS(BD.PD[Pago 5],BD.PD[Per.P5],AA$1,BD.PD[Pos],Tabla3[[#This Row],[Part.]]) -> 0 | AB7: =SUM(Tabla3[[#This Row],[P1]:[P24]]) -> 0
A8: 1.02 | B8: =VLOOKUP(Tabla3[[#This Row],[Part.]],PPto[],3,FALSE) -> 1.02 Diseño estructural | C8: =SUMIF(BD.PD[Pos],Tabla3[[#This Row],[Part.]],BD.PD[Ppto. Orden Interna '[DOP']]) -> 0 | D8: =SUMIFS(BD.PD[Pago 1],BD.PD[Per.P1],D$1,BD.PD[Pos],Tabla3[[#This Row],[Part.]])+SUMIFS(BD.PD[Pago 2],BD.PD[Per.P2],D$1,BD.PD[Pos],Tabla3[[#This Row],[Part.]])+SUMIFS(BD.PD[Pago 3],BD.PD[Per.P3],D$1,BD.PD[Pos],Tabla3[[#This Row],[Part.]])+SUMIFS(BD.PD[Pago 4],BD.PD[Per.P4],D$1,BD.PD[Pos],Tabla3[[#This Row],[Part.]])+SUMIFS(BD.PD[Pago 5],BD.PD[Per.P5],D$1,BD.PD[Pos],Tabla3[[#This Row],[Part.]]) -> 0 | E8: =SUMIFS(BD.PD[Pago 1],BD.PD[Per.P1],E$1,BD.PD[Pos],Tabla3[[#This Row],[Part.]])+SUMIFS(BD.PD[Pago 2],BD.PD[Per.P2],E$1,BD.PD[Pos],Tabla3[[#This Row],[Part.]])+SUMIFS(BD.PD[Pago 3],BD.PD[Per.P3],E$1,BD.PD[Pos],Tabla3[[#This Row],[Part.]])+SUMIFS(BD.PD[Pago 4],BD.PD[Per.P4],E$1,BD.PD[Pos],Tabla3[[#This Row],[Part.]])+SUMIFS(BD.PD[Pago 5],BD.PD[Per.P5],E$1,BD.PD[Pos],Tabla3[[#This Row],[Part.]]) -> 0 | F8: =SUMIFS(BD.PD[Pago 1],BD.PD[Per.P1],F$1,BD.PD[Pos],Tabla3[[#This Row],[Part.]])+SUMIFS(BD.PD[Pago 2],BD.PD[Per.P2],F$1,BD.PD[Pos],Tabla3[[#This Row],[Part.]])+SUMIFS(BD.PD[Pago 3],BD.PD[Per.P3],F$1,BD.PD[Pos],Tabla3[[#This Row],[Part.]])+SUMIFS(BD.PD[Pago 4],BD.PD[Per.P4],F$1,BD.PD[Pos],Tabla3[[#This Row],[Part.]])+SUMIFS(BD.PD[Pago 5],BD.PD[Per.P5],F$1,BD.PD[Pos],Tabla3[[#This Row],[Part.]]) -> 0 | G8: =SUMIFS(BD.PD[Pago 1],BD.PD[Per.P1],G$1,BD.PD[Pos],Tabla3[[#This Row],[Part.]])+SUMIFS(BD.PD[Pago 2],BD.PD[Per.P2],G$1,BD.PD[Pos],Tabla3[[#This Row],[Part.]])+SUMIFS(BD.PD[Pago 3],BD.PD[Per.P3],G$1,BD.PD[Pos],Tabla3[[#This Row],[Part.]])+SUMIFS(BD.PD[Pago 4],BD.PD[Per.P4],G$1,BD.PD[Pos],Tabla3[[#This Row],[Part.]])+SUMIFS(BD.PD[Pago 5],BD.PD[Per.P5],G$1,BD.PD[Pos],Tabla3[[#This Row],[Part.]]) -> 0 | H8: =SUMIFS(BD.PD[Pago 1],BD.PD[Per.P1],H$1,BD.PD[Pos],Tabla3[[#This Row],[Part.]])+SUMIFS(BD.PD[Pago 2],BD.PD[Per.P2],H$1,BD.PD[Pos],Tabla3[[#This Row],[Part.]])+SUMIFS(BD.PD[Pago 3],BD.PD[Per.P3],H$1,BD.PD[Pos],Tabla3[[#This Row],[Part.]])+SUMIFS(BD.PD[Pago 4],BD.PD[Per.P4],H$1,BD.PD[Pos],Tabla3[[#This Row],[Part.]])+SUMIFS(BD.PD[Pago 5],BD.PD[Per.P5],H$1,BD.PD[Pos],Tabla3[[#This Row],[Part.]]) -> 0 | I8: =SUMIFS(BD.PD[Pago 1],BD.PD[Per.P1],I$1,BD.PD[Pos],Tabla3[[#This Row],[Part.]])+SUMIFS(BD.PD[Pago 2],BD.PD[Per.P2],I$1,BD.PD[Pos],Tabla3[[#This Row],[Part.]])+SUMIFS(BD.PD[Pago 3],BD.PD[Per.P3],I$1,BD.PD[Pos],Tabla3[[#This Row],[Part.]])+SUMIFS(BD.PD[Pago 4],BD.PD[Per.P4],I$1,BD.PD[Pos],Tabla3[[#This Row],[Part.]])+SUMIFS(BD.PD[Pago 5],BD.PD[Per.P5],I$1,BD.PD[Pos],Tabla3[[#This Row],[Part.]]) -> 0 | J8: =SUMIFS(BD.PD[Pago 1],BD.PD[Per.P1],J$1,BD.PD[Pos],Tabla3[[#This Row],[Part.]])+SUMIFS(BD.PD[Pago 2],BD.PD[Per.P2],J$1,BD.PD[Pos],Tabla3[[#This Row],[Part.]])+SUMIFS(BD.PD[Pago 3],BD.PD[Per.P3],J$1,BD.PD[Pos],Tabla3[[#This Row],[Part.]])+SUMIFS(BD.PD[Pago 4],BD.PD[Per.P4],J$1,BD.PD[Pos],Tabla3[[#This Row],[Part.]])+SUMIFS(BD.PD[Pago 5],BD.PD[Per.P5],J$1,BD.PD[Pos],Tabla3[[#This Row],[Part.]]) -> 0 | K8: =SUMIFS(BD.PD[Pago 1],BD.PD[Per.P1],K$1,BD.PD[Pos],Tabla3[[#This Row],[Part.]])+SUMIFS(BD.PD[Pago 2],BD.PD[Per.P2],K$1,BD.PD[Pos],Tabla3[[#This Row],[Part.]])+SUMIFS(BD.PD[Pago 3],BD.PD[Per.P3],K$1,BD.PD[Pos],Tabla3[[#This Row],[Part.]])+SUMIFS(BD.PD[Pago 4],BD.PD[Per.P4],K$1,BD.PD[Pos],Tabla3[[#This Row],[Part.]])+SUMIFS(BD.PD[Pago 5],BD.PD[Per.P5],K$1,BD.PD[Pos],Tabla3[[#This Row],[Part.]]) -> 0 | ... AA8: =SUMIFS(BD.PD[Pago 1],BD.PD[Per.P1],AA$1,BD.PD[Pos],Tabla3[[#This Row],[Part.]])+SUMIFS(BD.PD[Pago 2],BD.PD[Per.P2],AA$1,BD.PD[Pos],Tabla3[[#This Row],[Part.]])+SUMIFS(BD.PD[Pago 3],BD.PD[Per.P3],AA$1,BD.PD[Pos],Tabla3[[#This Row],[Part.]])+SUMIFS(BD.PD[Pago 4],BD.PD[Per.P4],AA$1,BD.PD[Pos],Tabla3[[#This Row],[Part.]])+SUMIFS(BD.PD[Pago 5],BD.PD[Per.P5],AA$1,BD.PD[Pos],Tabla3[[#This Row],[Part.]]) -> 0 | AB8: =SUM(Tabla3[[#This Row],[P1]:[P24]]) -> 0
A9: 1.03 | B9: =VLOOKUP(Tabla3[[#This Row],[Part.]],PPto[],3,FALSE) -> 1.03 Diseño electromecánico | C9: =SUMIF(BD.PD[Pos],Tabla3[[#This Row],[Part.]],BD.PD[Ppto. Orden Interna '[DOP']]) -> 0 | D9: =SUMIFS(BD.PD[Pago 1],BD.PD[Per.P1],D$1,BD.PD[Pos],Tabla3[[#This Row],[Part.]])+SUMIFS(BD.PD[Pago 2],BD.PD[Per.P2],D$1,BD.PD[Pos],Tabla3[[#This Row],[Part.]])+SUMIFS(BD.PD[Pago 3],BD.PD[Per.P3],D$1,BD.PD[Pos],Tabla3[[#This Row],[Part.]])+SUMIFS(BD.PD[Pago 4],BD.PD[Per.P4],D$1,BD.PD[Pos],Tabla3[[#This Row],[Part.]])+SUMIFS(BD.PD[Pago 5],BD.PD[Per.P5],D$1,BD.PD[Pos],Tabla3[[#This Row],[Part.]]) -> 0 | E9: =SUMIFS(BD.PD[Pago 1],BD.PD[Per.P1],E$1,BD.PD[Pos],Tabla3[[#This Row],[Part.]])+SUMIFS(BD.PD[Pago 2],BD.PD[Per.P2],E$1,BD.PD[Pos],Tabla3[[#This Row],[Part.]])+SUMIFS(BD.PD[Pago 3],BD.PD[Per.P3],E$1,BD.PD[Pos],Tabla3[[#This Row],[Part.]])+SUMIFS(BD.PD[Pago 4],BD.PD[Per.P4],E$1,BD.PD[Pos],Tabla3[[#This Row],[Part.]])+SUMIFS(BD.PD[Pago 5],BD.PD[Per.P5],E$1,BD.PD[Pos],Tabla3[[#This Row],[Part.]]) -> 0 | F9: =SUMIFS(BD.PD[Pago 1],BD.PD[Per.P1],F$1,BD.PD[Pos],Tabla3[[#This Row],[Part.]])+SUMIFS(BD.PD[Pago 2],BD.PD[Per.P2],F$1,BD.PD[Pos],Tabla3[[#This Row],[Part.]])+SUMIFS(BD.PD[Pago 3],BD.PD[Per.P3],F$1,BD.PD[Pos],Tabla3[[#This Row],[Part.]])+SUMIFS(BD.PD[Pago 4],BD.PD[Per.P4],F$1,BD.PD[Pos],Tabla3[[#This Row],[Part.]])+SUMIFS(BD.PD[Pago 5],BD.PD[Per.P5],F$1,BD.PD[Pos],Tabla3[[#This Row],[Part.]]) -> 0 | G9: =SUMIFS(BD.PD[Pago 1],BD.PD[Per.P1],G$1,BD.PD[Pos],Tabla3[[#This Row],[Part.]])+SUMIFS(BD.PD[Pago 2],BD.PD[Per.P2],G$1,BD.PD[Pos],Tabla3[[#This Row],[Part.]])+SUMIFS(BD.PD[Pago 3],BD.PD[Per.P3],G$1,BD.PD[Pos],Tabla3[[#This Row],[Part.]])+SUMIFS(BD.PD[Pago 4],BD.PD[Per.P4],G$1,BD.PD[Pos],Tabla3[[#This Row],[Part.]])+SUMIFS(BD.PD[Pago 5],BD.PD[Per.P5],G$1,BD.PD[Pos],Tabla3[[#This Row],[Part.]]) -> 0 | H9: =SUMIFS(BD.PD[Pago 1],BD.PD[Per.P1],H$1,BD.PD[Pos],Tabla3[[#This Row],[Part.]])+SUMIFS(BD.PD[Pago 2],BD.PD[Per.P2],H$1,BD.PD[Pos],Tabla3[[#This Row],[Part.]])+SUMIFS(BD.PD[Pago 3],BD.PD[Per.P3],H$1,BD.PD[Pos],Tabla3[[#This Row],[Part.]])+SUMIFS(BD.PD[Pago 4],BD.PD[Per.P4],H$1,BD.PD[Pos],Tabla3[[#This Row],[Part.]])+SUMIFS(BD.PD[Pago 5],BD.PD[Per.P5],H$1,BD.PD[Pos],Tabla3[[#This Row],[Part.]]) -> 0 | I9: =SUMIFS(BD.PD[Pago 1],BD.PD[Per.P1],I$1,BD.PD[Pos],Tabla3[[#This Row],[Part.]])+SUMIFS(BD.PD[Pago 2],BD.PD[Per.P2],I$1,BD.PD[Pos],Tabla3[[#This Row],[Part.]])+SUMIFS(BD.PD[Pago 3],BD.PD[Per.P3],I$1,BD.PD[Pos],Tabla3[[#This Row],[Part.]])+SUMIFS(BD.PD[Pago 4],BD.PD[Per.P4],I$1,BD.PD[Pos],Tabla3[[#This Row],[Part.]])+SUMIFS(BD.PD[Pago 5],BD.PD[Per.P5],I$1,BD.PD[Pos],Tabla3[[#This Row],[Part.]]) -> 0 | J9: =SUMIFS(BD.PD[Pago 1],BD.PD[Per.P1],J$1,BD.PD[Pos],Tabla3[[#This Row],[Part.]])+SUMIFS(BD.PD[Pago 2],BD.PD[Per.P2],J$1,BD.PD[Pos],Tabla3[[#This Row],[Part.]])+SUMIFS(BD.PD[Pago 3],BD.PD[Per.P3],J$1,BD.PD[Pos],Tabla3[[#This Row],[Part.]])+SUMIFS(BD.PD[Pago 4],BD.PD[Per.P4],J$1,BD.PD[Pos],Tabla3[[#This Row],[Part.]])+SUMIFS(BD.PD[Pago 5],BD.PD[Per.P5],J$1,BD.PD[Pos],Tabla3[[#This Row],[Part.]]) -> 0 | K9: =SUMIFS(BD.PD[Pago 1],BD.PD[Per.P1],K$1,BD.PD[Pos],Tabla3[[#This Row],[Part.]])+SUMIFS(BD.PD[Pago 2],BD.PD[Per.P2],K$1,BD.PD[Pos],Tabla3[[#This Row],[Part.]])+SUMIFS(BD.PD[Pago 3],BD.PD[Per.P3],K$1,BD.PD[Pos],Tabla3[[#This Row],[Part.]])+SUMIFS(BD.PD[Pago 4],BD.PD[Per.P4],K$1,BD.PD[Pos],Tabla3[[#This Row],[Part.]])+SUMIFS(BD.PD[Pago 5],BD.PD[Per.P5],K$1,BD.PD[Pos],Tabla3[[#This Row],[Part.]]) -> 0 | ... AA9: =SUMIFS(BD.PD[Pago 1],BD.PD[Per.P1],AA$1,BD.PD[Pos],Tabla3[[#This Row],[Part.]])+SUMIFS(BD.PD[Pago 2],BD.PD[Per.P2],AA$1,BD.PD[Pos],Tabla3[[#This Row],[Part.]])+SUMIFS(BD.PD[Pago 3],BD.PD[Per.P3],AA$1,BD.PD[Pos],Tabla3[[#This Row],[Part.]])+SUMIFS(BD.PD[Pago 4],BD.PD[Per.P4],AA$1,BD.PD[Pos],Tabla3[[#This Row],[Part.]])+SUMIFS(BD.PD[Pago 5],BD.PD[Per.P5],AA$1,BD.PD[Pos],Tabla3[[#This Row],[Part.]]) -> 0 | AB9: =SUM(Tabla3[[#This Row],[P1]:[P24]]) -> 0
A10: 1.04 | B10: =VLOOKUP(Tabla3[[#This Row],[Part.]],PPto[],3,FALSE) -> 1.04 Diseño sanitario | C10: =SUMIF(BD.PD[Pos],Tabla3[[#This Row],[Part.]],BD.PD[Ppto. Orden Interna '[DOP']]) -> 0 | D10: =SUMIFS(BD.PD[Pago 1],BD.PD[Per.P1],D$1,BD.PD[Pos],Tabla3[[#This Row],[Part.]])+SUMIFS(BD.PD[Pago 2],BD.PD[Per.P2],D$1,BD.PD[Pos],Tabla3[[#This Row],[Part.]])+SUMIFS(BD.PD[Pago 3],BD.PD[Per.P3],D$1,BD.PD[Pos],Tabla3[[#This Row],[Part.]])+SUMIFS(BD.PD[Pago 4],BD.PD[Per.P4],D$1,BD.PD[Pos],Tabla3[[#This Row],[Part.]])+SUMIFS(BD.PD[Pago 5],BD.PD[Per.P5],D$1,BD.PD[Pos],Tabla3[[#This Row],[Part.]]) -> 0 | E10: =SUMIFS(BD.PD[Pago 1],BD.PD[Per.P1],E$1,BD.PD[Pos],Tabla3[[#This Row],[Part.]])+SUMIFS(BD.PD[Pago 2],BD.PD[Per.P2],E$1,BD.PD[Pos],Tabla3[[#This Row],[Part.]])+SUMIFS(BD.PD[Pago 3],BD.PD[Per.P3],E$1,BD.PD[Pos],Tabla3[[#This Row],[Part.]])+SUMIFS(BD.PD[Pago 4],BD.PD[Per.P4],E$1,BD.PD[Pos],Tabla3[[#This Row],[Part.]])+SUMIFS(BD.PD[Pago 5],BD.PD[Per.P5],E$1,BD.PD[Pos],Tabla3[[#This Row],[Part.]]) -> 0 | F10: =SUMIFS(BD.PD[Pago 1],BD.PD[Per.P1],F$1,BD.PD[Pos],Tabla3[[#This Row],[Part.]])+SUMIFS(BD.PD[Pago 2],BD.PD[Per.P2],F$1,BD.PD[Pos],Tabla3[[#This Row],[Part.]])+SUMIFS(BD.PD[Pago 3],BD.PD[Per.P3],F$1,BD.PD[Pos],Tabla3[[#This Row],[Part.]])+SUMIFS(BD.PD[Pago 4],BD.PD[Per.P4],F$1,BD.PD[Pos],Tabla3[[#This Row],[Part.]])+SUMIFS(BD.PD[Pago 5],BD.PD[Per.P5],F$1,BD.PD[Pos],Tabla3[[#This Row],[Part.]]) -> 0 | G10: =SUMIFS(BD.PD[Pago 1],BD.PD[Per.P1],G$1,BD.PD[Pos],Tabla3[[#This Row],[Part.]])+SUMIFS(BD.PD[Pago 2],BD.PD[Per.P2],G$1,BD.PD[Pos],Tabla3[[#This Row],[Part.]])+SUMIFS(BD.PD[Pago 3],BD.PD[Per.P3],G$1,BD.PD[Pos],Tabla3[[#This Row],[Part.]])+SUMIFS(BD.PD[Pago 4],BD.PD[Per.P4],G$1,BD.PD[Pos],Tabla3[[#This Row],[Part.]])+SUMIFS(BD.PD[Pago 5],BD.PD[Per.P5],G$1,BD.PD[Pos],Tabla3[[#This Row],[Part.]]) -> 0 | H10: =SUMIFS(BD.PD[Pago 1],BD.PD[Per.P1],H$1,BD.PD[Pos],Tabla3[[#This Row],[Part.]])+SUMIFS(BD.PD[Pago 2],BD.PD[Per.P2],H$1,BD.PD[Pos],Tabla3[[#This Row],[Part.]])+SUMIFS(BD.PD[Pago 3],BD.PD[Per.P3],H$1,BD.PD[Pos],Tabla3[[#This Row],[Part.]])+SUMIFS(BD.PD[Pago 4],BD.PD[Per.P4],H$1,BD.PD[Pos],Tabla3[[#This Row],[Part.]])+SUMIFS(BD.PD[Pago 5],BD.PD[Per.P5],H$1,BD.PD[Pos],Tabla3[[#This Row],[Part.]]) -> 0 | I10: =SUMIFS(BD.PD[Pago 1],BD.PD[Per.P1],I$1,BD.PD[Pos],Tabla3[[#This Row],[Part.]])+SUMIFS(BD.PD[Pago 2],BD.PD[Per.P2],I$1,BD.PD[Pos],Tabla3[[#This Row],[Part.]])+SUMIFS(BD.PD[Pago 3],BD.PD[Per.P3],I$1,BD.PD[Pos],Tabla3[[#This Row],[Part.]])+SUMIFS(BD.PD[Pago 4],BD.PD[Per.P4],I$1,BD.PD[Pos],Tabla3[[#This Row],[Part.]])+SUMIFS(BD.PD[Pago 5],BD.PD[Per.P5],I$1,BD.PD[Pos],Tabla3[[#This Row],[Part.]]) -> 0 | J10: =SUMIFS(BD.PD[Pago 1],BD.PD[Per.P1],J$1,BD.PD[Pos],Tabla3[[#This Row],[Part.]])+SUMIFS(BD.PD[Pago 2],BD.PD[Per.P2],J$1,BD.PD[Pos],Tabla3[[#This Row],[Part.]])+SUMIFS(BD.PD[Pago 3],BD.PD[Per.P3],J$1,BD.PD[Pos],Tabla3[[#This Row],[Part.]])+SUMIFS(BD.PD[Pago 4],BD.PD[Per.P4],J$1,BD.PD[Pos],Tabla3[[#This Row],[Part.]])+SUMIFS(BD.PD[Pago 5],BD.PD[Per.P5],J$1,BD.PD[Pos],Tabla3[[#This Row],[Part.]]) -> 0 | K10: =SUMIFS(BD.PD[Pago 1],BD.PD[Per.P1],K$1,BD.PD[Pos],Tabla3[[#This Row],[Part.]])+SUMIFS(BD.PD[Pago 2],BD.PD[Per.P2],K$1,BD.PD[Pos],Tabla3[[#This Row],[Part.]])+SUMIFS(BD.PD[Pago 3],BD.PD[Per.P3],K$1,BD.PD[Pos],Tabla3[[#This Row],[Part.]])+SUMIFS(BD.PD[Pago 4],BD.PD[Per.P4],K$1,BD.PD[Pos],Tabla3[[#This Row],[Part.]])+SUMIFS(BD.PD[Pago 5],BD.PD[Per.P5],K$1,BD.PD[Pos],Tabla3[[#This Row],[Part.]]) -> 0 | ... AA10: =SUMIFS(BD.PD[Pago 1],BD.PD[Per.P1],AA$1,BD.PD[Pos],Tabla3[[#This Row],[Part.]])+SUMIFS(BD.PD[Pago 2],BD.PD[Per.P2],AA$1,BD.PD[Pos],Tabla3[[#This Row],[Part.]])+SUMIFS(BD.PD[Pago 3],BD.PD[Per.P3],AA$1,BD.PD[Pos],Tabla3[[#This Row],[Part.]])+SUMIFS(BD.PD[Pago 4],BD.PD[Per.P4],AA$1,BD.PD[Pos],Tabla3[[#This Row],[Part.]])+SUMIFS(BD.PD[Pago 5],BD.PD[Per.P5],AA$1,BD.PD[Pos],Tabla3[[#This Row],[Part.]]) -> 0 | AB10: =SUM(Tabla3[[#This Row],[P1]:[P24]]) -> 0
A11: 1.05 | B11: =VLOOKUP(Tabla3[[#This Row],[Part.]],PPto[],3,FALSE) -> 1.05 Estudio Geotécnico | C11: =SUMIF(BD.PD[Pos],Tabla3[[#This Row],[Part.]],BD.PD[Ppto. Orden Interna '[DOP']]) -> 0 | D11: =SUMIFS(BD.PD[Pago 1],BD.PD[Per.P1],D$1,BD.PD[Pos],Tabla3[[#This Row],[Part.]])+SUMIFS(BD.PD[Pago 2],BD.PD[Per.P2],D$1,BD.PD[Pos],Tabla3[[#This Row],[Part.]])+SUMIFS(BD.PD[Pago 3],BD.PD[Per.P3],D$1,BD.PD[Pos],Tabla3[[#This Row],[Part.]])+SUMIFS(BD.PD[Pago 4],BD.PD[Per.P4],D$1,BD.PD[Pos],Tabla3[[#This Row],[Part.]])+SUMIFS(BD.PD[Pago 5],BD.PD[Per.P5],D$1,BD.PD[Pos],Tabla3[[#This Row],[Part.]]) -> 0 | E11: =SUMIFS(BD.PD[Pago 1],BD.PD[Per.P1],E$1,BD.PD[Pos],Tabla3[[#This Row],[Part.]])+SUMIFS(BD.PD[Pago 2],BD.PD[Per.P2],E$1,BD.PD[Pos],Tabla3[[#This Row],[Part.]])+SUMIFS(BD.PD[Pago 3],BD.PD[Per.P3],E$1,BD.PD[Pos],Tabla3[[#This Row],[Part.]])+SUMIFS(BD.PD[Pago 4],BD.PD[Per.P4],E$1,BD.PD[Pos],Tabla3[[#This Row],[Part.]])+SUMIFS(BD.PD[Pago 5],BD.PD[Per.P5],E$1,BD.PD[Pos],Tabla3[[#This Row],[Part.]]) -> 0 | F11: =SUMIFS(BD.PD[Pago 1],BD.PD[Per.P1],F$1,BD.PD[Pos],Tabla3[[#This Row],[Part.]])+SUMIFS(BD.PD[Pago 2],BD.PD[Per.P2],F$1,BD.PD[Pos],Tabla3[[#This Row],[Part.]])+SUMIFS(BD.PD[Pago 3],BD.PD[Per.P3],F$1,BD.PD[Pos],Tabla3[[#This Row],[Part.]])+SUMIFS(BD.PD[Pago 4],BD.PD[Per.P4],F$1,BD.PD[Pos],Tabla3[[#This Row],[Part.]])+SUMIFS(BD.PD[Pago 5],BD.PD[Per.P5],F$1,BD.PD[Pos],Tabla3[[#This Row],[Part.]]) -> 0 | G11: =SUMIFS(BD.PD[Pago 1],BD.PD[Per.P1],G$1,BD.PD[Pos],Tabla3[[#This Row],[Part.]])+SUMIFS(BD.PD[Pago 2],BD.PD[Per.P2],G$1,BD.PD[Pos],Tabla3[[#This Row],[Part.]])+SUMIFS(BD.PD[Pago 3],BD.PD[Per.P3],G$1,BD.PD[Pos],Tabla3[[#This Row],[Part.]])+SUMIFS(BD.PD[Pago 4],BD.PD[Per.P4],G$1,BD.PD[Pos],Tabla3[[#This Row],[Part.]])+SUMIFS(BD.PD[Pago 5],BD.PD[Per.P5],G$1,BD.PD[Pos],Tabla3[[#This Row],[Part.]]) -> 0 | H11: =SUMIFS(BD.PD[Pago 1],BD.PD[Per.P1],H$1,BD.PD[Pos],Tabla3[[#This Row],[Part.]])+SUMIFS(BD.PD[Pago 2],BD.PD[Per.P2],H$1,BD.PD[Pos],Tabla3[[#This Row],[Part.]])+SUMIFS(BD.PD[Pago 3],BD.PD[Per.P3],H$1,BD.PD[Pos],Tabla3[[#This Row],[Part.]])+SUMIFS(BD.PD[Pago 4],BD.PD[Per.P4],H$1,BD.PD[Pos],Tabla3[[#This Row],[Part.]])+SUMIFS(BD.PD[Pago 5],BD.PD[Per.P5],H$1,BD.PD[Pos],Tabla3[[#This Row],[Part.]]) -> 0 | I11: =SUMIFS(BD.PD[Pago 1],BD.PD[Per.P1],I$1,BD.PD[Pos],Tabla3[[#This Row],[Part.]])+SUMIFS(BD.PD[Pago 2],BD.PD[Per.P2],I$1,BD.PD[Pos],Tabla3[[#This Row],[Part.]])+SUMIFS(BD.PD[Pago 3],BD.PD[Per.P3],I$1,BD.PD[Pos],Tabla3[[#This Row],[Part.]])+SUMIFS(BD.PD[Pago 4],BD.PD[Per.P4],I$1,BD.PD[Pos],Tabla3[[#This Row],[Part.]])+SUMIFS(BD.PD[Pago 5],BD.PD[Per.P5],I$1,BD.PD[Pos],Tabla3[[#This Row],[Part.]]) -> 0 | J11: =SUMIFS(BD.PD[Pago 1],BD.PD[Per.P1],J$1,BD.PD[Pos],Tabla3[[#This Row],[Part.]])+SUMIFS(BD.PD[Pago 2],BD.PD[Per.P2],J$1,BD.PD[Pos],Tabla3[[#This Row],[Part.]])+SUMIFS(BD.PD[Pago 3],BD.PD[Per.P3],J$1,BD.PD[Pos],Tabla3[[#This Row],[Part.]])+SUMIFS(BD.PD[Pago 4],BD.PD[Per.P4],J$1,BD.PD[Pos],Tabla3[[#This Row],[Part.]])+SUMIFS(BD.PD[Pago 5],BD.PD[Per.P5],J$1,BD.PD[Pos],Tabla3[[#This Row],[Part.]]) -> 0 | K11: =SUMIFS(BD.PD[Pago 1],BD.PD[Per.P1],K$1,BD.PD[Pos],Tabla3[[#This Row],[Part.]])+SUMIFS(BD.PD[Pago 2],BD.PD[Per.P2],K$1,BD.PD[Pos],Tabla3[[#This Row],[Part.]])+SUMIFS(BD.PD[Pago 3],BD.PD[Per.P3],K$1,BD.PD[Pos],Tabla3[[#This Row],[Part.]])+SUMIFS(BD.PD[Pago 4],BD.PD[Per.P4],K$1,BD.PD[Pos],Tabla3[[#This Row],[Part.]])+SUMIFS(BD.PD[Pago 5],BD.PD[Per.P5],K$1,BD.PD[Pos],Tabla3[[#This Row],[Part.]]) -> 0 | ... AA11: =SUMIFS(BD.PD[Pago 1],BD.PD[Per.P1],AA$1,BD.PD[Pos],Tabla3[[#This Row],[Part.]])+SUMIFS(BD.PD[Pago 2],BD.PD[Per.P2],AA$1,BD.PD[Pos],Tabla3[[#This Row],[Part.]])+SUMIFS(BD.PD[Pago 3],BD.PD[Per.P3],AA$1,BD.PD[Pos],Tabla3[[#This Row],[Part.]])+SUMIFS(BD.PD[Pago 4],BD.PD[Per.P4],AA$1,BD.PD[Pos],Tabla3[[#This Row],[Part.]])+SUMIFS(BD.PD[Pago 5],BD.PD[Per.P5],AA$1,BD.PD[Pos],Tabla3[[#This Row],[Part.]]) -> 0 | AB11: =SUM(Tabla3[[#This Row],[P1]:[P24]]) -> 0
A12: 1.06 | B12: =VLOOKUP(Tabla3[[#This Row],[Part.]],PPto[],3,FALSE) -> 1.06 Levantamiento topográfico | C12: =SUMIF(BD.PD[Pos],Tabla3[[#This Row],[Part.]],BD.PD[Ppto. Orden Interna '[DOP']]) -> 0 | D12: =SUMIFS(BD.PD[Pago 1],BD.PD[Per.P1],D$1,BD.PD[Pos],Tabla3[[#This Row],[Part.]])+SUMIFS(BD.PD[Pago 2],BD.PD[Per.P2],D$1,BD.PD[Pos],Tabla3[[#This Row],[Part.]])+SUMIFS(BD.PD[Pago 3],BD.PD[Per.P3],D$1,BD.PD[Pos],Tabla3[[#This Row],[Part.]])+SUMIFS(BD.PD[Pago 4],BD.PD[Per.P4],D$1,BD.PD[Pos],Tabla3[[#This Row],[Part.]])+SUMIFS(BD.PD[Pago 5],BD.PD[Per.P5],D$1,BD.PD[Pos],Tabla3[[#This Row],[Part.]]) -> 0 | E12: =SUMIFS(BD.PD[Pago 1],BD.PD[Per.P1],E$1,BD.PD[Pos],Tabla3[[#This Row],[Part.]])+SUMIFS(BD.PD[Pago 2],BD.PD[Per.P2],E$1,BD.PD[Pos],Tabla3[[#This Row],[Part.]])+SUMIFS(BD.PD[Pago 3],BD.PD[Per.P3],E$1,BD.PD[Pos],Tabla3[[#This Row],[Part.]])+SUMIFS(BD.PD[Pago 4],BD.PD[Per.P4],E$1,BD.PD[Pos],Tabla3[[#This Row],[Part.]])+SUMIFS(BD.PD[Pago 5],BD.PD[Per.P5],E$1,BD.PD[Pos],Tabla3[[#This Row],[Part.]]) -> 0 | F12: =SUMIFS(BD.PD[Pago 1],BD.PD[Per.P1],F$1,BD.PD[Pos],Tabla3[[#This Row],[Part.]])+SUMIFS(BD.PD[Pago 2],BD.PD[Per.P2],F$1,BD.PD[Pos],Tabla3[[#This Row],[Part.]])+SUMIFS(BD.PD[Pago 3],BD.PD[Per.P3],F$1,BD.PD[Pos],Tabla3[[#This Row],[Part.]])+SUMIFS(BD.PD[Pago 4],BD.PD[Per.P4],F$1,BD.PD[Pos],Tabla3[[#This Row],[Part.]])+SUMIFS(BD.PD[Pago 5],BD.PD[Per.P5],F$1,BD.PD[Pos],Tabla3[[#This Row],[Part.]]) -> 0 | G12: =SUMIFS(BD.PD[Pago 1],BD.PD[Per.P1],G$1,BD.PD[Pos],Tabla3[[#This Row],[Part.]])+SUMIFS(BD.PD[Pago 2],BD.PD[Per.P2],G$1,BD.PD[Pos],Tabla3[[#This Row],[Part.]])+SUMIFS(BD.PD[Pago 3],BD.PD[Per.P3],G$1,BD.PD[Pos],Tabla3[[#This Row],[Part.]])+SUMIFS(BD.PD[Pago 4],BD.PD[Per.P4],G$1,BD.PD[Pos],Tabla3[[#This Row],[Part.]])+SUMIFS(BD.PD[Pago 5],BD.PD[Per.P5],G$1,BD.PD[Pos],Tabla3[[#This Row],[Part.]]) -> 0 | H12: =SUMIFS(BD.PD[Pago 1],BD.PD[Per.P1],H$1,BD.PD[Pos],Tabla3[[#This Row],[Part.]])+SUMIFS(BD.PD[Pago 2],BD.PD[Per.P2],H$1,BD.PD[Pos],Tabla3[[#This Row],[Part.]])+SUMIFS(BD.PD[Pago 3],BD.PD[Per.P3],H$1,BD.PD[Pos],Tabla3[[#This Row],[Part.]])+SUMIFS(BD.PD[Pago 4],BD.PD[Per.P4],H$1,BD.PD[Pos],Tabla3[[#This Row],[Part.]])+SUMIFS(BD.PD[Pago 5],BD.PD[Per.P5],H$1,BD.PD[Pos],Tabla3[[#This Row],[Part.]]) -> 0 | I12: =SUMIFS(BD.PD[Pago 1],BD.PD[Per.P1],I$1,BD.PD[Pos],Tabla3[[#This Row],[Part.]])+SUMIFS(BD.PD[Pago 2],BD.PD[Per.P2],I$1,BD.PD[Pos],Tabla3[[#This Row],[Part.]])+SUMIFS(BD.PD[Pago 3],BD.PD[Per.P3],I$1,BD.PD[Pos],Tabla3[[#This Row],[Part.]])+SUMIFS(BD.PD[Pago 4],BD.PD[Per.P4],I$1,BD.PD[Pos],Tabla3[[#This Row],[Part.]])+SUMIFS(BD.PD[Pago 5],BD.PD[Per.P5],I$1,BD.PD[Pos],Tabla3[[#This Row],[Part.]]) -> 0 | J12: =SUMIFS(BD.PD[Pago 1],BD.PD[Per.P1],J$1,BD.PD[Pos],Tabla3[[#This Row],[Part.]])+SUMIFS(BD.PD[Pago 2],BD.PD[Per.P2],J$1,BD.PD[Pos],Tabla3[[#This Row],[Part.]])+SUMIFS(BD.PD[Pago 3],BD.PD[Per.P3],J$1,BD.PD[Pos],Tabla3[[#This Row],[Part.]])+SUMIFS(BD.PD[Pago 4],BD.PD[Per.P4],J$1,BD.PD[Pos],Tabla3[[#This Row],[Part.]])+SUMIFS(BD.PD[Pago 5],BD.PD[Per.P5],J$1,BD.PD[Pos],Tabla3[[#This Row],[Part.]]) -> 0 | K12: =SUMIFS(BD.PD[Pago 1],BD.PD[Per.P1],K$1,BD.PD[Pos],Tabla3[[#This Row],[Part.]])+SUMIFS(BD.PD[Pago 2],BD.PD[Per.P2],K$1,BD.PD[Pos],Tabla3[[#This Row],[Part.]])+SUMIFS(BD.PD[Pago 3],BD.PD[Per.P3],K$1,BD.PD[Pos],Tabla3[[#This Row],[Part.]])+SUMIFS(BD.PD[Pago 4],BD.PD[Per.P4],K$1,BD.PD[Pos],Tabla3[[#This Row],[Part.]])+SUMIFS(BD.PD[Pago 5],BD.PD[Per.P5],K$1,BD.PD[Pos],Tabla3[[#This Row],[Part.]]) -> 0 | ... AA12: =SUMIFS(BD.PD[Pago 1],BD.PD[Per.P1],AA$1,BD.PD[Pos],Tabla3[[#This Row],[Part.]])+SUMIFS(BD.PD[Pago 2],BD.PD[Per.P2],AA$1,BD.PD[Pos],Tabla3[[#This Row],[Part.]])+SUMIFS(BD.PD[Pago 3],BD.PD[Per.P3],AA$1,BD.PD[Pos],Tabla3[[#This Row],[Part.]])+SUMIFS(BD.PD[Pago 4],BD.PD[Per.P4],AA$1,BD.PD[Pos],Tabla3[[#This Row],[Part.]])+SUMIFS(BD.PD[Pago 5],BD.PD[Per.P5],AA$1,BD.PD[Pos],Tabla3[[#This Row],[Part.]]) -> 0 | AB12: =SUM(Tabla3[[#This Row],[P1]:[P24]]) -> 0
A13: 1.07 | B13: =VLOOKUP(Tabla3[[#This Row],[Part.]],PPto[],3,FALSE) -> 1.07 Permisos | C13: =SUMIF(BD.PD[Pos],Tabla3[[#This Row],[Part.]],BD.PD[Ppto. Orden Interna '[DOP']]) -> 0 | D13: =SUMIFS(BD.PD[Pago 1],BD.PD[Per.P1],D$1,BD.PD[Pos],Tabla3[[#This Row],[Part.]])+SUMIFS(BD.PD[Pago 2],BD.PD[Per.P2],D$1,BD.PD[Pos],Tabla3[[#This Row],[Part.]])+SUMIFS(BD.PD[Pago 3],BD.PD[Per.P3],D$1,BD.PD[Pos],Tabla3[[#This Row],[Part.]])+SUMIFS(BD.PD[Pago 4],BD.PD[Per.P4],D$1,BD.PD[Pos],Tabla3[[#This Row],[Part.]])+SUMIFS(BD.PD[Pago 5],BD.PD[Per.P5],D$1,BD.PD[Pos],Tabla3[[#This Row],[Part.]]) -> 0 | E13: =SUMIFS(BD.PD[Pago 1],BD.PD[Per.P1],E$1,BD.PD[Pos],Tabla3[[#This Row],[Part.]])+SUMIFS(BD.PD[Pago 2],BD.PD[Per.P2],E$1,BD.PD[Pos],Tabla3[[#This Row],[Part.]])+SUMIFS(BD.PD[Pago 3],BD.PD[Per.P3],E$1,BD.PD[Pos],Tabla3[[#This Row],[Part.]])+SUMIFS(BD.PD[Pago 4],BD.PD[Per.P4],E$1,BD.PD[Pos],Tabla3[[#This Row],[Part.]])+SUMIFS(BD.PD[Pago 5],BD.PD[Per.P5],E$1,BD.PD[Pos],Tabla3[[#This Row],[Part.]]) -> 0 | F13: =SUMIFS(BD.PD[Pago 1],BD.PD[Per.P1],F$1,BD.PD[Pos],Tabla3[[#This Row],[Part.]])+SUMIFS(BD.PD[Pago 2],BD.PD[Per.P2],F$1,BD.PD[Pos],Tabla3[[#This Row],[Part.]])+SUMIFS(BD.PD[Pago 3],BD.PD[Per.P3],F$1,BD.PD[Pos],Tabla3[[#This Row],[Part.]])+SUMIFS(BD.PD[Pago 4],BD.PD[Per.P4],F$1,BD.PD[Pos],Tabla3[[#This Row],[Part.]])+SUMIFS(BD.PD[Pago 5],BD.PD[Per.P5],F$1,BD.PD[Pos],Tabla3[[#This Row],[Part.]]) -> 0 | G13: =SUMIFS(BD.PD[Pago 1],BD.PD[Per.P1],G$1,BD.PD[Pos],Tabla3[[#This Row],[Part.]])+SUMIFS(BD.PD[Pago 2],BD.PD[Per.P2],G$1,BD.PD[Pos],Tabla3[[#This Row],[Part.]])+SUMIFS(BD.PD[Pago 3],BD.PD[Per.P3],G$1,BD.PD[Pos],Tabla3[[#This Row],[Part.]])+SUMIFS(BD.PD[Pago 4],BD.PD[Per.P4],G$1,BD.PD[Pos],Tabla3[[#This Row],[Part.]])+SUMIFS(BD.PD[Pago 5],BD.PD[Per.P5],G$1,BD.PD[Pos],Tabla3[[#This Row],[Part.]]) -> 0 | H13: =SUMIFS(BD.PD[Pago 1],BD.PD[Per.P1],H$1,BD.PD[Pos],Tabla3[[#This Row],[Part.]])+SUMIFS(BD.PD[Pago 2],BD.PD[Per.P2],H$1,BD.PD[Pos],Tabla3[[#This Row],[Part.]])+SUMIFS(BD.PD[Pago 3],BD.PD[Per.P3],H$1,BD.PD[Pos],Tabla3[[#This Row],[Part.]])+SUMIFS(BD.PD[Pago 4],BD.PD[Per.P4],H$1,BD.PD[Pos],Tabla3[[#This Row],[Part.]])+SUMIFS(BD.PD[Pago 5],BD.PD[Per.P5],H$1,BD.PD[Pos],Tabla3[[#This Row],[Part.]]) -> 0 | I13: =SUMIFS(BD.PD[Pago 1],BD.PD[Per.P1],I$1,BD.PD[Pos],Tabla3[[#This Row],[Part.]])+SUMIFS(BD.PD[Pago 2],BD.PD[Per.P2],I$1,BD.PD[Pos],Tabla3[[#This Row],[Part.]])+SUMIFS(BD.PD[Pago 3],BD.PD[Per.P3],I$1,BD.PD[Pos],Tabla3[[#This Row],[Part.]])+SUMIFS(BD.PD[Pago 4],BD.PD[Per.P4],I$1,BD.PD[Pos],Tabla3[[#This Row],[Part.]])+SUMIFS(BD.PD[Pago 5],BD.PD[Per.P5],I$1,BD.PD[Pos],Tabla3[[#This Row],[Part.]]) -> 0 | J13: =SUMIFS(BD.PD[Pago 1],BD.PD[Per.P1],J$1,BD.PD[Pos],Tabla3[[#This Row],[Part.]])+SUMIFS(BD.PD[Pago 2],BD.PD[Per.P2],J$1,BD.PD[Pos],Tabla3[[#This Row],[Part.]])+SUMIFS(BD.PD[Pago 3],BD.PD[Per.P3],J$1,BD.PD[Pos],Tabla3[[#This Row],[Part.]])+SUMIFS(BD.PD[Pago 4],BD.PD[Per.P4],J$1,BD.PD[Pos],Tabla3[[#This Row],[Part.]])+SUMIFS(BD.PD[Pago 5],BD.PD[Per.P5],J$1,BD.PD[Pos],Tabla3[[#This Row],[Part.]]) -> 0 | K13: =SUMIFS(BD.PD[Pago 1],BD.PD[Per.P1],K$1,BD.PD[Pos],Tabla3[[#This Row],[Part.]])+SUMIFS(BD.PD[Pago 2],BD.PD[Per.P2],K$1,BD.PD[Pos],Tabla3[[#This Row],[Part.]])+SUMIFS(BD.PD[Pago 3],BD.PD[Per.P3],K$1,BD.PD[Pos],Tabla3[[#This Row],[Part.]])+SUMIFS(BD.PD[Pago 4],BD.PD[Per.P4],K$1,BD.PD[Pos],Tabla3[[#This Row],[Part.]])+SUMIFS(BD.PD[Pago 5],BD.PD[Per.P5],K$1,BD.PD[Pos],Tabla3[[#This Row],[Part.]]) -> 0 | ... AA13: =SUMIFS(BD.PD[Pago 1],BD.PD[Per.P1],AA$1,BD.PD[Pos],Tabla3[[#This Row],[Part.]])+SUMIFS(BD.PD[Pago 2],BD.PD[Per.P2],AA$1,BD.PD[Pos],Tabla3[[#This Row],[Part.]])+SUMIFS(BD.PD[Pago 3],BD.PD[Per.P3],AA$1,BD.PD[Pos],Tabla3[[#This Row],[Part.]])+SUMIFS(BD.PD[Pago 4],BD.PD[Per.P4],AA$1,BD.PD[Pos],Tabla3[[#This Row],[Part.]])+SUMIFS(BD.PD[Pago 5],BD.PD[Per.P5],AA$1,BD.PD[Pos],Tabla3[[#This Row],[Part.]]) -> 0 | AB13: =SUM(Tabla3[[#This Row],[P1]:[P24]]) -> 0
A14: 1.08 | B14: =VLOOKUP(Tabla3[[#This Row],[Part.]],PPto[],3,FALSE) -> 1.08 Diseño sistema contra incendios | C14: =SUMIF(BD.PD[Pos],Tabla3[[#This Row],[Part.]],BD.PD[Ppto. Orden Interna '[DOP']]) -> 0 | D14: =SUMIFS(BD.PD[Pago 1],BD.PD[Per.P1],D$1,BD.PD[Pos],Tabla3[[#This Row],[Part.]])+SUMIFS(BD.PD[Pago 2],BD.PD[Per.P2],D$1,BD.PD[Pos],Tabla3[[#This Row],[Part.]])+SUMIFS(BD.PD[Pago 3],BD.PD[Per.P3],D$1,BD.PD[Pos],Tabla3[[#This Row],[Part.]])+SUMIFS(BD.PD[Pago 4],BD.PD[Per.P4],D$1,BD.PD[Pos],Tabla3[[#This Row],[Part.]])+SUMIFS(BD.PD[Pago 5],BD.PD[Per.P5],D$1,BD.PD[Pos],Tabla3[[#This Row],[Part.]]) -> 0 | E14: =SUMIFS(BD.PD[Pago 1],BD.PD[Per.P1],E$1,BD.PD[Pos],Tabla3[[#This Row],[Part.]])+SUMIFS(BD.PD[Pago 2],BD.PD[Per.P2],E$1,BD.PD[Pos],Tabla3[[#This Row],[Part.]])+SUMIFS(BD.PD[Pago 3],BD.PD[Per.P3],E$1,BD.PD[Pos],Tabla3[[#This Row],[Part.]])+SUMIFS(BD.PD[Pago 4],BD.PD[Per.P4],E$1,BD.PD[Pos],Tabla3[[#This Row],[Part.]])+SUMIFS(BD.PD[Pago 5],BD.PD[Per.P5],E$1,BD.PD[Pos],Tabla3[[#This Row],[Part.]]) -> 0 | F14: =SUMIFS(BD.PD[Pago 1],BD.PD[Per.P1],F$1,BD.PD[Pos],Tabla3[[#This Row],[Part.]])+SUMIFS(BD.PD[Pago 2],BD.PD[Per.P2],F$1,BD.PD[Pos],Tabla3[[#This Row],[Part.]])+SUMIFS(BD.PD[Pago 3],BD.PD[Per.P3],F$1,BD.PD[Pos],Tabla3[[#This Row],[Part.]])+SUMIFS(BD.PD[Pago 4],BD.PD[Per.P4],F$1,BD.PD[Pos],Tabla3[[#This Row],[Part.]])+SUMIFS(BD.PD[Pago 5],BD.PD[Per.P5],F$1,BD.PD[Pos],Tabla3[[#This Row],[Part.]]) -> 0 | G14: =SUMIFS(BD.PD[Pago 1],BD.PD[Per.P1],G$1,BD.PD[Pos],Tabla3[[#This Row],[Part.]])+SUMIFS(BD.PD[Pago 2],BD.PD[Per.P2],G$1,BD.PD[Pos],Tabla3[[#This Row],[Part.]])+SUMIFS(BD.PD[Pago 3],BD.PD[Per.P3],G$1,BD.PD[Pos],Tabla3[[#This Row],[Part.]])+SUMIFS(BD.PD[Pago 4],BD.PD[Per.P4],G$1,BD.PD[Pos],Tabla3[[#This Row],[Part.]])+SUMIFS(BD.PD[Pago 5],BD.PD[Per.P5],G$1,BD.PD[Pos],Tabla3[[#This Row],[Part.]]) -> 0 | H14: =SUMIFS(BD.PD[Pago 1],BD.PD[Per.P1],H$1,BD.PD[Pos],Tabla3[[#This Row],[Part.]])+SUMIFS(BD.PD[Pago 2],BD.PD[Per.P2],H$1,BD.PD[Pos],Tabla3[[#This Row],[Part.]])+SUMIFS(BD.PD[Pago 3],BD.PD[Per.P3],H$1,BD.PD[Pos],Tabla3[[#This Row],[Part.]])+SUMIFS(BD.PD[Pago 4],BD.PD[Per.P4],H$1,BD.PD[Pos],Tabla3[[#This Row],[Part.]])+SUMIFS(BD.PD[Pago 5],BD.PD[Per.P5],H$1,BD.PD[Pos],Tabla3[[#This Row],[Part.]]) -> 0 | I14: =SUMIFS(BD.PD[Pago 1],BD.PD[Per.P1],I$1,BD.PD[Pos],Tabla3[[#This Row],[Part.]])+SUMIFS(BD.PD[Pago 2],BD.PD[Per.P2],I$1,BD.PD[Pos],Tabla3[[#This Row],[Part.]])+SUMIFS(BD.PD[Pago 3],BD.PD[Per.P3],I$1,BD.PD[Pos],Tabla3[[#This Row],[Part.]])+SUMIFS(BD.PD[Pago 4],BD.PD[Per.P4],I$1,BD.PD[Pos],Tabla3[[#This Row],[Part.]])+SUMIFS(BD.PD[Pago 5],BD.PD[Per.P5],I$1,BD.PD[Pos],Tabla3[[#This Row],[Part.]]) -> 0 | J14: =SUMIFS(BD.PD[Pago 1],BD.PD[Per.P1],J$1,BD.PD[Pos],Tabla3[[#This Row],[Part.]])+SUMIFS(BD.PD[Pago 2],BD.PD[Per.P2],J$1,BD.PD[Pos],Tabla3[[#This Row],[Part.]])+SUMIFS(BD.PD[Pago 3],BD.PD[Per.P3],J$1,BD.PD[Pos],Tabla3[[#This Row],[Part.]])+SUMIFS(BD.PD[Pago 4],BD.PD[Per.P4],J$1,BD.PD[Pos],Tabla3[[#This Row],[Part.]])+SUMIFS(BD.PD[Pago 5],BD.PD[Per.P5],J$1,BD.PD[Pos],Tabla3[[#This Row],[Part.]]) -> 0 | K14: =SUMIFS(BD.PD[Pago 1],BD.PD[Per.P1],K$1,BD.PD[Pos],Tabla3[[#This Row],[Part.]])+SUMIFS(BD.PD[Pago 2],BD.PD[Per.P2],K$1,BD.PD[Pos],Tabla3[[#This Row],[Part.]])+SUMIFS(BD.PD[Pago 3],BD.PD[Per.P3],K$1,BD.PD[Pos],Tabla3[[#This Row],[Part.]])+SUMIFS(BD.PD[Pago 4],BD.PD[Per.P4],K$1,BD.PD[Pos],Tabla3[[#This Row],[Part.]])+SUMIFS(BD.PD[Pago 5],BD.PD[Per.P5],K$1,BD.PD[Pos],Tabla3[[#This Row],[Part.]]) -> 0 | ... AA14: =SUMIFS(BD.PD[Pago 1],BD.PD[Per.P1],AA$1,BD.PD[Pos],Tabla3[[#This Row],[Part.]])+SUMIFS(BD.PD[Pago 2],BD.PD[Per.P2],AA$1,BD.PD[Pos],Tabla3[[#This Row],[Part.]])+SUMIFS(BD.PD[Pago 3],BD.PD[Per.P3],AA$1,BD.PD[Pos],Tabla3[[#This Row],[Part.]])+SUMIFS(BD.PD[Pago 4],BD.PD[Per.P4],AA$1,BD.PD[Pos],Tabla3[[#This Row],[Part.]])+SUMIFS(BD.PD[Pago 5],BD.PD[Per.P5],AA$1,BD.PD[Pos],Tabla3[[#This Row],[Part.]]) -> 0 | AB14: =SUM(Tabla3[[#This Row],[P1]:[P24]]) -> 0
A15: 1.09 | B15: =VLOOKUP(Tabla3[[#This Row],[Part.]],PPto[],3,FALSE) -> 1.09 Diseño sistema gas | C15: =SUMIF(BD.PD[Pos],Tabla3[[#This Row],[Part.]],BD.PD[Ppto. Orden Interna '[DOP']]) -> 0 | D15: =SUMIFS(BD.PD[Pago 1],BD.PD[Per.P1],D$1,BD.PD[Pos],Tabla3[[#This Row],[Part.]])+SUMIFS(BD.PD[Pago 2],BD.PD[Per.P2],D$1,BD.PD[Pos],Tabla3[[#This Row],[Part.]])+SUMIFS(BD.PD[Pago 3],BD.PD[Per.P3],D$1,BD.PD[Pos],Tabla3[[#This Row],[Part.]])+SUMIFS(BD.PD[Pago 4],BD.PD[Per.P4],D$1,BD.PD[Pos],Tabla3[[#This Row],[Part.]])+SUMIFS(BD.PD[Pago 5],BD.PD[Per.P5],D$1,BD.PD[Pos],Tabla3[[#This Row],[Part.]]) -> 0 | E15: =SUMIFS(BD.PD[Pago 1],BD.PD[Per.P1],E$1,BD.PD[Pos],Tabla3[[#This Row],[Part.]])+SUMIFS(BD.PD[Pago 2],BD.PD[Per.P2],E$1,BD.PD[Pos],Tabla3[[#This Row],[Part.]])+SUMIFS(BD.PD[Pago 3],BD.PD[Per.P3],E$1,BD.PD[Pos],Tabla3[[#This Row],[Part.]])+SUMIFS(BD.PD[Pago 4],BD.PD[Per.P4],E$1,BD.PD[Pos],Tabla3[[#This Row],[Part.]])+SUMIFS(BD.PD[Pago 5],BD.PD[Per.P5],E$1,BD.PD[Pos],Tabla3[[#This Row],[Part.]]) -> 0 | F15: =SUMIFS(BD.PD[Pago 1],BD.PD[Per.P1],F$1,BD.PD[Pos],Tabla3[[#This Row],[Part.]])+SUMIFS(BD.PD[Pago 2],BD.PD[Per.P2],F$1,BD.PD[Pos],Tabla3[[#This Row],[Part.]])+SUMIFS(BD.PD[Pago 3],BD.PD[Per.P3],F$1,BD.PD[Pos],Tabla3[[#This Row],[Part.]])+SUMIFS(BD.PD[Pago 4],BD.PD[Per.P4],F$1,BD.PD[Pos],Tabla3[[#This Row],[Part.]])+SUMIFS(BD.PD[Pago 5],BD.PD[Per.P5],F$1,BD.PD[Pos],Tabla3[[#This Row],[Part.]]) -> 0 | G15: =SUMIFS(BD.PD[Pago 1],BD.PD[Per.P1],G$1,BD.PD[Pos],Tabla3[[#This Row],[Part.]])+SUMIFS(BD.PD[Pago 2],BD.PD[Per.P2],G$1,BD.PD[Pos],Tabla3[[#This Row],[Part.]])+SUMIFS(BD.PD[Pago 3],BD.PD[Per.P3],G$1,BD.PD[Pos],Tabla3[[#This Row],[Part.]])+SUMIFS(BD.PD[Pago 4],BD.PD[Per.P4],G$1,BD.PD[Pos],Tabla3[[#This Row],[Part.]])+SUMIFS(BD.PD[Pago 5],BD.PD[Per.P5],G$1,BD.PD[Pos],Tabla3[[#This Row],[Part.]]) -> 0 | H15: =SUMIFS(BD.PD[Pago 1],BD.PD[Per.P1],H$1,BD.PD[Pos],Tabla3[[#This Row],[Part.]])+SUMIFS(BD.PD[Pago 2],BD.PD[Per.P2],H$1,BD.PD[Pos],Tabla3[[#This Row],[Part.]])+SUMIFS(BD.PD[Pago 3],BD.PD[Per.P3],H$1,BD.PD[Pos],Tabla3[[#This Row],[Part.]])+SUMIFS(BD.PD[Pago 4],BD.PD[Per.P4],H$1,BD.PD[Pos],Tabla3[[#This Row],[Part.]])+SUMIFS(BD.PD[Pago 5],BD.PD[Per.P5],H$1,BD.PD[Pos],Tabla3[[#This Row],[Part.]]) -> 0 | I15: =SUMIFS(BD.PD[Pago 1],BD.PD[Per.P1],I$1,BD.PD[Pos],Tabla3[[#This Row],[Part.]])+SUMIFS(BD.PD[Pago 2],BD.PD[Per.P2],I$1,BD.PD[Pos],Tabla3[[#This Row],[Part.]])+SUMIFS(BD.PD[Pago 3],BD.PD[Per.P3],I$1,BD.PD[Pos],Tabla3[[#This Row],[Part.]])+SUMIFS(BD.PD[Pago 4],BD.PD[Per.P4],I$1,BD.PD[Pos],Tabla3[[#This Row],[Part.]])+SUMIFS(BD.PD[Pago 5],BD.PD[Per.P5],I$1,BD.PD[Pos],Tabla3[[#This Row],[Part.]]) -> 0 | J15: =SUMIFS(BD.PD[Pago 1],BD.PD[Per.P1],J$1,BD.PD[Pos],Tabla3[[#This Row],[Part.]])+SUMIFS(BD.PD[Pago 2],BD.PD[Per.P2],J$1,BD.PD[Pos],Tabla3[[#This Row],[Part.]])+SUMIFS(BD.PD[Pago 3],BD.PD[Per.P3],J$1,BD.PD[Pos],Tabla3[[#This Row],[Part.]])+SUMIFS(BD.PD[Pago 4],BD.PD[Per.P4],J$1,BD.PD[Pos],Tabla3[[#This Row],[Part.]])+SUMIFS(BD.PD[Pago 5],BD.PD[Per.P5],J$1,BD.PD[Pos],Tabla3[[#This Row],[Part.]]) -> 0 | K15: =SUMIFS(BD.PD[Pago 1],BD.PD[Per.P1],K$1,BD.PD[Pos],Tabla3[[#This Row],[Part.]])+SUMIFS(BD.PD[Pago 2],BD.PD[Per.P2],K$1,BD.PD[Pos],Tabla3[[#This Row],[Part.]])+SUMIFS(BD.PD[Pago 3],BD.PD[Per.P3],K$1,BD.PD[Pos],Tabla3[[#This Row],[Part.]])+SUMIFS(BD.PD[Pago 4],BD.PD[Per.P4],K$1,BD.PD[Pos],Tabla3[[#This Row],[Part.]])+SUMIFS(BD.PD[Pago 5],BD.PD[Per.P5],K$1,BD.PD[Pos],Tabla3[[#This Row],[Part.]]) -> 0 | ... AA15: =SUMIFS(BD.PD[Pago 1],BD.PD[Per.P1],AA$1,BD.PD[Pos],Tabla3[[#This Row],[Part.]])+SUMIFS(BD.PD[Pago 2],BD.PD[Per.P2],AA$1,BD.PD[Pos],Tabla3[[#This Row],[Part.]])+SUMIFS(BD.PD[Pago 3],BD.PD[Per.P3],AA$1,BD.PD[Pos],Tabla3[[#This Row],[Part.]])+SUMIFS(BD.PD[Pago 4],BD.PD[Per.P4],AA$1,BD.PD[Pos],Tabla3[[#This Row],[Part.]])+SUMIFS(BD.PD[Pago 5],BD.PD[Per.P5],AA$1,BD.PD[Pos],Tabla3[[#This Row],[Part.]]) -> 0 | AB15: =SUM(Tabla3[[#This Row],[P1]:[P24]]) -> 0
A16: 2 | B16: =VLOOKUP(Tabla3[[#This Row],[Part.]],PPto[],3,FALSE) -> 2.00 Obra Civil | C16: =SUM(C17:C27) -> 15391355 | D16: =SUM(D17:D27) -> 0 | E16: =SUM(E17:E27) -> 0 | F16: =SUM(F17:F27) -> 2413668.7 | G16: =SUM(G17:G27) -> 0 | H16: =SUM(H17:H27) -> 2215515.8 | I16: =SUM(I17:I27) -> 0 | J16: =SUM(J17:J27) -> 0 | ... AA16: =SUM(AA17:AA27) -> 2847245 | AB16: =SUM(Tabla3[[#This Row],[P1]:[P24]]) -> 15391355
