Workbook
Name \4: #REF!
Name \4: #REF!
Name \4: #REF!
Name \6: #REF!
Name \6: #REF!
Name \6: #REF!
Name \A: #REF!
Name \A: #REF!
Name \A: #REF!
Name \E: #REF!
Name \E: #REF!
Name \I: #REF!
Name \I: #REF!
Name \M: #REF!
Name \M: #REF!
Name \N: #REF!
Name \N: #REF!
Name \O: #REF!
Name \O: #REF!
Name \U: #REF!
Name \U: #REF!
Name __DAT1: #REF!
Name __DAT10: #REF!
Name __DAT11: #REF!
Name __DAT12: #REF!
Name __DAT13: #REF!
Name __DAT14: #REF!
Name __DAT2: #REF!
Name __DAT3: #REF!
Name __DAT4: #REF!
Name __DAT5: #REF!
Name __DAT6: #REF!
Name __DAT7: #REF!
Name __DAT8: #REF!
Name __DAT9: #REF!
Name _DAT1: #REF!
Name _DAT10: #REF!
Name _DAT11: #REF!
Name _DAT12: #REF!
Name _DAT13: #REF!
Name _DAT14: #REF!
Name _DAT15: #REF!
Name _DAT16: #REF!
Name _DAT17: #REF!
Name _DAT18: #REF!
Name _DAT19: #REF!
Name _DAT2: #REF!
Name _DAT20: #REF!
Name _DAT21: #REF!
Name _DAT3: #REF!
Name _DAT4: #REF!
Name _DAT5: #REF!
Name _DAT6: #REF!
Name _DAT7: #REF!
Name _DAT8: #REF!
Name _DAT9: #REF!
Name ACERO: #REF!
Name ACERO: #REF!
Name ACERO: #REF!
Name ACERO: #REF!

Sheet Actualización

Sheet Plan OI
C1: Presupuesto Detallado - Propuesta para Sirena Compacta Mao
C2: Area de Compras de Activos
C3: 45512
C5: Fecha Version: 04/09/2029 | D5: Alto Nivel | E5: Plan detallado Aprobado | I5: Plan Detallado DOP | L5: Plan Detallado en ejecución
D6: Total Presupuesto [USD] | E6: Total Presupuesto [USD] | G6: Ppto OI [DOP] | H6: Ppto Capex [DOP] | I6: Total Iniciativa [DOP] | J6: Ppto OI [USD] | K6: Ppto Capex [USD] | L6: Total Iniciativa [USD]
C7: TOTAL GENERAL ESTIMADO | D7: =D10+D11+D12 -> 3179486.8 | E7: =E10+E11+E12 -> 2950565.9 | G7: =SUM(G10:G12) -> 1.8021213e+08 | H7: =SUM(H10:H12) -> 0 | I7: =H7+G7 -> 1.8021213e+08 | J7: =SUM(J10:J12) -> 2860509.9 | K7: =SUM(K10:K12) -> 0 | L7: =K7+J7 -> 2860509.9
C9: Resumen de Partidas
C10: EQUIPAMIENTO | D10: =SUMIF(PPto[Gran Part.],$C10,PPto[Total '[USD']]) -> 2901152.5 | E10: =SUMIF(PPto[Gran Part.],$C10,PPto[Total '[USD']3]) -> 2728452.2 | G10: =SUMIF(PPto[Gran Part.],$C10,PPto[Ppto. OI '[DOP']2]) -> 1.6825576e+08 | H10: =SUMIF(PPto[Gran Part.],$C10,PPto[Ppto. Capex '[DOP']]) -> 0 | I10: =SUMIF(PPto[Gran Part.],$C10,PPto[Total '[DOP']]) -> 1.6825576e+08 | J10: =SUMIF(PPto[Gran Part.],C10,PPto[Ppto. OI '[USD']]) -> 2670726.3 | K10: =SUMIF(PPto[Gran Part.],C10,PPto[Ppto. Capex '[USD']]) -> 0 | L10: =K10+J10 -> 2670726.3
C11: EDIFICACIÓN | D11: =SUMIF(PPto[Gran Part.],$C11,PPto[Total '[USD']]) -> 278334.38 | E11: =SUMIF(PPto[Gran Part.],$C11,PPto[Total '[USD']3]) -> 222113.72 | G11: =SUMIF(PPto[Gran Part.],$C11,PPto[Ppto. OI '[DOP']2]) -> 11956367 | H11: =SUMIF(PPto[Gran Part.],$C11,PPto[Ppto. Capex '[DOP']]) -> 0 | I11: =SUMIF(PPto[Gran Part.],$C11,PPto[Total '[DOP']]) -> 11956367 | J11: =SUMIF(PPto[Gran Part.],C11,PPto[Ppto. OI '[USD']]) -> 189783.61 | K11: =SUMIF(PPto[Gran Part.],C11,PPto[Ppto. Capex '[USD']]) -> 0 | L11: =K11+J11 -> 189783.61
C12: TERRENO | D12: 0 | E12: 0 | G12: =SUMIF(PPto[Gran Part.],$C12,PPto[Ppto. OI '[DOP']2]) -> 0 | H12: =SUMIF(PPto[Gran Part.],$C12,PPto[Ppto. Capex '[DOP']]) -> 0 | I12: =H12+G12 -> 0 | J12: =SUMIF(PPto[Gran Part.],C12,PPto[Ppto. OI '[USD']]) -> 0 | K12: =SUMIF(PPto[Gran Part.],C12,PPto[Ppto. Capex '[USD']]) -> 0 | L12: =K12+J12 -> 0
C13: Gasto | D13: 0 | E13: 0 | G13: =SUMIF(PPto[Gran Part.],$C13,PPto[Ppto. OI '[DOP']2]) -> 0 | H13: =SUMIF(PPto[Gran Part.],$C13,PPto[Ppto. Capex '[DOP']]) -> 0 | I13: =H13+G13 -> 0 | J13: =SUMIF(PPto[Gran Part.],C13,PPto[Ppto. OI '[USD']]) -> 0 | K13: =SUMIF(PPto[Gran Part.],C13,PPto[Ppto. Capex '[USD']]) -> 0 | L13: =K13+J13 -> 0
C15: Área de la Localidad
C16: M² Construcción
C17: M² Sala de Ventas
C18: M² Terreno
G19: OI | H19: Capex | J19: OI | K19: Capex
A20: Part. | B20: Gran Part. | C20: Edificación, Instalaciones y Equipamientos | D20: Total [USD] | E20: Total [USD]3 | F20: Columna2 | G20: Ppto. OI [DOP]2 | H20: Ppto. Capex [DOP] | I20: Total [DOP] | J20: Ppto. OI [USD] | K20: Ppto. Capex [USD] | L20: Total [USD]2 | M20: Columna1 | N20: Ahorro según ejecución
A21: 1 | C21: 1.00 Estudios Preliminares | D21: =SUM(D22:D28) -> 0 | E21: =SUM(E22:E28) -> 0 | G21: =SUM(G22:G30) -> 0 | H21: =SUM(H22:H30) -> 0 | I21: =PPto[[#This Row],[Ppto. Capex '[DOP']]]+PPto[[#This Row],[Ppto. OI '[DOP']2]] -> 0 | J21: =SUM(J22:J30) -> 0 | K21: =SUM(K22:K30) -> 0 | L21: =PPto[[#This Row],[Ppto. Capex '[USD']]]+PPto[[#This Row],[Ppto. OI '[USD']]] -> 0 | N21: =+PPto[[#This Row],[Total '[USD']3]]-PPto[[#This Row],[Total '[USD']2]] -> 0
A22: 1.01 | B22: Edificación | C22: 1.01 Diseño arquitectónico | D22: 0 | E22: 0 | G22: =SUMIFS(BD.PD[Ppto. Orden Interna '[DOP']],BD.PD[Pos],PPto[[#This Row],[Part.]],BD.PD[Tipo Ppto],G$19) -> 0 | H22: =SUMIFS(BD.PD[Ppto. Orden Interna '[DOP']],BD.PD[Pos],PPto[[#This Row],[Part.]],BD.PD[Tipo Ppto],H$19) -> 0 | I22: =PPto[[#This Row],[Ppto. Capex '[DOP']]]+PPto[[#This Row],[Ppto. OI '[DOP']2]] -> 0 | J22: =SUMIFS(BD.PD[Ppto. Orden Interna '[USD']],BD.PD[Pos],PPto[[#This Row],[Part.]],BD.PD[Tipo Ppto],J$19) -> 0 | K22: =SUMIFS(BD.PD[Ppto. Orden Interna '[USD']],BD.PD[Pos],PPto[[#This Row],[Part.]],BD.PD[Tipo Ppto],K$19) -> 0 | L22: =PPto[[#This Row],[Ppto. Capex '[USD']]]+PPto[[#This Row],[Ppto. OI '[USD']]] -> 0 | N22: =+PPto[[#This Row],[Total '[USD']3]]-PPto[[#This Row],[Total '[USD']2]] -> 0
A23: 1.02 | B23: Edificación | C23: 1.02 Diseño estructural | D23: 0 | E23: 0 | G23: =SUMIFS(BD.PD[Ppto. Orden Interna '[DOP']],BD.PD[Pos],PPto[[#This Row],[Part.]],BD.PD[Tipo Ppto],G$19) -> 0 | H23: =SUMIFS(BD.PD[Ppto. Orden Interna '[DOP']],BD.PD[Pos],PPto[[#This Row],[Part.]],BD.PD[Tipo Ppto],H$19) -> 0 | I23: =PPto[[#This Row],[Ppto. Capex '[DOP']]]+PPto[[#This Row],[Ppto. OI '[DOP']2]] -> 0 | J23: =SUMIFS(BD.PD[Ppto. Orden Interna '[USD']],BD.PD[Pos],PPto[[#This Row],[Part.]],BD.PD[Tipo Ppto],J$19) -> 0 | K23: =SUMIFS(BD.PD[Ppto. Orden Interna '[USD']],BD.PD[Pos],PPto[[#This Row],[Part.]],BD.PD[Tipo Ppto],K$19) -> 0 | L23: =PPto[[#This Row],[Ppto. Capex '[USD']]]+PPto[[#This Row],[Ppto. OI '[USD']]] -> 0 | N23: =+PPto[[#This Row],[Total '[USD']3]]-PPto[[#This Row],[Total '[USD']2]] -> 0
A24: 1.03 | B24: Edificación | C24: 1.03 Diseño electromecánico | D24: 0 | E24: 0 | G24: =SUMIFS(BD.PD[Ppto. Orden Interna '[DOP']],BD.PD[Pos],PPto[[#This Row],[Part.]],BD.PD[Tipo Ppto],G$19) -> 0 | H24: =SUMIFS(BD.PD[Ppto. Orden Interna '[DOP']],BD.PD[Pos],PPto[[#This Row],[Part.]],BD.PD[Tipo Ppto],H$19) -> 0 | I24: =PPto[[#This Row],[Ppto. Capex '[DOP']]]+PPto[[#This Row],[Ppto. OI '[DOP']2]] -> 0 | J24: =SUMIFS(BD.PD[Ppto. Orden Interna '[USD']],BD.PD[Pos],PPto[[#This Row],[Part.]],BD.PD[Tipo Ppto],J$19) -> 0 | K24: =SUMIFS(BD.PD[Ppto. Orden Interna '[USD']],BD.PD[Pos],PPto[[#This Row],[Part.]],BD.PD[Tipo Ppto],K$19) -> 0 | L24: =PPto[[#This Row],[Ppto. Capex '[USD']]]+PPto[[#This Row],[Ppto. OI '[USD']]] -> 0 | N24: =+PPto[[#This Row],[Total '[USD']3]]-PPto[[#This Row],[Total '[USD']2]] -> 0
A25: 1.04 | B25: Edificación | C25: 1.04 Diseño sanitario | D25: 0 | E25: 0 | G25: =SUMIFS(BD.PD[Ppto. Orden Interna '[DOP']],BD.PD[Pos],PPto[[#This Row],[Part.]],BD.PD[Tipo Ppto],G$19) -> 0 | H25: =SUMIFS(BD.PD[Ppto. Orden Interna '[DOP']],BD.PD[Pos],PPto[[#This Row],[Part.]],BD.PD[Tipo Ppto],H$19) -> 0 | I25: =PPto[[#This Row],[Ppto. Capex '[DOP']]]+PPto[[#This Row],[Ppto. OI '[DOP']2]] -> 0 | J25: =SUMIFS(BD.PD[Ppto. Orden Interna '[USD']],BD.PD[Pos],PPto[[#This Row],[Part.]],BD.PD[Tipo Ppto],J$19) -> 0 | K25: =SUMIFS(BD.PD[Ppto. Orden Interna '[USD']],BD.PD[Pos],PPto[[#This Row],[Part.]],BD.PD[Tipo Ppto],K$19) -> 0 | L25: =PPto[[#This Row],[Ppto. Capex '[USD']]]+PPto[[#This Row],[Ppto. OI '[USD']]] -> 0 | N25: =+PPto[[#This Row],[Total '[USD']3]]-PPto[[#This Row],[Total '[USD']2]] -> 0
A26: 1.05 | B26: Edificación | C26: 1.05 Estudio Geotécnico | D26: 0 | E26: 0 | G26: =SUMIFS(BD.PD[Ppto. Orden Interna '[DOP']],BD.PD[Pos],PPto[[#This Row],[Part.]],BD.PD[Tipo Ppto],G$19) -> 0 | H26: =SUMIFS(BD.PD[Ppto. Orden Interna '[DOP']],BD.PD[Pos],PPto[[#This Row],[Part.]],BD.PD[Tipo Ppto],H$19) -> 0 | I26: =PPto[[#This Row],[Ppto. Capex '[DOP']]]+PPto[[#This Row],[Ppto. OI '[DOP']2]] -> 0 | J26: =SUMIFS(BD.PD[Ppto. Orden Interna '[USD']],BD.PD[Pos],PPto[[#This Row],[Part.]],BD.PD[Tipo Ppto],J$19) -> 0 | K26: =SUMIFS(BD.PD[Ppto. Orden Interna '[USD']],BD.PD[Pos],PPto[[#This Row],[Part.]],BD.PD[Tipo Ppto],K$19) -> 0 | L26: =PPto[[#This Row],[Ppto. Capex '[USD']]]+PPto[[#This Row],[Ppto. OI '[USD']]] -> 0 | N26: =+PPto[[#This Row],[Total '[USD']3]]-PPto[[#This Row],[Total '[USD']2]] -> 0
A27: 1.06 | B27: Edificación | C27: 1.06 Levantamiento topográfico | D27: 0 | E27: 0 | G27: =SUMIFS(BD.PD[Ppto. Orden Interna '[DOP']],BD.PD[Pos],PPto[[#This Row],[Part.]],BD.PD[Tipo Ppto],G$19) -> 0 | H27: =SUMIFS(BD.PD[Ppto. Orden Interna '[DOP']],BD.PD[Pos],PPto[[#This Row],[Part.]],BD.PD[Tipo Ppto],H$19) -> 0 | I27: =PPto[[#This Row],[Ppto. Capex '[DOP']]]+PPto[[#This Row],[Ppto. OI '[DOP']2]] -> 0 | J27: =SUMIFS(BD.PD[Ppto. Orden Interna '[USD']],BD.PD[Pos],PPto[[#This Row],[Part.]],BD.PD[Tipo Ppto],J$19) -> 0 | K27: =SUMIFS(BD.PD[Ppto. Orden Interna '[USD']],BD.PD[Pos],PPto[[#This Row],[Part.]],BD.PD[Tipo Ppto],K$19) -> 0 | L27: =PPto[[#This Row],[Ppto. Capex '[USD']]]+PPto[[#This Row],[Ppto. OI '[USD']]] -> 0 | N27: =+PPto[[#This Row],[Total '[USD']3]]-PPto[[#This Row],[Total '[USD']2]] -> 0
A28: 1.07 | B28: Edificación | C28: 1.07 Permisos | D28: 0 | E28: 0 | G28: =SUMIFS(BD.PD[Ppto. Orden Interna '[DOP']],BD.PD[Pos],PPto[[#This Row],[Part.]],BD.PD[Tipo Ppto],G$19) -> 0 | H28: =SUMIFS(BD.PD[Ppto. Orden Interna '[DOP']],BD.PD[Pos],PPto[[#This Row],[Part.]],BD.PD[Tipo Ppto],H$19) -> 0 | I28: =PPto[[#This Row],[Ppto. Capex '[DOP']]]+PPto[[#This Row],[Ppto. OI '[DOP']2]] -> 0 | J28: =SUMIFS(BD.PD[Ppto. Orden Interna '[USD']],BD.PD[Pos],PPto[[#This Row],[Part.]],BD.PD[Tipo Ppto],J$19) -> 0 | K28: =SUMIFS(BD.PD[Ppto. Orden Interna '[USD']],BD.PD[Pos],PPto[[#This Row],[Part.]],BD.PD[Tipo Ppto],K$19) -> 0 | L28: =PPto[[#This Row],[Ppto. Capex '[USD']]]+PPto[[#This Row],[Ppto. OI '[USD']]] -> 0 | N28: =+PPto[[#This Row],[Total '[USD']3]]-PPto[[#This Row],[Total '[USD']2]] -> 0
A29: 1.08 | B29: Edificación | C29: 1.08 Diseño sistema contra incendios | D29: 0 | E29: 0 | G29: =SUMIFS(BD.PD[Ppto. Orden Interna '[DOP']],BD.PD[Pos],PPto[[#This Row],[Part.]],BD.PD[Tipo Ppto],G$19) -> 0 | H29: =SUMIFS(BD.PD[Ppto. Orden Interna '[DOP']],BD.PD[Pos],PPto[[#This Row],[Part.]],BD.PD[Tipo Ppto],H$19) -> 0 | I29: =PPto[[#This Row],[Ppto. Capex '[DOP']]]+PPto[[#This Row],[Ppto. OI '[DOP']2]] -> 0 | J29: =SUMIFS(BD.PD[Ppto. Orden Interna '[USD']],BD.PD[Pos],PPto[[#This Row],[Part.]],BD.PD[Tipo Ppto],J$19) -> 0 | K29: =SUMIFS(BD.PD[Ppto. Orden Interna '[USD']],BD.PD[Pos],PPto[[#This Row],[Part.]],BD.PD[Tipo Ppto],K$19) -> 0 | L29: =PPto[[#This Row],[Ppto. Capex '[USD']]]+PPto[[#This Row],[Ppto. OI '[USD']]] -> 0 | N29: =+PPto[[#This Row],[Total '[USD']3]]-PPto[[#This Row],[Total '[USD']2]] -> 0
A30: 1.09 | B30: Edificación | C30: 1.09 Diseño sistema gas | D30: 0 | E30: 0 | G30: =SUMIFS(BD.PD[Ppto. Orden Interna '[DOP']],BD.PD[Pos],PPto[[#This Row],[Part.]],BD.PD[Tipo Ppto],G$19) -> 0 | H30: =SUMIFS(BD.PD[Ppto. Orden Interna '[DOP']],BD.PD[Pos],PPto[[#This Row],[Part.]],BD.PD[Tipo Ppto],H$19) -> 0 | I30: =PPto[[#This Row],[Ppto. Capex '[DOP']]]+PPto[[#This Row],[Ppto. OI '[DOP']2]] -> 0 | J30: =SUMIFS(BD.PD[Ppto. Orden Interna '[USD']],BD.PD[Pos],PPto[[#This Row],[Part.]],BD.PD[Tipo Ppto],J$19) -> 0 | K30: =SUMIFS(BD.PD[Ppto. Orden Interna '[USD']],BD.PD[Pos],PPto[[#This Row],[Part.]],BD.PD[Tipo Ppto],K$19) -> 0 | L30: =PPto[[#This Row],[Ppto. Capex '[USD']]]+PPto[[#This Row],[Ppto. OI '[USD']]] -> 0 | N30: =+PPto[[#This Row],[Total '[USD']3]]-PPto[[#This Row],[Total '[USD']2]] -> 0
A31: 2 | C31: 2.00 Obra Civil | D31: =SUM(D32:D42) -> 278334.38 | E31: =SUM(E32:E42) -> 222113.72 | G31: =SUM(G32:G42) -> 11956367 | H31: =SUM(H32:H42) -> 0 | I31: =PPto[[#This Row],[Ppto. Capex '[DOP']]]+PPto[[#This Row],[Ppto. OI '[DOP']2]] -> 11956367 | J31: =SUM(J32:J42) -> 189783.61 | K31: =SUM(K32:K42) -> 0 | L31: =PPto[[#This Row],[Ppto. Capex '[USD']]]+PPto[[#This Row],[Ppto. OI '[USD']]] -> 189783.61
A32: 2.01 | B32: Edificación | C32: 2.01 Edificación - Obra Civil | D32: 161119.6 | E32: 8353.66 | G32: =SUMIFS(BD.PD[Ppto. Orden Interna '[DOP']],BD.PD[Pos],PPto[[#This Row],[Part.]],BD.PD[Tipo Ppto],G$19) -> 526280.58 | H32: =SUMIFS(BD.PD[Ppto. Orden Interna '[DOP']],BD.PD[Pos],PPto[[#This Row],[Part.]],BD.PD[Tipo Ppto],H$19) -> 0 | I32: =PPto[[#This Row],[Ppto. Capex '[DOP']]]+PPto[[#This Row],[Ppto. OI '[DOP']2]] -> 526280.58 | J32: =SUMIFS(BD.PD[Ppto. Orden Interna '[USD']],BD.PD[Pos],PPto[[#This Row],[Part.]],BD.PD[Tipo Ppto],J$19) -> 8353.66 | K32: =SUMIFS(BD.PD[Ppto. Orden Interna '[USD']],BD.PD[Pos],PPto[[#This Row],[Part.]],BD.PD[Tipo Ppto],K$19) -> 0 | L32: =PPto[[#This Row],[Ppto. Capex '[USD']]]+PPto[[#This Row],[Ppto. OI '[USD']]] -> 8353.66 | N32: =+PPto[[#This Row],[Total '[USD']3]]-PPto[[#This Row],[Total '[USD']2]] -> 0
A33: 2.02 | B33: Edificación | C33: 2.02 Edificación - Estructura Metálica | D33: 0 | E33: 0 | G33: =SUMIFS(BD.PD[Ppto. Orden Interna '[DOP']],BD.PD[Pos],PPto[[#This Row],[Part.]],BD.PD[Tipo Ppto],G$19) -> 0 | H33: =SUMIFS(BD.PD[Ppto. Orden Interna '[DOP']],BD.PD[Pos],PPto[[#This Row],[Part.]],BD.PD[Tipo Ppto],H$19) -> 0 | I33: =PPto[[#This Row],[Ppto. Capex '[DOP']]]+PPto[[#This Row],[Ppto. OI '[DOP']2]] -> 0 | J33: =SUMIFS(BD.PD[Ppto. Orden Interna '[USD']],BD.PD[Pos],PPto[[#This Row],[Part.]],BD.PD[Tipo Ppto],J$19) -> 0 | K33: =SUMIFS(BD.PD[Ppto. Orden Interna '[USD']],BD.PD[Pos],PPto[[#This Row],[Part.]],BD.PD[Tipo Ppto],K$19) -> 0 | L33: =PPto[[#This Row],[Ppto. Capex '[USD']]]+PPto[[#This Row],[Ppto. OI '[USD']]] -> 0 | N33: =+PPto[[#This Row],[Total '[USD']3]]-PPto[[#This Row],[Total '[USD']2]] -> 0
A34: 2.03 | B34: Edificación | C34: 2.03 Edificación - Techo S.S. y Cerramientos Multipanel | D34: 0 | E34: 0 | G34: =SUMIFS(BD.PD[Ppto. Orden Interna '[DOP']],BD.PD[Pos],PPto[[#This Row],[Part.]],BD.PD[Tipo Ppto],G$19) -> 0 | H34: =SUMIFS(BD.PD[Ppto. Orden Interna '[DOP']],BD.PD[Pos],PPto[[#This Row],[Part.]],BD.PD[Tipo Ppto],H$19) -> 0 | I34: =PPto[[#This Row],[Ppto. Capex '[DOP']]]+PPto[[#This Row],[Ppto. OI '[DOP']2]] -> 0 | J34: =SUMIFS(BD.PD[Ppto. Orden Interna '[USD']],BD.PD[Pos],PPto[[#This Row],[Part.]],BD.PD[Tipo Ppto],J$19) -> 0 | K34: =SUMIFS(BD.PD[Ppto. Orden Interna '[USD']],BD.PD[Pos],PPto[[#This Row],[Part.]],BD.PD[Tipo Ppto],K$19) -> 0 | L34: =PPto[[#This Row],[Ppto. Capex '[USD']]]+PPto[[#This Row],[Ppto. OI '[USD']]] -> 0 | N34: =+PPto[[#This Row],[Total '[USD']3]]-PPto[[#This Row],[Total '[USD']2]] -> 0
A35: 2.04 | B35: Edificación | C35: 2.04 Edificación - Tragaluces "Skylights" | D35: 0 | E35: 0 | G35: =SUMIFS(BD.PD[Ppto. Orden Interna '[DOP']],BD.PD[Pos],PPto[[#This Row],[Part.]],BD.PD[Tipo Ppto],G$19) -> 0 | H35: =SUMIFS(BD.PD[Ppto. Orden Interna '[DOP']],BD.PD[Pos],PPto[[#This Row],[Part.]],BD.PD[Tipo Ppto],H$19) -> 0 | I35: =PPto[[#This Row],[Ppto. Capex '[DOP']]]+PPto[[#This Row],[Ppto. OI '[DOP']2]] -> 0 | J35: =SUMIFS(BD.PD[Ppto. Orden Interna '[USD']],BD.PD[Pos],PPto[[#This Row],[Part.]],BD.PD[Tipo Ppto],J$19) -> 0 | K35: =SUMIFS(BD.PD[Ppto. Orden Interna '[USD']],BD.PD[Pos],PPto[[#This Row],[Part.]],BD.PD[Tipo Ppto],K$19) -> 0 | L35: =PPto[[#This Row],[Ppto. Capex '[USD']]]+PPto[[#This Row],[Ppto. OI '[USD']]] -> 0 | N35: =+PPto[[#This Row],[Total '[USD']3]]-PPto[[#This Row],[Total '[USD']2]] -> 0
A36: 2.05 | B36: Edificación | C36: 2.05 Instalaciones Sanitarias | D36: 25100 | E36: 15099.42 | G36: =SUMIFS(BD.PD[Ppto. Orden Interna '[DOP']],BD.PD[Pos],PPto[[#This Row],[Part.]],BD.PD[Tipo Ppto],G$19) -> 1071000 | H36: =SUMIFS(BD.PD[Ppto. Orden Interna '[DOP']],BD.PD[Pos],PPto[[#This Row],[Part.]],BD.PD[Tipo Ppto],H$19) -> 0 | I36: =PPto[[#This Row],[Ppto. Capex '[DOP']]]+PPto[[#This Row],[Ppto. OI '[DOP']2]] -> 1071000 | J36: =SUMIFS(BD.PD[Ppto. Orden Interna '[USD']],BD.PD[Pos],PPto[[#This Row],[Part.]],BD.PD[Tipo Ppto],J$19) -> 17000 | K36: =SUMIFS(BD.PD[Ppto. Orden Interna '[USD']],BD.PD[Pos],PPto[[#This Row],[Part.]],BD.PD[Tipo Ppto],K$19) -> 0 | L36: =PPto[[#This Row],[Ppto. Capex '[USD']]]+PPto[[#This Row],[Ppto. OI '[USD']]] -> 17000 | N36: =+PPto[[#This Row],[Total '[USD']3]]-PPto[[#This Row],[Total '[USD']2]] -> -1900.5797
A37: 2.06 | B37: Edificación | C37: 2.06 Instalación de Gas | D37: 0 | E37: 7260.3834 | G37: =SUMIFS(BD.PD[Ppto. Orden Interna '[DOP']],BD.PD[Pos],PPto[[#This Row],[Part.]],BD.PD[Tipo Ppto],G$19) -> 0 | H37: =SUMIFS(BD.PD[Ppto. Orden Interna '[DOP']],BD.PD[Pos],PPto[[#This Row],[Part.]],BD.PD[Tipo Ppto],H$19) -> 0 | I37: =PPto[[#This Row],[Ppto. Capex '[DOP']]]+PPto[[#This Row],[Ppto. OI '[DOP']2]] -> 0 | J37: =SUMIFS(BD.PD[Ppto. Orden Interna '[USD']],BD.PD[Pos],PPto[[#This Row],[Part.]],BD.PD[Tipo Ppto],J$19) -> 0 | K37: =SUMIFS(BD.PD[Ppto. Orden Interna '[USD']],BD.PD[Pos],PPto[[#This Row],[Part.]],BD.PD[Tipo Ppto],K$19) -> 0 | L37: =PPto[[#This Row],[Ppto. Capex '[USD']]]+PPto[[#This Row],[Ppto. OI '[USD']]] -> 0 | N37: =+PPto[[#This Row],[Total '[USD']3]]-PPto[[#This Row],[Total '[USD']2]] -> 7260.3834
A38: 2.07 | B38: Edificación | C38: 2.07 Sistema Contra Incendios | D38: 8266.7758 | E38: 114712.49 | G38: =SUMIFS(BD.PD[Ppto. Orden Interna '[DOP']],BD.PD[Pos],PPto[[#This Row],[Part.]],BD.PD[Tipo Ppto],G$19) -> 6294056 | H38: =SUMIFS(BD.PD[Ppto. Orden Interna '[DOP']],BD.PD[Pos],PPto[[#This Row],[Part.]],BD.PD[Tipo Ppto],H$19) -> 0 | I38: =PPto[[#This Row],[Ppto. Capex '[DOP']]]+PPto[[#This Row],[Ppto. OI '[DOP']2]] -> 6294056 | J38: =SUMIFS(BD.PD[Ppto. Orden Interna '[USD']],BD.PD[Pos],PPto[[#This Row],[Part.]],BD.PD[Tipo Ppto],J$19) -> 99905.65 | K38: =SUMIFS(BD.PD[Ppto. Orden Interna '[USD']],BD.PD[Pos],PPto[[#This Row],[Part.]],BD.PD[Tipo Ppto],K$19) -> 0 | L38: =PPto[[#This Row],[Ppto. Capex '[USD']]]+PPto[[#This Row],[Ppto. OI '[USD']]] -> 99905.65 | N38: =+PPto[[#This Row],[Total '[USD']3]]-PPto[[#This Row],[Total '[USD']2]] -> 14806.836
A39: 2.08 | B39: Edificación | C39: 2.08 Instalaciones Mecánicas | D39: 83848 | E39: 65014.422 | G39: =SUMIFS(BD.PD[Ppto. Orden Interna '[DOP']],BD.PD[Pos],PPto[[#This Row],[Part.]],BD.PD[Tipo Ppto],G$19) -> 3329609.7 | H39: =SUMIFS(BD.PD[Ppto. Orden Interna '[DOP']],BD.PD[Pos],PPto[[#This Row],[Part.]],BD.PD[Tipo Ppto],H$19) -> 0 | I39: =PPto[[#This Row],[Ppto. Capex '[DOP']]]+PPto[[#This Row],[Ppto. OI '[DOP']2]] -> 3329609.7 | J39: =SUMIFS(BD.PD[Ppto. Orden Interna '[USD']],BD.PD[Pos],PPto[[#This Row],[Part.]],BD.PD[Tipo Ppto],J$19) -> 52850.947 | K39: =SUMIFS(BD.PD[Ppto. Orden Interna '[USD']],BD.PD[Pos],PPto[[#This Row],[Part.]],BD.PD[Tipo Ppto],K$19) -> 0 | L39: =PPto[[#This Row],[Ppto. Capex '[USD']]]+PPto[[#This Row],[Ppto. OI '[USD']]] -> 52850.947 | N39: =+PPto[[#This Row],[Total '[USD']3]]-PPto[[#This Row],[Total '[USD']2]] -> 12163.475
A40: 2.09 | B40: Edificación | C40: 2.09 Rejillas y Sumideros | D40: 0 | E40: 11673.35 | G40: =SUMIFS(BD.PD[Ppto. Orden Interna '[DOP']],BD.PD[Pos],PPto[[#This Row],[Part.]],BD.PD[Tipo Ppto],G$19) -> 735421.05 | H40: =SUMIFS(BD.PD[Ppto. Orden Interna '[DOP']],BD.PD[Pos],PPto[[#This Row],[Part.]],BD.PD[Tipo Ppto],H$19) -> 0 | I40: =PPto[[#This Row],[Ppto. Capex '[DOP']]]+PPto[[#This Row],[Ppto. OI '[DOP']2]] -> 735421.05 | J40: =SUMIFS(BD.PD[Ppto. Orden Interna '[USD']],BD.PD[Pos],PPto[[#This Row],[Part.]],BD.PD[Tipo Ppto],J$19) -> 11673.35 | K40: =SUMIFS(BD.PD[Ppto. Orden Interna '[USD']],BD.PD[Pos],PPto[[#This Row],[Part.]],BD.PD[Tipo Ppto],K$19) -> 0 | L40: =PPto[[#This Row],[Ppto. Capex '[USD']]]+PPto[[#This Row],[Ppto. OI '[USD']]] -> 11673.35 | M40: Rejillas y sumideros del nuevo proveedor | N40: =+PPto[[#This Row],[Total '[USD']3]]-PPto[[#This Row],[Total '[USD']2]] -> 0
A41: 2.1 | B41: Edificación | C41: 2.10 Supervisión Civil y Sanitaria | D41: 0 | E41: 0 | G41: =SUMIFS(BD.PD[Ppto. Orden Interna '[DOP']],BD.PD[Pos],PPto[[#This Row],[Part.]],BD.PD[Tipo Ppto],G$19) -> 0 | H41: =SUMIFS(BD.PD[Ppto. Orden Interna '[DOP']],BD.PD[Pos],PPto[[#This Row],[Part.]],BD.PD[Tipo Ppto],H$19) -> 0 | I41: =PPto[[#This Row],[Ppto. Capex '[DOP']]]+PPto[[#This Row],[Ppto. OI '[DOP']2]] -> 0 | J41: =SUMIFS(BD.PD[Ppto. Orden Interna '[USD']],BD.PD[Pos],PPto[[#This Row],[Part.]],BD.PD[Tipo Ppto],J$19) -> 0 | K41: =SUMIFS(BD.PD[Ppto. Orden Interna '[USD']],BD.PD[Pos],PPto[[#This Row],[Part.]],BD.PD[Tipo Ppto],K$19) -> 0 | L41: =PPto[[#This Row],[Ppto. Capex '[USD']]]+PPto[[#This Row],[Ppto. OI '[USD']]] -> 0 | N41: =+PPto[[#This Row],[Total '[USD']3]]-PPto[[#This Row],[Total '[USD']2]] -> 0
A42: 2.11 | B42: Edificación | C42: 2.11 Supervisión Arquitectónica | D42: 0 | E42: 0 | G42: =SUMIFS(BD.PD[Ppto. Orden Interna '[DOP']],BD.PD[Pos],PPto[[#This Row],[Part.]],BD.PD[Tipo Ppto],G$19) -> 0 | H42: =SUMIFS(BD.PD[Ppto. Orden Interna '[DOP']],BD.PD[Pos],PPto[[#This Row],[Part.]],BD.PD[Tipo Ppto],H$19) -> 0 | I42: =PPto[[#This Row],[Ppto. Capex '[DOP']]]+PPto[[#This Row],[Ppto. OI '[DOP']2]] -> 0 | J42: =SUMIFS(BD.PD[Ppto. Orden Interna '[USD']],BD.PD[Pos],PPto[[#This Row],[Part.]],BD.PD[Tipo Ppto],J$19) -> 0 | K42: =SUMIFS(BD.PD[Ppto. Orden Interna '[USD']],BD.PD[Pos],PPto[[#This Row],[Part.]],BD.PD[Tipo Ppto],K$19) -> 0 | L42: =PPto[[#This Row],[Ppto. Capex '[USD']]]+PPto[[#This Row],[Ppto. OI '[USD']]] -> 0 | N42: =+PPto[[#This Row],[Total '[USD']3]]-PPto[[#This Row],[Total '[USD']2]] -> 0
A43: 3 | C43: 3.00 Sistema Eléctrico | D43: =SUM(D44:D47) -> 146108.56 | E43: =SUM(E44:E47) -> 180559.13 | G43: =SUM(G44:G47) -> 27933332 | H43: =SUM(H44:H47) -> 0 | I43: =PPto[[#This Row],[Ppto. Capex '[DOP']]]+PPto[[#This Row],[Ppto. OI '[DOP']2]] -> 27933332 | J43: =SUM(J44:J47) -> 443386.23 | K43: =SUM(K44:K47) -> 0 | L43: =PPto[[#This Row],[Ppto. Capex '[USD']]]+PPto[[#This Row],[Ppto. OI '[USD']]] -> 443386.23 | N43: =+PPto[[#This Row],[Total '[USD']3]]-PPto[[#This Row],[Total '[USD']2]] -> -262827.1
...

Sheet Hoja1
A3: Etiquetas de fila | B3: Suma de Ppto. Orden Interna [DOP] | C3: Suma de Ppto. Orden Interna [USD] | D3: Suma de Pago 1 | E3: Suma de Pago 2 | F3: Suma de Pago 3 | G3: Suma de Pago 4 | H3: Suma de Pago 5
A4: 2.01 Edificación - Obra Civil | B4: 395146.08 | C4: 6272.16 | D4: 197573.04 | E4: 197573.04 | F4: 0 | G4: 0 | H4: 0
A5: MARAZZI PISO PROGRESS ANTHRACITE 30X60MK | B5: 56758.968 | C5: 900.936 | D5: 28379.484 | E5: 28379.484 | F5: 0 | G5: 0 | H5: 0
A6: MARAZZI RAGNO CONCEPT GRIGIO 30X60CM | B6: 281195.71 | C6: 4463.424 | D6: 140597.86 | E6: 140597.86 | F6: 0 | G6: 0 | H6: 0
A7: MARAZZI REV MATERIKA STR SAT 3D 40X120MM | B7: 57191.4 | C7: 907.8 | D7: 28595.7 | E7: 28595.7 | F7: 0 | G7: 0 | H7: 0
A8: 2.05 Instalaciones Sanitarias | B8: 1071000 | C8: 17000 | D8: 535500 | E8: 535500 | F8: 0 | G8: 0 | H8: 0
A9: SISTEMA DE PURIFICACION DE AGUA COMPLETO | B9: 1071000 | C9: 17000 | D9: 535500 | E9: 535500 | F9: 0 | G9: 0 | H9: 0
A10: 2.06 Instalación de Gas | B10: 363276.8 | C10: 5766.2984 | D10: 181638.4 | E10: 181638.4 | F10: 0 | G10: 0 | H10: 0
A11: SISTEMA DETECCION GAS COCINA | B11: 363276.8 | C11: 5766.2984 | D11: 181638.4 | E11: 181638.4 | F11: 0 | G11: 0 | H11: 0
A12: 2.07 Sistema Contra Incendios | B12: 6895286.1 | C12: 109448.99 | D12: 4089545.3 | E12: 2805740.8 | F12: 0 | G12: 0 | H12: 0
A13: BOMBA SCI 1,500 GPM @145 PSI | B13: 5611481.6 | C13: 89071.136 | D13: 2805740.8 | E13: 2805740.8 | F13: 0 | G13: 0 | H13: 0
A14: COVER PARA EXTINTOR C02 10-20LBS | B14: 7635.6 | C14: 121.2 | D14: 7635.6 | E14: 0 | F14: 0 | G14: 0 | H14: 0
A15: EXTINTOR ABC HALOTRON AGENTE LIMPIO 11LB | B15: 211506.12 | C15: 3357.24 | D15: 211506.12 | E15: 0 | F15: 0 | G15: 0 | H15: 0
... A307: Total general | B307: 1.6632645e+08 | C307: 2640102.4 | D307: 90395093 | E307: 75931357 | F307: 0 | G307: 0 | H307: 0

Sheet Flujo de Caja
D1: 1 | E1: 2 | F1: 3 | G1: 4 | H1: 5 | I1: 6 | J1: 7 | K1: 8 | L1: 9 | M1: 10 | N1: 11 | O1: 12 | P1: 13 | Q1: 14 | R1: 15 | S1: 16 | T1: 17 | U1: 18 | V1: 19 | W1: 20 | X1: 21 | Y1: 22 | Z1: 23 | AA1: 24 | AB1: 25 | AC1: 26 | AD1: 27 | AE1: 28 | AF1: 29 | AG1: 30
AH2: Rojo: La sumatoria de pagos no coincide con Ppto.
B3: Apertura Noviembre 2026 | D3: Flujo de Caja Iniciativa
B4: ='Plan OI'!C1 -> Presupuesto Detallado - Propuesta para Sirena Compacta Mao | D4: Enero | E4: Febrero | F4: Marzo | G4: Abril | H4: Mayo | I4: Junio | J4: Julio | K4: Agosto | L4: Septiembre | M4: Octubre | N4: Noviembre | O4: Diciembre | P4: Enero | Q4: Febrero | R4: Marzo | S4: Abril | T4: Mayo | U4: Junio | V4: Julio | W4: Agosto | X4: Septiembre | Y4: Octubre | Z4: Noviembre | AA4: Diciembre
A5: Part. | B5: Edificación, Instalaciones y Equipamientos | C5: Ppto OI [DOP] | D5: P1 | E5: P2 | F5: P3 | G5: P4 | H5: P5 | I5: P6 | J5: P7 | K5: P8 | L5: P9 | M5: P10 | N5: P11 | O5: P12 | P5: P13 | Q5: P14 | R5: P15 | S5: P16 | T5: P17 | U5: P18 | V5: P19 | W5: P20 | X5: P21 | Y5: P22 | Z5: P23 | AA5: P24 | AB5: P245 | AC5: P246 | AD5: P243 | AE5: P244 | AF5: P242 | AG5: P25 | AH5: Total Ppto.
A6: 1 | B6: =VLOOKUP(Tabla3[[#This Row],[Part.]],PPto[],3,FALSE) -> 1.00 Estudios Preliminares | C6: =SUM(C7:C15) -> 0 | D6: =SUM(D7:D15) -> 0 | E6: =SUM(E7:E15) -> 0 | F6: =SUM(F7:F15) -> 0 | G6: =SUM(G7:G15) -> 0 | H6: =SUM(H7:H15) -> 0 | I6: =SUM(I7:I15) -> 0 | J6: =SUM(J7:J15) -> 0 | ... AA6: =SUM(AA7:AA15) -> 0 | AB6: =SUMIFS(BD.PD[Pago 1],BD.PD[Per.P1],AB$1,BD.PD[Pos],Tabla3[[#This Row],[Part.]])+SUMIFS(BD.PD[Pago 2],BD.PD[Per.P2],AB$1,BD.PD[Pos],Tabla3[[#This Row],[Part.]])+SUMIFS(BD.PD[Pago 3],BD.PD[Per.P3],AB$1,BD.PD[Pos],Tabla3[[#This Row],[Part.]])+SUMIFS(BD.PD[Pago 4],BD.PD[Per.P4],AB$1,BD.PD[Pos],Tabla3[[#This Row],[Part.]])+SUMIFS(BD.PD[Pago 5],BD.PD[Per.P5],AB$1,BD.PD[Pos],Tabla3[[#This Row],[Part.]]) -> 0 | AC6: =SUMIFS(BD.PD[Pago 1],BD.PD[Per.P1],AC$1,BD.PD[Pos],Tabla3[[#This Row],[Part.]])+SUMIFS(BD.PD[Pago 2],BD.PD[Per.P2],AC$1,BD.PD[Pos],Tabla3[[#This Row],[Part.]])+SUMIFS(BD.PD[Pago 3],BD.PD[Per.P3],AC$1,BD.PD[Pos],Tabla3[[#This Row],[Part.]])+SUMIFS(BD.PD[Pago 4],BD.PD[Per.P4],AC$1,BD.PD[Pos],Tabla3[[#This Row],[Part.]])+SUMIFS(BD.PD[Pago 5],BD.PD[Per.P5],AC$1,BD.PD[Pos],Tabla3[[#This Row],[Part.]]) -> 0 | AD6: =SUMIFS(BD.PD[Pago 1],BD.PD[Per.P1],AD$1,BD.PD[Pos],Tabla3[[#This Row],[Part.]])+SUMIFS(BD.PD[Pago 2],BD.PD[Per.P2],AD$1,BD.PD[Pos],Tabla3[[#This Row],[Part.]])+SUMIFS(BD.PD[Pago 3],BD.PD[Per.P3],AD$1,BD.PD[Pos],Tabla3[[#This Row],[Part.]])+SUMIFS(BD.PD[Pago 4],BD.PD[Per.P4],AD$1,BD.PD[Pos],Tabla3[[#This Row],[Part.]])+SUMIFS(BD.PD[Pago 5],BD.PD[Per.P5],AD$1,BD.PD[Pos],Tabla3[[#This Row],[Part.]]) -> 0 | AE6: =SUMIFS(BD.PD[Pago 1],BD.PD[Per.P1],AE$1,BD.PD[Pos],Tabla3[[#This Row],[Part.]])+SUMIFS(BD.PD[Pago 2],BD.PD[Per.P2],AE$1,BD.PD[Pos],Tabla3[[#This Row],[Part.]])+SUMIFS(BD.PD[Pago 3],BD.PD[Per.P3],AE$1,BD.PD[Pos],Tabla3[[#This Row],[Part.]])+SUMIFS(BD.PD[Pago 4],BD.PD[Per.P4],AE$1,BD.PD[Pos],Tabla3[[#This Row],[Part.]])+SUMIFS(BD.PD[Pago 5],BD.PD[Per.P5],AE$1,BD.PD[Pos],Tabla3[[#This Row],[Part.]]) -> 0 | AF6: =SUMIFS(BD.PD[Pago 1],BD.PD[Per.P1],AF$1,BD.PD[Pos],Tabla3[[#This Row],[Part.]])+SUMIFS(BD.PD[Pago 2],BD.PD[Per.P2],AF$1,BD.PD[Pos],Tabla3[[#This Row],[Part.]])+SUMIFS(BD.PD[Pago 3],BD.PD[Per.P3],AF$1,BD.PD[Pos],Tabla3[[#This Row],[Part.]])+SUMIFS(BD.PD[Pago 4],BD.PD[Per.P4],AF$1,BD.PD[Pos],Tabla3[[#This Row],[Part.]])+SUMIFS(BD.PD[Pago 5],BD.PD[Per.P5],AF$1,BD.PD[Pos],Tabla3[[#This Row],[Part.]]) -> 0 | AG6: =SUMIFS(BD.PD[Pago 1],BD.PD[Per.P1],AG$1,BD.PD[Pos],Tabla3[[#This Row],[Part.]])+SUMIFS(BD.PD[Pago 2],BD.PD[Per.P2],AG$1,BD.PD[Pos],Tabla3[[#This Row],[Part.]])+SUMIFS(BD.PD[Pago 3],BD.PD[Per.P3],AG$1,BD.PD[Pos],Tabla3[[#This Row],[Part.]])+SUMIFS(BD.PD[Pago 4],BD.PD[Per.P4],AG$1,BD.PD[Pos],Tabla3[[#This Row],[Part.]])+SUMIFS(BD.PD[Pago 5],BD.PD[Per.P5],AG$1,BD.PD[Pos],Tabla3[[#This Row],[Part.]]) -> 0 | AH6: =SUM(Tabla3[[#This Row],[P1]:[P24]]) -> 0
A7: 1.01 | B7: =VLOOKUP(Tabla3[[#This Row],[Part.]],PPto[],3,FALSE) -> 1.01 Diseño arquitectónico | C7: =SUMIF(BD.PD[Pos],Tabla3[[#This Row],[Part.]],BD.PD[Ppto. Orden Interna '[DOP']]) -> 0 | D7: =SUMIFS(BD.PD[Pago 1],BD.PD[Per.P1],D$1,BD.PD[Pos],Tabla3[[#This Row],[Part.]])+SUMIFS(BD.PD[Pago 2],BD.PD[Per.P2],D$1,BD.PD[Pos],Tabla3[[#This Row],[Part.]])+SUMIFS(BD.PD[Pago 3],BD.PD[Per.P3],D$1,BD.PD[Pos],Tabla3[[#This Row],[Part.]])+SUMIFS(BD.PD[Pago 4],BD.PD[Per.P4],D$1,BD.PD[Pos],Tabla3[[#This Row],[Part.]])+SUMIFS(BD.PD[Pago 5],BD.PD[Per.P5],D$1,BD.PD[Pos],Tabla3[[#This Row],[Part.]]) -> 0 | E7: =SUMIFS(BD.PD[Pago 1],BD.PD[Per.P1],E$1,BD.PD[Pos],Tabla3[[#This Row],[Part.]])+SUMIFS(BD.PD[Pago 2],BD.PD[Per.P2],E$1,BD.PD[Pos],Tabla3[[#This Row],[Part.]])+SUMIFS(BD.PD[Pago 3],BD.PD[Per.P3],E$1,BD.PD[Pos],Tabla3[[#This Row],[Part.]])+SUMIFS(BD.PD[Pago 4],BD.PD[Per.P4],E$1,BD.PD[Pos],Tabla3[[#This Row],[Part.]])+SUMIFS(BD.PD[Pago 5],BD.PD[Per.P5],E$1,BD.PD[Pos],Tabla3[[#This Row],[Part.]]) -> 0 | F7: =SUMIFS(BD.PD[Pago 1],BD.PD[Per.P1],F$1,BD.PD[Pos],Tabla3[[#This Row],[Part.]])+SUMIFS(BD.PD[Pago 2],BD.PD[Per.P2],F$1,BD.PD[Pos],Tabla3[[#This Row],[Part.]])+SUMIFS(BD.PD[Pago 3],BD.PD[Per.P3],F$1,BD.PD[Pos],Tabla3[[#This Row],[Part.]])+SUMIFS(BD.PD[Pago 4],BD.PD[Per.P4],F$1,BD.PD[Pos],Tabla3[[#This Row],[Part.]])+SUMIFS(BD.PD[Pago 5],BD.PD[Per.P5],F$1,BD.PD[Pos],Tabla3[[#This Row],[Part.]]) -> 0 | G7: =SUMIFS(BD.PD[Pago 1],BD.PD[Per.P1],G$1,BD.PD[Pos],Tabla3[[#This Row],[Part.]])+SUMIFS(BD.PD[Pago 2],BD.PD[Per.P2],G$1,BD.PD[Pos],Tabla3[[#This Row],[Part.]])+SUMIFS(BD.PD[Pago 3],BD.PD[Per.P3],G$1,BD.PD[Pos],Tabla3[[#This Row],[Part.]])+SUMIFS(BD.PD[Pago 4],BD.PD[Per.P4],G$1,BD.PD[Pos],Tabla3[[#This Row],[Part.]])+SUMIFS(BD.PD[Pago 5],BD.PD[Per.P5],G$1,BD.PD[Pos],Tabla3[[#This Row],[Part.]]) -> 0 | H7: =SUMIFS(BD.PD[Pago 1],BD.PD[Per.P1],H$1,BD.PD[Pos],Tabla3[[#This Row],[Part.]])+SUMIFS(BD.PD[Pago 2],BD.PD[Per.P2],H$1,BD.PD[Pos],Tabla3[[#This Row],[Part.]])+SUMIFS(BD.PD[Pago 3],BD.PD[Per.P3],H$1,BD.PD[Pos],Tabla3[[#This Row],[Part.]])+SUMIFS(BD.PD[Pago 4],BD.PD[Per.P4],H$1,BD.PD[Pos],Tabla3[[#This Row],[Part.]])+SUMIFS(BD.PD[Pago 5],BD.PD[Per.P5],H$1,BD.PD[Pos],Tabla3[[#This Row],[Part.]]) -> 0 | I7: =SUMIFS(BD.PD[Pago 1],BD.PD[Per.P1],I$1,BD.PD[Pos],Tabla3[[#This Row],[Part.]])+SUMIFS(BD.PD[Pago 2],BD.PD[Per.P2],I$1,BD.PD[Pos],Tabla3[[#This Row],[Part.]])+SUMIFS(BD.PD[Pago 3],BD.PD[Per.P3],I$1,BD.PD[Pos],Tabla3[[#This Row],[Part.]])+SUMIFS(BD.PD[Pago 4],BD.PD[Per.P4],I$1,BD.PD[Pos],Tabla3[[#This Row],[Part.]])+SUMIFS(BD.PD[Pago 5],BD.PD[Per.P5],I$1,BD.PD[Pos],Tabla3[[#This Row],[Part.]]) -> 0 | J7: =SUMIFS(BD.PD[Pago 1],BD.PD[Per.P1],J$1,BD.PD[Pos],Tabla3[[#This Row],[Part.]])+SUMIFS(BD.PD[Pago 2],BD.PD[Per.P2],J$1,BD.PD[Pos],Tabla3[[#This Row],[Part.]])+SUMIFS(BD.PD[Pago 3],BD.PD[Per.P3],J$1,BD.PD[Pos],Tabla3[[#This Row],[Part.]])+SUMIFS(BD.PD[Pago 4],BD.PD[Per.P4],J$1,BD.PD[Pos],Tabla3[[#This Row],[Part.]])+SUMIFS(BD.PD[Pago 5],BD.PD[Per.P5],J$1,BD.PD[Pos],Tabla3[[#This Row],[Part.]]) -> 0 | K7: =SUMIFS(BD.PD[Pago 1],BD.PD[Per.P1],K$1,BD.PD[Pos],Tabla3[[#This Row],[Part.]])+SUMIFS(BD.PD[Pago 2],BD.PD[Per.P2],K$1,BD.PD[Pos],Tabla3[[#This Row],[Part.]])+SUMIFS(BD.PD[Pago 3],BD.PD[Per.P3],K$1,BD.PD[Pos],Tabla3[[#This Row],[Part.]])+SUMIFS(BD.PD[Pago 4],BD.PD[Per.P4],K$1,BD.PD[Pos],Tabla3[[#This Row],[Part.]])+SUMIFS(BD.PD[Pago 5],BD.PD[Per.P5],K$1,BD.PD[Pos],Tabla3[[#This Row],[Part.]]) -> 0 | ... AG7: =SUMIFS(BD.PD[Pago 1],BD.PD[Per.P1],AG$1,BD.PD[Pos],Tabla3[[#This Row],[Part.]])+SUMIFS(BD.PD[Pago 2],BD.PD[Per.P2],AG$1,BD.PD[Pos],Tabla3[[#This Row],[Part.]])+SUMIFS(BD.PD[Pago 3],BD.PD[Per.P3],AG$1,BD.PD[Pos],Tabla3[[#This Row],[Part.]])+SUMIFS(BD.PD[Pago 4],BD.PD[Per.P4],AG$1,BD.PD[Pos],Tabla3[[#This Row],[Part.]])+SUMIFS(BD.PD[Pago 5],BD.PD[Per.P5],AG$1,BD.PD[Pos],Tabla3[[#This Row],[Part.]]) -> 0 | AH7: =SUM(Tabla3[[#This Row],[P1]:[P24]]) -> 0
A8: 1.02 | B8: =VLOOKUP(Tabla3[[#This Row],[Part.]],PPto[],3,FALSE) -> 1.02 Diseño estructural | C8: =SUMIF(BD.PD[Pos],Tabla3[[#This Row],[Part.]],BD.PD[Ppto. Orden Interna '[DOP']]) -> 0 | D8: =SUMIFS(BD.PD[Pago 1],BD.PD[Per.P1],D$1,BD.PD[Pos],Tabla3[[#This Row],[Part.]])+SUMIFS(BD.PD[Pago 2],BD.PD[Per.P2],D$1,BD.PD[Pos],Tabla3[[#This Row],[Part.]])+SUMIFS(BD.PD[Pago 3],BD.PD[Per.P3],D$1,BD.PD[Pos],Tabla3[[#This Row],[Part.]])+SUMIFS(BD.PD[Pago 4],BD.PD[Per.P4],D$1,BD.PD[Pos],Tabla3[[#This Row],[Part.]])+SUMIFS(BD.PD[Pago 5],BD.PD[Per.P5],D$1,BD.PD[Pos],Tabla3[[#This Row],[Part.]]) -> 0 | E8: =SUMIFS(BD.PD[Pago 1],BD.PD[Per.P1],E$1,BD.PD[Pos],Tabla3[[#This Row],[Part.]])+SUMIFS(BD.PD[Pago 2],BD.PD[Per.P2],E$1,BD.PD[Pos],Tabla3[[#This Row],[Part.]])+SUMIFS(BD.PD[Pago 3],BD.PD[Per.P3],E$1,BD.PD[Pos],Tabla3[[#This Row],[Part.]])+SUMIFS(BD.PD[Pago 4],BD.PD[Per.P4],E$1,BD.PD[Pos],Tabla3[[#This Row],[Part.]])+SUMIFS(BD.PD[Pago 5],BD.PD[Per.P5],E$1,BD.PD[Pos],Tabla3[[#This Row],[Part.]]) -> 0 | F8: =SUMIFS(BD.PD[Pago 1],BD.PD[Per.P1],F$1,BD.PD[Pos],Tabla3[[#This Row],[Part.]])+SUMIFS(BD.PD[Pago 2],BD.PD[Per.P2],F$1,BD.PD[Pos],Tabla3[[#This Row],[Part.]])+SUMIFS(BD.PD[Pago 3],BD.PD[Per.P3],F$1,BD.PD[Pos],Tabla3[[#This Row],[Part.]])+SUMIFS(BD.PD[Pago 4],BD.PD[Per.P4],F$1,BD.PD[Pos],Tabla3[[#This Row],[Part.]])+SUMIFS(BD.PD[Pago 5],BD.PD[Per.P5],F$1,BD.PD[Pos],Tabla3[[#This Row],[Part.]]) -> 0 | G8: =SUMIFS(BD.PD[Pago 1],BD.PD[Per.P1],G$1,BD.PD[Pos],Tabla3[[#This Row],[Part.]])+SUMIFS(BD.PD[Pago 2],BD.PD[Per.P2],G$1,BD.PD[Pos],Tabla3[[#This Row],[Part.]])+SUMIFS(BD.PD[Pago 3],BD.PD[Per.P3],G$1,BD.PD[Pos],Tabla3[[#This Row],[Part.]])+SUMIFS(BD.PD[Pago 4],BD.PD[Per.P4],G$1,BD.PD[Pos],Tabla3[[#This Row],[Part.]])+SUMIFS(BD.PD[Pago 5],BD.PD[Per.P5],G$1,BD.PD[Pos],Tabla3[[#This Row],[Part.]]) -> 0 | H8: =SUMIFS(BD.PD[Pago 1],BD.PD[Per.P1],H$1,BD.PD[Pos],Tabla3[[#This Row],[Part.]])+SUMIFS(BD.PD[Pago 2],BD.PD[Per.P2],H$1,BD.PD[Pos],Tabla3[[#This Row],[Part.]])+SUMIFS(BD.PD[Pago 3],BD.PD[Per.P3],H$1,BD.PD[Pos],Tabla3[[#This Row],[Part.]])+SUMIFS(BD.PD[Pago 4],BD.PD[Per.P4],H$1,BD.PD[Pos],Tabla3[[#This Row],[Part.]])+SUMIFS(BD.PD[Pago 5],BD.PD[Per.P5],H$1,BD.PD[Pos],Tabla3[[#This Row],[Part.]]) -> 0 | I8: =SUMIFS(BD.PD[Pago 1],BD.PD[Per.P1],I$1,BD.PD[Pos],Tabla3[[#This Row],[Part.]])+SUMIFS(BD.PD[Pago 2],BD.PD[Per.P2],I$1,BD.PD[Pos],Tabla3[[#This Row],[Part.]])+SUMIFS(BD.PD[Pago 3],BD.PD[Per.P3],I$1,BD.PD[Pos],Tabla3[[#This Row],[Part.]])+SUMIFS(BD.PD[Pago 4],BD.PD[Per.P4],I$1,BD.PD[Pos],Tabla3[[#This Row],[Part.]])+SUMIFS(BD.PD[Pago 5],BD.PD[Per.P5],I$1,BD.PD[Pos],Tabla3[[#This Row],[Part.]]) -> 0 | J8: =SUMIFS(BD.PD[Pago 1],BD.PD[Per.P1],J$1,BD.PD[Pos],Tabla3[[#This Row],[Part.]])+SUMIFS(BD.PD[Pago 2],BD.PD[Per.P2],J$1,BD.PD[Pos],Tabla3[[#This Row],[Part.]])+SUMIFS(BD.PD[Pago 3],BD.PD[Per.P3],J$1,BD.PD[Pos],Tabla3[[#This Row],[Part.]])+SUMIFS(BD.PD[Pago 4],BD.PD[Per.P4],J$1,BD.PD[Pos],Tabla3[[#This Row],[Part.]])+SUMIFS(BD.PD[Pago 5],BD.PD[Per.P5],J$1,BD.PD[Pos],Tabla3[[#This Row],[Part.]]) -> 0 | K8: =SUMIFS(BD.PD[Pago 1],BD.PD[Per.P1],K$1,BD.PD[Pos],Tabla3[[#This Row],[Part.]])+SUMIFS(BD.PD[Pago 2],BD.PD[Per.P2],K$1,BD.PD[Pos],Tabla3[[#This Row],[Part.]])+SUMIFS(BD.PD[Pago 3],BD.PD[Per.P3],K$1,BD.PD[Pos],Tabla3[[#This Row],[Part.]])+SUMIFS(BD.PD[Pago 4],BD.PD[Per.P4],K$1,BD.PD[Pos],Tabla3[[#This Row],[Part.]])+SUMIFS(BD.PD[Pago 5],BD.PD[Per.P5],K$1,BD.PD[Pos],Tabla3[[#This Row],[Part.]]) -> 0 | ... AG8: =SUMIFS(BD.PD[Pago 1],BD.PD[Per.P1],AG$1,BD.PD[Pos],Tabla3[[#This Row],[Part.]])+SUMIFS(BD.PD[Pago 2],BD.PD[Per.P2],AG$1,BD.PD[Pos],Tabla3[[#This Row],[Part.]])+SUMIFS(BD.PD[Pago 3],BD.PD[Per.P3],AG$1,BD.PD[Pos],Tabla3[[#This Row],[Part.]])+SUMIFS(BD.PD[Pago 4],BD.PD[Per.P4],AG$1,BD.PD[Pos],Tabla3[[#This Row],[Part.]])+SUMIFS(BD.PD[Pago 5],BD.PD[Per.P5],AG$1,BD.PD[Pos],Tabla3[[#This Row],[Part.]]) -> 0 | AH8: =SUM(Tabla3[[#This Row],[P1]:[P24]]) -> 0
A9: 1.03 | B9: =VLOOKUP(Tabla3[[#This Row],[Part.]],PPto[],3,FALSE) -> 1.03 Diseño electromecánico | C9: =SUMIF(BD.PD[Pos],Tabla3[[#This Row],[Part.]],BD.PD[Ppto. Orden Interna '[DOP']]) -> 0 | D9: =SUMIFS(BD.PD[Pago 1],BD.PD[Per.P1],D$1,BD.PD[Pos],Tabla3[[#This Row],[Part.]])+SUMIFS(BD.PD[Pago 2],BD.PD[Per.P2],D$1,BD.PD[Pos],Tabla3[[#This Row],[Part.]])+SUMIFS(BD.PD[Pago 3],BD.PD[Per.P3],D$1,BD.PD[Pos],Tabla3[[#This Row],[Part.]])+SUMIFS(BD.PD[Pago 4],BD.PD[Per.P4],D$1,BD.PD[Pos],Tabla3[[#This Row],[Part.]])+SUMIFS(BD.PD[Pago 5],BD.PD[Per.P5],D$1,BD.PD[Pos],Tabla3[[#This Row],[Part.]]) -> 0 | E9: =SUMIFS(BD.PD[Pago 1],BD.PD[Per.P1],E$1,BD.PD[Pos],Tabla3[[#This Row],[Part.]])+SUMIFS(BD.PD[Pago 2],BD.PD[Per.P2],E$1,BD.PD[Pos],Tabla3[[#This Row],[Part.]])+SUMIFS(BD.PD[Pago 3],BD.PD[Per.P3],E$1,BD.PD[Pos],Tabla3[[#This Row],[Part.]])+SUMIFS(BD.PD[Pago 4],BD.PD[Per.P4],E$1,BD.PD[Pos],Tabla3[[#This Row],[Part.]])+SUMIFS(BD.PD[Pago 5],BD.PD[Per.P5],E$1,BD.PD[Pos],Tabla3[[#This Row],[Part.]]) -> 0 | F9: =SUMIFS(BD.PD[Pago 1],BD.PD[Per.P1],F$1,BD.PD[Pos],Tabla3[[#This Row],[Part.]])+SUMIFS(BD.PD[Pago 2],BD.PD[Per.P2],F$1,BD.PD[Pos],Tabla3[[#This Row],[Part.]])+SUMIFS(BD.PD[Pago 3],BD.PD[Per.P3],F$1,BD.PD[Pos],Tabla3[[#This Row],[Part.]])+SUMIFS(BD.PD[Pago 4],BD.PD[Per.P4],F$1,BD.PD[Pos],Tabla3[[#This Row],[Part.]])+SUMIFS(BD.PD[Pago 5],BD.PD[Per.P5],F$1,BD.PD[Pos],Tabla3[[#This Row],[Part.]]) -> 0 | G9: =SUMIFS(BD.PD[Pago 1],BD.PD[Per.P1],G$1,BD.PD[Pos],Tabla3[[#This Row],[Part.]])+SUMIFS(BD.PD[Pago 2],BD.PD[Per.P2],G$1,BD.PD[Pos],Tabla3[[#This Row],[Part.]])+SUMIFS(BD.PD[Pago 3],BD.PD[Per.P3],G$1,BD.PD[Pos],Tabla3[[#This Row],[Part.]])+SUMIFS(BD.PD[Pago 4],BD.PD[Per.P4],G$1,BD.PD[Pos],Tabla3[[#This Row],[Part.]])+SUMIFS(BD.PD[Pago 5],BD.PD[Per.P5],G$1,BD.PD[Pos],Tabla3[[#This Row],[Part.]]) -> 0 | H9: =SUMIFS(BD.PD[Pago 1],BD.PD[Per.P1],H$1,BD.PD[Pos],Tabla3[[#This Row],[Part.]])+SUMIFS(BD.PD[Pago 2],BD.PD[Per.P2],H$1,BD.PD[Pos],Tabla3[[#This Row],[Part.]])+SUMIFS(BD.PD[Pago 3],BD.PD[Per.P3],H$1,BD.PD[Pos],Tabla3[[#This Row],[Part.]])+SUMIFS(BD.PD[Pago 4],BD.PD[Per.P4],H$1,BD.PD[Pos],Tabla3[[#This Row],[Part.]])+SUMIFS(BD.PD[Pago 5],BD.PD[Per.P5],H$1,BD.PD[Pos],Tabla3[[#This Row],[Part.]]) -> 0 | I9: =SUMIFS(BD.PD[Pago 1],BD.PD[Per.P1],I$1,BD.PD[Pos],Tabla3[[#This Row],[Part.]])+SUMIFS(BD.PD[Pago 2],BD.PD[Per.P2],I$1,BD.PD[Pos],Tabla3[[#This Row],[Part.]])+SUMIFS(BD.PD[Pago 3],BD.PD[Per.P3],I$1,BD.PD[Pos],Tabla3[[#This Row],[Part.]])+SUMIFS(BD.PD[Pago 4],BD.PD[Per.P4],I$1,BD.PD[Pos],Tabla3[[#This Row],[Part.]])+SUMIFS(BD.PD[Pago 5],BD.PD[Per.P5],I$1,BD.PD[Pos],Tabla3[[#This Row],[Part.]]) -> 0 | J9: =SUMIFS(BD.PD[Pago 1],BD.PD[Per.P1],J$1,BD.PD[Pos],Tabla3[[#This Row],[Part.]])+SUMIFS(BD.PD[Pago 2],BD.PD[Per.P2],J$1,BD.PD[Pos],Tabla3[[#This Row],[Part.]])+SUMIFS(BD.PD[Pago 3],BD.PD[Per.P3],J$1,BD.PD[Pos],Tabla3[[#This Row],[Part.]])+SUMIFS(BD.PD[Pago 4],BD.PD[Per.P4],J$1,BD.PD[Pos],Tabla3[[#This Row],[Part.]])+SUMIFS(BD.PD[Pago 5],BD.PD[Per.P5],J$1,BD.PD[Pos],Tabla3[[#This Row],[Part.]]) -> 0 | K9: =SUMIFS(BD.PD[Pago 1],BD.PD[Per.P1],K$1,BD.PD[Pos],Tabla3[[#This Row],[Part.]])+SUMIFS(BD.PD[Pago 2],BD.PD[Per.P2],K$1,BD.PD[Pos],Tabla3[[#This Row],[Part.]])+SUMIFS(BD.PD[Pago 3],BD.PD[Per.P3],K$1,BD.PD[Pos],Tabla3[[#This Row],[Part.]])+SUMIFS(BD.PD[Pago 4],BD.PD[Per.P4],K$1,BD.PD[Pos],Tabla3[[#This Row],[Part.]])+SUMIFS(BD.PD[Pago 5],BD.PD[Per.P5],K$1,BD.PD[Pos],Tabla3[[#This Row],[Part.]]) -> 0 | ... AG9: =SUMIFS(BD.PD[Pago 1],BD.PD[Per.P1],AG$1,BD.PD[Pos],Tabla3[[#This Row],[Part.]])+SUMIFS(BD.PD[Pago 2],BD.PD[Per.P2],AG$1,BD.PD[Pos],Tabla3[[#This Row],[Part.]])+SUMIFS(BD.PD[Pago 3],BD.PD[Per.P3],AG$1,BD.PD[Pos],Tabla3[[#This Row],[Part.]])+SUMIFS(BD.PD[Pago 4],BD.PD[Per.P4],AG$1,BD.PD[Pos],Tabla3[[#This Row],[Part.]])+SUMIFS(BD.PD[Pago 5],BD.PD[Per.P5],AG$1,BD.PD[Pos],Tabla3[[#This Row],[Part.]]) -> 0 | AH9: =SUM(Tabla3[[#This Row],[P1]:[P24]]) -> 0
A10: 1.04 | B10: =VLOOKUP(Tabla3[[#This Row],[Part.]],PPto[],3,FALSE) -> 1.04 Diseño sanitario | C10: =SUMIF(BD.PD[Pos],Tabla3[[#This Row],[Part.]],BD.PD[Ppto. Orden Interna '[DOP']]) -> 0 | D10: =SUMIFS(BD.PD[Pago 1],BD.PD[Per.P1],D$1,BD.PD[Pos],Tabla3[[#This Row],[Part.]])+SUMIFS(BD.PD[Pago 2],BD.PD[Per.P2],D$1,BD.PD[Pos],Tabla3[[#This Row],[Part.]])+SUMIFS(BD.PD[Pago 3],BD.PD[Per.P3],D$1,BD.PD[Pos],Tabla3[[#This Row],[Part.]])+SUMIFS(BD.PD[Pago 4],BD.PD[Per.P4],D$1,BD.PD[Pos],Tabla3[[#This Row],[Part.]])+SUMIFS(BD.PD[Pago 5],BD.PD[Per.P5],D$1,BD.PD[Pos],Tabla3[[#This Row],[Part.]]) -> 0 | E10: =SUMIFS(BD.PD[Pago 1],BD.PD[Per.P1],E$1,BD.PD[Pos],Tabla3[[#This Row],[Part.]])+SUMIFS(BD.PD[Pago 2],BD.PD[Per.P2],E$1,BD.PD[Pos],Tabla3[[#This Row],[Part.]])+SUMIFS(BD.PD[Pago 3],BD.PD[Per.P3],E$1,BD.PD[Pos],Tabla3[[#This Row],[Part.]])+SUMIFS(BD.PD[Pago 4],BD.PD[Per.P4],E$1,BD.PD[Pos],Tabla3[[#This Row],[Part.]])+SUMIFS(BD.PD[Pago 5],BD.PD[Per.P5],E$1,BD.PD[Pos],Tabla3[[#This Row],[Part.]]) -> 0 | F10: =SUMIFS(BD.PD[Pago 1],BD.PD[Per.P1],F$1,BD.PD[Pos],Tabla3[[#This Row],[Part.]])+SUMIFS(BD.PD[Pago 2],BD.PD[Per.P2],F$1,BD.PD[Pos],Tabla3[[#This Row],[Part.]])+SUMIFS(BD.PD[Pago 3],BD.PD[Per.P3],F$1,BD.PD[Pos],Tabla3[[#This Row],[Part.]])+SUMIFS(BD.PD[Pago 4],BD.PD[Per.P4],F$1,BD.PD[Pos],Tabla3[[#This Row],[Part.]])+SUMIFS(BD.PD[Pago 5],BD.PD[Per.P5],F$1,BD.PD[Pos],Tabla3[[#This Row],[Part.]]) -> 0 | G10: =SUMIFS(BD.PD[Pago 1],BD.PD[Per.P1],G$1,BD.PD[Pos],Tabla3[[#This Row],[Part.]])+SUMIFS(BD.PD[Pago 2],BD.PD[Per.P2],G$1,BD.PD[Pos],Tabla3[[#This Row],[Part.]])+SUMIFS(BD.PD[Pago 3],BD.PD[Per.P3],G$1,BD.PD[Pos],Tabla3[[#This Row],[Part.]])+SUMIFS(BD.PD[Pago 4],BD.PD[Per.P4],G$1,BD.PD[Pos],Tabla3[[#This Row],[Part.]])+SUMIFS(BD.PD[Pago 5],BD.PD[Per.P5],G$1,BD.PD[Pos],Tabla3[[#This Row],[Part.]]) -> 0 | H10: =SUMIFS(BD.PD[Pago 1],BD.PD[Per.P1],H$1,BD.PD[Pos],Tabla3[[#This Row],[Part.]])+SUMIFS(BD.PD[Pago 2],BD.PD[Per.P2],H$1,BD.PD[Pos],Tabla3[[#This Row],[Part.]])+SUMIFS(BD.PD[Pago 3],BD.PD[Per.P3],H$1,BD.PD[Pos],Tabla3[[#This Row],[Part.]])+SUMIFS(BD.PD[Pago 4],BD.PD[Per.P4],H$1,BD.PD[Pos],Tabla3[[#This Row],[Part.]])+SUMIFS(BD.PD[Pago 5],BD.PD[Per.P5],H$1,BD.PD[Pos],Tabla3[[#This Row],[Part.]]) -> 0 | I10: =SUMIFS(BD.PD[Pago 1],BD.PD[Per.P1],I$1,BD.PD[Pos],Tabla3[[#This Row],[Part.]])+SUMIFS(BD.PD[Pago 2],BD.PD[Per.P2],I$1,BD.PD[Pos],Tabla3[[#This Row],[Part.]])+SUMIFS(BD.PD[Pago 3],BD.PD[Per.P3],I$1,BD.PD[Pos],Tabla3[[#This Row],[Part.]])+SUMIFS(BD.PD[Pago 4],BD.PD[Per.P4],I$1,BD.PD[Pos],Tabla3[[#This Row],[Part.]])+SUMIFS(BD.PD[Pago 5],BD.PD[Per.P5],I$1,BD.PD[Pos],Tabla3[[#This Row],[Part.]]) -> 0 | J10: =SUMIFS(BD.PD[Pago 1],BD.PD[Per.P1],J$1,BD.PD[Pos],Tabla3[[#This Row],[Part.]])+SUMIFS(BD.PD[Pago 2],BD.PD[Per.P2],J$1,BD.PD[Pos],Tabla3[[#This Row],[Part.]])+SUMIFS(BD.PD[Pago 3],BD.PD[Per.P3],J$1,BD.PD[Pos],Tabla3[[#This Row],[Part.]])+SUMIFS(BD.PD[Pago 4],BD.PD[Per.P4],J$1,BD.PD[Pos],Tabla3[[#This Row],[Part.]])+SUMIFS(BD.PD[Pago 5],BD.PD[Per.P5],J$1,BD.PD[Pos],Tabla3[[#This Row],[Part.]]) -> 0 | K10: =SUMIFS(BD.PD[Pago 1],BD.PD[Per.P1],K$1,BD.PD[Pos],Tabla3[[#This Row],[Part.]])+SUMIFS(BD.PD[Pago 2],BD.PD[Per.P2],K$1,BD.PD[Pos],Tabla3[[#This Row],[Part.]])+SUMIFS(BD.PD[Pago 3],BD.PD[Per.P3],K$1,BD.PD[Pos],Tabla3[[#This Row],[Part.]])+SUMIFS(BD.PD[Pago 4],BD.PD[Per.P4],K$1,BD.PD[Pos],Tabla3[[#This Row],[Part.]])+SUMIFS(BD.PD[Pago 5],BD.PD[Per.P5],K$1,BD.PD[Pos],Tabla3[[#This Row],[Part.]]) -> 0 | ... AG10: =SUMIFS(BD.PD[Pago 1],BD.PD[Per.P1],AG$1,BD.PD[Pos],Tabla3[[#This Row],[Part.]])+SUMIFS(BD.PD[Pago 2],BD.PD[Per.P2],AG$1,BD.PD[Pos],Tabla3[[#This Row],[Part.]])+SUMIFS(BD.PD[Pago 3],BD.PD[Per.P3],AG$1,BD.PD[Pos],Tabla3[[#This Row],[Part.]])+SUMIFS(BD.PD[Pago 4],BD.PD[Per.P4],AG$1,BD.PD[Pos],Tabla3[[#This Row],[Part.]])+SUMIFS(BD.PD[Pago 5],BD.PD[Per.P5],AG$1,BD.PD[Pos],Tabla3[[#This Row],[Part.]]) -> 0 | AH10: =SUM(Tabla3[[#This Row],[P1]:[P24]]) -> 0
A11: 1.05 | B11: =VLOOKUP(Tabla3[[#This Row],[Part.]],PPto[],3,FALSE) -> 1.05 Estudio Geotécnico | C11: =SUMIF(BD.PD[Pos],Tabla3[[#This Row],[Part.]],BD.PD[Ppto. Orden Interna '[DOP']]) -> 0 | D11: =SUMIFS(BD.PD[Pago 1],BD.PD[Per.P1],D$1,BD.PD[Pos],Tabla3[[#This Row],[Part.]])+SUMIFS(BD.PD[Pago 2],BD.PD[Per.P2],D$1,BD.PD[Pos],Tabla3[[#This Row],[Part.]])+SUMIFS(BD.PD[Pago 3],BD.PD[Per.P3],D$1,BD.PD[Pos],Tabla3[[#This Row],[Part.]])+SUMIFS(BD.PD[Pago 4],BD.PD[Per.P4],D$1,BD.PD[Pos],Tabla3[[#This Row],[Part.]])+SUMIFS(BD.PD[Pago 5],BD.PD[Per.P5],D$1,BD.PD[Pos],Tabla3[[#This Row],[Part.]]) -> 0 | E11: =SUMIFS(BD.PD[Pago 1],BD.PD[Per.P1],E$1,BD.PD[Pos],Tabla3[[#This Row],[Part.]])+SUMIFS(BD.PD[Pago 2],BD.PD[Per.P2],E$1,BD.PD[Pos],Tabla3[[#This Row],[Part.]])+SUMIFS(BD.PD[Pago 3],BD.PD[Per.P3],E$1,BD.PD[Pos],Tabla3[[#This Row],[Part.]])+SUMIFS(BD.PD[Pago 4],BD.PD[Per.P4],E$1,BD.PD[Pos],Tabla3[[#This Row],[Part.]])+SUMIFS(BD.PD[Pago 5],BD.PD[Per.P5],E$1,BD.PD[Pos],Tabla3[[#This Row],[Part.]]) -> 0 | F11: =SUMIFS(BD.PD[Pago 1],BD.PD[Per.P1],F$1,BD.PD[Pos],Tabla3[[#This Row],[Part.]])+SUMIFS(BD.PD[Pago 2],BD.PD[Per.P2],F$1,BD.PD[Pos],Tabla3[[#This Row],[Part.]])+SUMIFS(BD.PD[Pago 3],BD.PD[Per.P3],F$1,BD.PD[Pos],Tabla3[[#This Row],[Part.]])+SUMIFS(BD.PD[Pago 4],BD.PD[Per.P4],F$1,BD.PD[Pos],Tabla3[[#This Row],[Part.]])+SUMIFS(BD.PD[Pago 5],BD.PD[Per.P5],F$1,BD.PD[Pos],Tabla3[[#This Row],[Part.]]) -> 0 | G11: =SUMIFS(BD.PD[Pago 1],BD.PD[Per.P1],G$1,BD.PD[Pos],Tabla3[[#This Row],[Part.]])+SUMIFS(BD.PD[Pago 2],BD.PD[Per.P2],G$1,BD.PD[Pos],Tabla3[[#This Row],[Part.]])+SUMIFS(BD.PD[Pago 3],BD.PD[Per.P3],G$1,BD.PD[Pos],Tabla3[[#This Row],[Part.]])+SUMIFS(BD.PD[Pago 4],BD.PD[Per.P4],G$1,BD.PD[Pos],Tabla3[[#This Row],[Part.]])+SUMIFS(BD.PD[Pago 5],BD.PD[Per.P5],G$1,BD.PD[Pos],Tabla3[[#This Row],[Part.]]) -> 0 | H11: =SUMIFS(BD.PD[Pago 1],BD.PD[Per.P1],H$1,BD.PD[Pos],Tabla3[[#This Row],[Part.]])+SUMIFS(BD.PD[Pago 2],BD.PD[Per.P2],H$1,BD.PD[Pos],Tabla3[[#This Row],[Part.]])+SUMIFS(BD.PD[Pago 3],BD.PD[Per.P3],H$1,BD.PD[Pos],Tabla3[[#This Row],[Part.]])+SUMIFS(BD.PD[Pago 4],BD.PD[Per.P4],H$1,BD.PD[Pos],Tabla3[[#This Row],[Part.]])+SUMIFS(BD.PD[Pago 5],BD.PD[Per.P5],H$1,BD.PD[Pos],Tabla3[[#This Row],[Part.]]) -> 0 | I11: =SUMIFS(BD.PD[Pago 1],BD.PD[Per.P1],I$1,BD.PD[Pos],Tabla3[[#This Row],[Part.]])+SUMIFS(BD.PD[Pago 2],BD.PD[Per.P2],I$1,BD.PD[Pos],Tabla3[[#This Row],[Part.]])+SUMIFS(BD.PD[Pago 3],BD.PD[Per.P3],I$1,BD.PD[Pos],Tabla3[[#This Row],[Part.]])+SUMIFS(BD.PD[Pago 4],BD.PD[Per.P4],I$1,BD.PD[Pos],Tabla3[[#This Row],[Part.]])+SUMIFS(BD.PD[Pago 5],BD.PD[Per.P5],I$1,BD.PD[Pos],Tabla3[[#This Row],[Part.]]) -> 0 | J11: =SUMIFS(BD.PD[Pago 1],BD.PD[Per.P1],J$1,BD.PD[Pos],Tabla3[[#This Row],[Part.]])+SUMIFS(BD.PD[Pago 2],BD.PD[Per.P2],J$1,BD.PD[Pos],Tabla3[[#This Row],[Part.]])+SUMIFS(BD.PD[Pago 3],BD.PD[Per.P3],J$1,BD.PD[Pos],Tabla3[[#This Row],[Part.]])+SUMIFS(BD.PD[Pago 4],BD.PD[Per.P4],J$1,BD.PD[Pos],Tabla3[[#This Row],[Part.]])+SUMIFS(BD.PD[Pago 5],BD.PD[Per.P5],J$1,BD.PD[Pos],Tabla3[[#This Row],[Part.]]) -> 0 | K11: =SUMIFS(BD.PD[Pago 1],BD.PD[Per.P1],K$1,BD.PD[Pos],Tabla3[[#This Row],[Part.]])+SUMIFS(BD.PD[Pago 2],BD.PD[Per.P2],K$1,BD.PD[Pos],Tabla3[[#This Row],[Part.]])+SUMIFS(BD.PD[Pago 3],BD.PD[Per.P3],K$1,BD.PD[Pos],Tabla3[[#This Row],[Part.]])+SUMIFS(BD.PD[Pago 4],BD.PD[Per.P4],K$1,BD.PD[Pos],Tabla3[[#This Row],[Part.]])+SUMIFS(BD.PD[Pago 5],BD.PD[Per.P5],K$1,BD.PD[Pos],Tabla3[[#This Row],[Part.]]) -> 0 | ... AG11: =SUMIFS(BD.PD[Pago 1],BD.PD[Per.P1],AG$1,BD.PD[Pos],Tabla3[[#This Row],[Part.]])+SUMIFS(BD.PD[Pago 2],BD.PD[Per.P2],AG$1,BD.PD[Pos],Tabla3[[#This Row],[Part.]])+SUMIFS(BD.PD[Pago 3],BD.PD[Per.P3],AG$1,BD.PD[Pos],Tabla3[[#This Row],[Part.]])+SUMIFS(BD.PD[Pago 4],BD.PD[Per.P4],AG$1,BD.PD[Pos],Tabla3[[#This Row],[Part.]])+SUMIFS(BD.PD[Pago 5],BD.PD[Per.P5],AG$1,BD.PD[Pos],Tabla3[[#This Row],[Part.]]) -> 0 | AH11: =SUM(Tabla3[[#This Row],[P1]:[P24]]) -> 0
A12: 1.06 | B12: =VLOOKUP(Tabla3[[#This Row],[Part.]],PPto[],3,FALSE) -> 1.06 Levantamiento topográfico | C12: =SUMIF(BD.PD[Pos],Tabla3[[#This Row],[Part.]],BD.PD[Ppto. Orden Interna '[DOP']]) -> 0 | D12: =SUMIFS(BD.PD[Pago 1],BD.PD[Per.P1],D$1,BD.PD[Pos],Tabla3[[#This Row],[Part.]])+SUMIFS(BD.PD[Pago 2],BD.PD[Per.P2],D$1,BD.PD[Pos],Tabla3[[#This Row],[Part.]])+SUMIFS(BD.PD[Pago 3],BD.PD[Per.P3],D$1,BD.PD[Pos],Tabla3[[#This Row],[Part.]])+SUMIFS(BD.PD[Pago 4],BD.PD[Per.P4],D$1,BD.PD[Pos],Tabla3[[#This Row],[Part.]])+SUMIFS(BD.PD[Pago 5],BD.PD[Per.P5],D$1,BD.PD[Pos],Tabla3[[#This Row],[Part.]]) -> 0 | E12: =SUMIFS(BD.PD[Pago 1],BD.PD[Per.P1],E$1,BD.PD[Pos],Tabla3[[#This Row],[Part.]])+SUMIFS(BD.PD[Pago 2],BD.PD[Per.P2],E$1,BD.PD[Pos],Tabla3[[#This Row],[Part.]])+SUMIFS(BD.PD[Pago 3],BD.PD[Per.P3],E$1,BD.PD[Pos],Tabla3[[#This Row],[Part.]])+SUMIFS(BD.PD[Pago 4],BD.PD[Per.P4],E$1,BD.PD[Pos],Tabla3[[#This Row],[Part.]])+SUMIFS(BD.PD[Pago 5],BD.PD[Per.P5],E$1,BD.PD[Pos],Tabla3[[#This Row],[Part.]]) -> 0 | F12: =SUMIFS(BD.PD[Pago 1],BD.PD[Per.P1],F$1,BD.PD[Pos],Tabla3[[#This Row],[Part.]])+SUMIFS(BD.PD[Pago 2],BD.PD[Per.P2],F$1,BD.PD[Pos],Tabla3[[#This Row],[Part.]])+SUMIFS(BD.PD[Pago 3],BD.PD[Per.P3],F$1,BD.PD[Pos],Tabla3[[#This Row],[Part.]])+SUMIFS(BD.PD[Pago 4],BD.PD[Per.P4],F$1,BD.PD[Pos],Tabla3[[#This Row],[Part.]])+SUMIFS(BD.PD[Pago 5],BD.PD[Per.P5],F$1,BD.PD[Pos],Tabla3[[#This Row],[Part.]]) -> 0 | G12: =SUMIFS(BD.PD[Pago 1],BD.PD[Per.P1],G$1,BD.PD[Pos],Tabla3[[#This Row],[Part.]])+SUMIFS(BD.PD[Pago 2],BD.PD[Per.P2],G$1,BD.PD[Pos],Tabla3[[#This Row],[Part.]])+SUMIFS(BD.PD[Pago 3],BD.PD[Per.P3],G$1,BD.PD[Pos],Tabla3[[#This Row],[Part.]])+SUMIFS(BD.PD[Pago 4],BD.PD[Per.P4],G$1,BD.PD[Pos],Tabla3[[#This Row],[Part.]])+SUMIFS(BD.PD[Pago 5],BD.PD[Per.P5],G$1,BD.PD[Pos],Tabla3[[#This Row],[Part.]]) -> 0 | H12: =SUMIFS(BD.PD[Pago 1],BD.PD[Per.P1],H$1,BD.PD[Pos],Tabla3[[#This Row],[Part.]])+SUMIFS(BD.PD[Pago 2],BD.PD[Per.P2],H$1,BD.PD[Pos],Tabla3[[#This Row],[Part.]])+SUMIFS(BD.PD[Pago 3],BD.PD[Per.P3],H$1,BD.PD[Pos],Tabla3[[#This Row],[Part.]])+SUMIFS(BD.PD[Pago 4],BD.PD[Per.P4],H$1,BD.PD[Pos],Tabla3[[#This Row],[Part.]])+SUMIFS(BD.PD[Pago 5],BD.PD[Per.P5],H$1,BD.PD[Pos],Tabla3[[#This Row],[Part.]]) -> 0 | I12: =SUMIFS(BD.PD[Pago 1],BD.PD[Per.P1],I$1,BD.PD[Pos],Tabla3[[#This Row],[Part.]])+SUMIFS(BD.PD[Pago 2],BD.PD[Per.P2],I$1,BD.PD[Pos],Tabla3[[#This Row],[Part.]])+SUMIFS(BD.PD[Pago 3],BD.PD[Per.P3],I$1,BD.PD[Pos],Tabla3[[#This Row],[Part.]])+SUMIFS(BD.PD[Pago 4],BD.PD[Per.P4],I$1,BD.PD[Pos],Tabla3[[#This Row],[Part.]])+SUMIFS(BD.PD[Pago 5],BD.PD[Per.P5],I$1,BD.PD[Pos],Tabla3[[#This Row],[Part.]]) -> 0 | J12: =SUMIFS(BD.PD[Pago 1],BD.PD[Per.P1],J$1,BD.PD[Pos],Tabla3[[#This Row],[Part.]])+SUMIFS(BD.PD[Pago 2],BD.PD[Per.P2],J$1,BD.PD[Pos],Tabla3[[#This Row],[Part.]])+SUMIFS(BD.PD[Pago 3],BD.PD[Per.P3],J$1,BD.PD[Pos],Tabla3[[#This Row],[Part.]])+SUMIFS(BD.PD[Pago 4],BD.PD[Per.P4],J$1,BD.PD[Pos],Tabla3[[#This Row],[Part.]])+SUMIFS(BD.PD[Pago 5],BD.PD[Per.P5],J$1,BD.PD[Pos],Tabla3[[#This Row],[Part.]]) -> 0 | K12: =SUMIFS(BD.PD[Pago 1],BD.PD[Per.P1],K$1,BD.PD[Pos],Tabla3[[#This Row],[Part.]])+SUMIFS(BD.PD[Pago 2],BD.PD[Per.P2],K$1,BD.PD[Pos],Tabla3[[#This Row],[Part.]])+SUMIFS(BD.PD[Pago 3],BD.PD[Per.P3],K$1,BD.PD[Pos],Tabla3[[#This Row],[Part.]])+SUMIFS(BD.PD[Pago 4],BD.PD[Per.P4],K$1,BD.PD[Pos],Tabla3[[#This Row],[Part.]])+SUMIFS(BD.PD[Pago 5],BD.PD[Per.P5],K$1,BD.PD[Pos],Tabla3[[#This Row],[Part.]]) -> 0 | ... AG12: =SUMIFS(BD.PD[Pago 1],BD.PD[Per.P1],AG$1,BD.PD[Pos],Tabla3[[#This Row],[Part.]])+SUMIFS(BD.PD[Pago 2],BD.PD[Per.P2],AG$1,BD.PD[Pos],Tabla3[[#This Row],[Part.]])+SUMIFS(BD.PD[Pago 3],BD.PD[Per.P3],AG$1,BD.PD[Pos],Tabla3[[#This Row],[Part.]])+SUMIFS(BD.PD[Pago 4],BD.PD[Per.P4],AG$1,BD.PD[Pos],Tabla3[[#This Row],[Part.]])+SUMIFS(BD.PD[Pago 5],BD.PD[Per.P5],AG$1,BD.PD[Pos],Tabla3[[#This Row],[Part.]]) -> 0 | AH12: =SUM(Tabla3[[#This Row],[P1]:[P24]]) -> 0
A13: 1.07 | B13: =VLOOKUP(Tabla3[[#This Row],[Part.]],PPto[],3,FALSE) -> 1.07 Permisos | C13: =SUMIF(BD.PD[Pos],Tabla3[[#This Row],[Part.]],BD.PD[Ppto. Orden Interna '[DOP']]) -> 0 | D13: =SUMIFS(BD.PD[Pago 1],BD.PD[Per.P1],D$1,BD.PD[Pos],Tabla3[[#This Row],[Part.]])+SUMIFS(BD.PD[Pago 2],BD.PD[Per.P2],D$1,BD.PD[Pos],Tabla3[[#This Row],[Part.]])+SUMIFS(BD.PD[Pago 3],BD.PD[Per.P3],D$1,BD.PD[Pos],Tabla3[[#This Row],[Part.]])+SUMIFS(BD.PD[Pago 4],BD.PD[Per.P4],D$1,BD.PD[Pos],Tabla3[[#This Row],[Part.]])+SUMIFS(BD.PD[Pago 5],BD.PD[Per.P5],D$1,BD.PD[Pos],Tabla3[[#This Row],[Part.]]) -> 0 | E13: =SUMIFS(BD.PD[Pago 1],BD.PD[Per.P1],E$1,BD.PD[Pos],Tabla3[[#This Row],[Part.]])+SUMIFS(BD.PD[Pago 2],BD.PD[Per.P2],E$1,BD.PD[Pos],Tabla3[[#This Row],[Part.]])+SUMIFS(BD.PD[Pago 3],BD.PD[Per.P3],E$1,BD.PD[Pos],Tabla3[[#This Row],[Part.]])+SUMIFS(BD.PD[Pago 4],BD.PD[Per.P4],E$1,BD.PD[Pos],Tabla3[[#This Row],[Part.]])+SUMIFS(BD.PD[Pago 5],BD.PD[Per.P5],E$1,BD.PD[Pos],Tabla3[[#This Row],[Part.]]) -> 0 | F13: =SUMIFS(BD.PD[Pago 1],BD.PD[Per.P1],F$1,BD.PD[Pos],Tabla3[[#This Row],[Part.]])+SUMIFS(BD.PD[Pago 2],BD.PD[Per.P2],F$1,BD.PD[Pos],Tabla3[[#This Row],[Part.]])+SUMIFS(BD.PD[Pago 3],BD.PD[Per.P3],F$1,BD.PD[Pos],Tabla3[[#This Row],[Part.]])+SUMIFS(BD.PD[Pago 4],BD.PD[Per.P4],F$1,BD.PD[Pos],Tabla3[[#This Row],[Part.]])+SUMIFS(BD.PD[Pago 5],BD.PD[Per.P5],F$1,BD.PD[Pos],Tabla3[[#This Row],[Part.]]) -> 0 | G13: =SUMIFS(BD.PD[Pago 1],BD.PD[Per.P1],G$1,BD.PD[Pos],Tabla3[[#This Row],[Part.]])+SUMIFS(BD.PD[Pago 2],BD.PD[Per.P2],G$1,BD.PD[Pos],Tabla3[[#This Row],[Part.]])+SUMIFS(BD.PD[Pago 3],BD.PD[Per.P3],G$1,BD.PD[Pos],Tabla3[[#This Row],[Part.]])+SUMIFS(BD.PD[Pago 4],BD.PD[Per.P4],G$1,BD.PD[Pos],Tabla3[[#This Row],[Part.]])+SUMIFS(BD.PD[Pago 5],BD.PD[Per.P5],G$1,BD.PD[Pos],Tabla3[[#This Row],[Part.]]) -> 0 | H13: =SUMIFS(BD.PD[Pago 1],BD.PD[Per.P1],H$1,BD.PD[Pos],Tabla3[[#This Row],[Part.]])+SUMIFS(BD.PD[Pago 2],BD.PD[Per.P2],H$1,BD.PD[Pos],Tabla3[[#This Row],[Part.]])+SUMIFS(BD.PD[Pago 3],BD.PD[Per.P3],H$1,BD.PD[Pos],Tabla3[[#This Row],[Part.]])+SUMIFS(BD.PD[Pago 4],BD.PD[Per.P4],H$1,BD.PD[Pos],Tabla3[[#This Row],[Part.]])+SUMIFS(BD.PD[Pago 5],BD.PD[Per.P5],H$1,BD.PD[Pos],Tabla3[[#This Row],[Part.]]) -> 0 | I13: =SUMIFS(BD.PD[Pago 1],BD.PD[Per.P1],I$1,BD.PD[Pos],Tabla3[[#This Row],[Part.]])+SUMIFS(BD.PD[Pago 2],BD.PD[Per.P2],I$1,BD.PD[Pos],Tabla3[[#This Row],[Part.]])+SUMIFS(BD.PD[Pago 3],BD.PD[Per.P3],I$1,BD.PD[Pos],Tabla3[[#This Row],[Part.]])+SUMIFS(BD.PD[Pago 4],BD.PD[Per.P4],I$1,BD.PD[Pos],Tabla3[[#This Row],[Part.]])+SUMIFS(BD.PD[Pago 5],BD.PD[Per.P5],I$1,BD.PD[Pos],Tabla3[[#This Row],[Part.]]) -> 0 | J13: =SUMIFS(BD.PD[Pago 1],BD.PD[Per.P1],J$1,BD.PD[Pos],Tabla3[[#This Row],[Part.]])+SUMIFS(BD.PD[Pago 2],BD.PD[Per.P2],J$1,BD.PD[Pos],Tabla3[[#This Row],[Part.]])+SUMIFS(BD.PD[Pago 3],BD.PD[Per.P3],J$1,BD.PD[Pos],Tabla3[[#This Row],[Part.]])+SUMIFS(BD.PD[Pago 4],BD.PD[Per.P4],J$1,BD.PD[Pos],Tabla3[[#This Row],[Part.]])+SUMIFS(BD.PD[Pago 5],BD.PD[Per.P5],J$1,BD.PD[Pos],Tabla3[[#This Row],[Part.]]) -> 0 | K13: =SUMIFS(BD.PD[Pago 1],BD.PD[Per.P1],K$1,BD.PD[Pos],Tabla3[[#This Row],[Part.]])+SUMIFS(BD.PD[Pago 2],BD.PD[Per.P2],K$1,BD.PD[Pos],Tabla3[[#This Row],[Part.]])+SUMIFS(BD.PD[Pago 3],BD.PD[Per.P3],K$1,BD.PD[Pos],Tabla3[[#This Row],[Part.]])+SUMIFS(BD.PD[Pago 4],BD.PD[Per.P4],K$1,BD.PD[Pos],Tabla3[[#This Row],[Part.]])+SUMIFS(BD.PD[Pago 5],BD.PD[Per.P5],K$1,BD.PD[Pos],Tabla3[[#This Row],[Part.]]) -> 0 | ... AG13: =SUMIFS(BD.PD[Pago 1],BD.PD[Per.P1],AG$1,BD.PD[Pos],Tabla3[[#This Row],[Part.]])+SUMIFS(BD.PD[Pago 2],BD.PD[Per.P2],AG$1,BD.PD[Pos],Tabla3[[#This Row],[Part.]])+SUMIFS(BD.PD[Pago 3],BD.PD[Per.P3],AG$1,BD.PD[Pos],Tabla3[[#This Row],[Part.]])+SUMIFS(BD.PD[Pago 4],BD.PD[Per.P4],AG$1,BD.PD[Pos],Tabla3[[#This Row],[Part.]])+SUMIFS(BD.PD[Pago 5],BD.PD[Per.P5],AG$1,BD.PD[Pos],Tabla3[[#This Row],[Part.]]) -> 0 | AH13: =SUM(Tabla3[[#This Row],[P1]:[P24]]) -> 0
A14: 1.08 | B14: =VLOOKUP(Tabla3[[#This Row],[Part.]],PPto[],3,FALSE) -> 1.08 Diseño sistema contra incendios | C14: =SUMIF(BD.PD[Pos],Tabla3[[#This Row],[Part.]],BD.PD[Ppto. Orden Interna '[DOP']]) -> 0 | D14: =SUMIFS(BD.PD[Pago 1],BD.PD[Per.P1],D$1,BD.PD[Pos],Tabla3[[#This Row],[Part.]])+SUMIFS(BD.PD[Pago 2],BD.PD[Per.P2],D$1,BD.PD[Pos],Tabla3[[#This Row],[Part.]])+SUMIFS(BD.PD[Pago 3],BD.PD[Per.P3],D$1,BD.PD[Pos],Tabla3[[#This Row],[Part.]])+SUMIFS(BD.PD[Pago 4],BD.PD[Per.P4],D$1,BD.PD[Pos],Tabla3[[#This Row],[Part.]])+SUMIFS(BD.PD[Pago 5],BD.PD[Per.P5],D$1,BD.PD[Pos],Tabla3[[#This Row],[Part.]]) -> 0 | E14: =SUMIFS(BD.PD[Pago 1],BD.PD[Per.P1],E$1,BD.PD[Pos],Tabla3[[#This Row],[Part.]])+SUMIFS(BD.PD[Pago 2],BD.PD[Per.P2],E$1,BD.PD[Pos],Tabla3[[#This Row],[Part.]])+SUMIFS(BD.PD[Pago 3],BD.PD[Per.P3],E$1,BD.PD[Pos],Tabla3[[#This Row],[Part.]])+SUMIFS(BD.PD[Pago 4],BD.PD[Per.P4],E$1,BD.PD[Pos],Tabla3[[#This Row],[Part.]])+SUMIFS(BD.PD[Pago 5],BD.PD[Per.P5],E$1,BD.PD[Pos],Tabla3[[#This Row],[Part.]]) -> 0 | F14: =SUMIFS(BD.PD[Pago 1],BD.PD[Per.P1],F$1,BD.PD[Pos],Tabla3[[#This Row],[Part.]])+SUMIFS(BD.PD[Pago 2],BD.PD[Per.P2],F$1,BD.PD[Pos],Tabla3[[#This Row],[Part.]])+SUMIFS(BD.PD[Pago 3],BD.PD[Per.P3],F$1,BD.PD[Pos],Tabla3[[#This Row],[Part.]])+SUMIFS(BD.PD[Pago 4],BD.PD[Per.P4],F$1,BD.PD[Pos],Tabla3[[#This Row],[Part.]])+SUMIFS(BD.PD[Pago 5],BD.PD[Per.P5],F$1,BD.PD[Pos],Tabla3[[#This Row],[Part.]]) -> 0 | G14: =SUMIFS(BD.PD[Pago 1],BD.PD[Per.P1],G$1,BD.PD[Pos],Tabla3[[#This Row],[Part.]])+SUMIFS(BD.PD[Pago 2],BD.PD[Per.P2],G$1,BD.PD[Pos],Tabla3[[#This Row],[Part.]])+SUMIFS(BD.PD[Pago 3],BD.PD[Per.P3],G$1,BD.PD[Pos],Tabla3[[#This Row],[Part.]])+SUMIFS(BD.PD[Pago 4],BD.PD[Per.P4],G$1,BD.PD[Pos],Tabla3[[#This Row],[Part.]])+SUMIFS(BD.PD[Pago 5],BD.PD[Per.P5],G$1,BD.PD[Pos],Tabla3[[#This Row],[Part.]]) -> 0 | H14: =SUMIFS(BD.PD[Pago 1],BD.PD[Per.P1],H$1,BD.PD[Pos],Tabla3[[#This Row],[Part.]])+SUMIFS(BD.PD[Pago 2],BD.PD[Per.P2],H$1,BD.PD[Pos],Tabla3[[#This Row],[Part.]])+SUMIFS(BD.PD[Pago 3],BD.PD[Per.P3],H$1,BD.PD[Pos],Tabla3[[#This Row],[Part.]])+SUMIFS(BD.PD[Pago 4],BD.PD[Per.P4],H$1,BD.PD[Pos],Tabla3[[#This Row],[Part.]])+SUMIFS(BD.PD[Pago 5],BD.PD[Per.P5],H$1,BD.PD[Pos],Tabla3[[#This Row],[Part.]]) -> 0 | I14: =SUMIFS(BD.PD[Pago 1],BD.PD[Per.P1],I$1,BD.PD[Pos],Tabla3[[#This Row],[Part.]])+SUMIFS(BD.PD[Pago 2],BD.PD[Per.P2],I$1,BD.PD[Pos],Tabla3[[#This Row],[Part.]])+SUMIFS(BD.PD[Pago 3],BD.PD[Per.P3],I$1,BD.PD[Pos],Tabla3[[#This Row],[Part.]])+SUMIFS(BD.PD[Pago 4],BD.PD[Per.P4],I$1,BD.PD[Pos],Tabla3[[#This Row],[Part.]])+SUMIFS(BD.PD[Pago 5],BD.PD[Per.P5],I$1,BD.PD[Pos],Tabla3[[#This Row],[Part.]]) -> 0 | J14: =SUMIFS(BD.PD[Pago 1],BD.PD[Per.P1],J$1,BD.PD[Pos],Tabla3[[#This Row],[Part.]])+SUMIFS(BD.PD[Pago 2],BD.PD[Per.P2],J$1,BD.PD[Pos],Tabla3[[#This Row],[Part.]])+SUMIFS(BD.PD[Pago 3],BD.PD[Per.P3],J$1,BD.PD[Pos],Tabla3[[#This Row],[Part.]])+SUMIFS(BD.PD[Pago 4],BD.PD[Per.P4],J$1,BD.PD[Pos],Tabla3[[#This Row],[Part.]])+SUMIFS(BD.PD[Pago 5],BD.PD[Per.P5],J$1,BD.PD[Pos],Tabla3[[#This Row],[Part.]]) -> 0 | K14: =SUMIFS(BD.PD[Pago 1],BD.PD[Per.P1],K$1,BD.PD[Pos],Tabla3[[#This Row],[Part.]])+SUMIFS(BD.PD[Pago 2],BD.PD[Per.P2],K$1,BD.PD[Pos],Tabla3[[#This Row],[Part.]])+SUMIFS(BD.PD[Pago 3],BD.PD[Per.P3],K$1,BD.PD[Pos],Tabla3[[#This Row],[Part.]])+SUMIFS(BD.PD[Pago 4],BD.PD[Per.P4],K$1,BD.PD[Pos],Tabla3[[#This Row],[Part.]])+SUMIFS(BD.PD[Pago 5],BD.PD[Per.P5],K$1,BD.PD[Pos],Tabla3[[#This Row],[Part.]]) -> 0 | ... AG14: =SUMIFS(BD.PD[Pago 1],BD.PD[Per.P1],AG$1,BD.PD[Pos],Tabla3[[#This Row],[Part.]])+SUMIFS(BD.PD[Pago 2],BD.PD[Per.P2],AG$1,BD.PD[Pos],Tabla3[[#This Row],[Part.]])+SUMIFS(BD.PD[Pago 3],BD.PD[Per.P3],AG$1,BD.PD[Pos],Tabla3[[#This Row],[Part.]])+SUMIFS(BD.PD[Pago 4],BD.PD[Per.P4],AG$1,BD.PD[Pos],Tabla3[[#This Row],[Part.]])+SUMIFS(BD.PD[Pago 5],BD.PD[Per.P5],AG$1,BD.PD[Pos],Tabla3[[#This Row],[Part.]]) -> 0 | AH14: =SUM(Tabla3[[#This Row],[P1]:[P24]]) -> 0
