Workbook
Name \4: #REF!
Name \6: #REF!
Name \A: #REF!
Name \E: #REF!
Name \I: #REF!
Name \M: #REF!
Name \N: #REF!
Name \O: #REF!
Name \U: #REF!
Name __DAT1: #REF!
Name __DAT10: #REF!
Name __DAT11: #REF!
Name __DAT12: #REF!
Name __DAT13: #REF!
Name __DAT14: #REF!
Name __DAT2: #REF!
Name __DAT3: #REF!
Name __DAT4: #REF!
Name __DAT5: #REF!
Name __DAT6: #REF!
Name __DAT7: #REF!
Name __DAT8: #REF!
Name __DAT9: #REF!
Name _DAT1: #REF!
Name _DAT10: #REF!
Name _DAT11: #REF!
Name _DAT12: #REF!
Name _DAT13: #REF!
Name _DAT14: #REF!
Name _DAT15: #REF!
Name _DAT16: #REF!
Name _DAT17: #REF!
Name _DAT18: #REF!
Name _DAT19: #REF!
Name _DAT2: #REF!
Name _DAT20: #REF!
Name _DAT21: #REF!
Name _DAT3: #REF!
Name _DAT4: #REF!
Name _DAT5: #REF!
Name _DAT6: #REF!
Name _DAT7: #REF!
Name _DAT8: #REF!
Name _DAT9: #REF!
Name _EV: [1]LoV!$A$147:$B$217
Name _EV: #REF!
Name _GC: [1]LoV!$U$2:$V$169
Name _GC: #REF!
Name _IIM: [1]LoV!$A$116:$B$133
Name _IIM: #REF!
Name _M: [1]LoV!$AC$2:$AD$11093
Name _M: #REF!
Name _PE: [1]LoV!$A$136:$B$144
Name _PE: #REF!
Name _T: [1]LoV!$A$220:$B$265
Name _T: #REF!
Name _TC: [1]LoV!$A$268:$B$271
Name _TC: #REF!
Name ACERO: #REF!
Name ACERO: #REF!

Sheet Plan OI
C1: Presupuesto Detallado - Propuesta para Sirena Compacta Las Terrenas
C2: Area de Compras de Activos
C3: 19 de agosto 2026
C4: Fecha Version: | D4: Alto Nivel | H4: Plan Detallado DOP | K4: Plan Detallado USD
D5: Total Presupuesto [DOP] | F5: Ppto OI [DOP] | G5: Ppto Capex [DOP] | H5: Total Iniciativa [DOP] | I5: Ppto OI [USD] | J5: Ppto Capex [USD] | K5: Total Iniciativa [USD]
C6: TOTAL GENERAL ESTIMADO | D6: 2.3949544e+08 | F6: =SUM(F9:F11) -> 2.295797e+08 | G6: =SUM(G9:G11) -> 0 | H6: =G6+F6 -> 2.295797e+08 | I6: =SUM(I9:I11) -> 3763601.6 | J6: =SUM(J9:J11) -> 0 | K6: =J6+I6 -> 3763601.6
C8: Resumen de Partidas
C9: EQUIPAMIENTO | D9: =SUMIF(PPto[Gran Part.],$C9,PPto[Total '[USD']]) -> 2.0460328e+08 | F9: =SUMIF(PPto[Gran Part.],$C9,PPto[Ppto. OI '[DOP']2]) -> 2.2249835e+08 | G9: =SUMIF(PPto[Gran Part.],$C9,PPto[Ppto. Capex '[DOP']]) -> 0 | H9: =G9+F9 -> 2.2249835e+08 | I9: =SUMIF(PPto[Gran Part.],C9,PPto[Ppto. OI '[USD']]) -> 3647514 | J9: =SUMIF(PPto[Gran Part.],C9,PPto[Ppto. Capex '[USD']]) -> 0 | K9: =J9+I9 -> 3647514
C10: EDIFICACIÓN | D10: =SUMIF(PPto[Gran Part.],$C10,PPto[Total '[USD']]) -> 7081344.5 | F10: =SUMIF(PPto[Gran Part.],$C10,PPto[Ppto. OI '[DOP']2]) -> 7081344.5 | G10: =SUMIF(PPto[Gran Part.],$C10,PPto[Ppto. Capex '[DOP']]) -> 0 | H10: =G10+F10 -> 7081344.5 | I10: =SUMIF(PPto[Gran Part.],C10,PPto[Ppto. OI '[USD']]) -> 116087.61 | J10: =SUMIF(PPto[Gran Part.],C10,PPto[Ppto. Capex '[USD']]) -> 0 | K10: =J10+I10 -> 116087.61
C11: TERRENO | D11: 0 | F11: =SUMIF(PPto[Gran Part.],$C11,PPto[Ppto. OI '[DOP']2]) -> 0 | G11: =SUMIF(PPto[Gran Part.],$C11,PPto[Ppto. Capex '[DOP']]) -> 0 | H11: =G11+F11 -> 0 | I11: =SUMIF(PPto[Gran Part.],C11,PPto[Ppto. OI '[USD']]) -> 0 | J11: =SUMIF(PPto[Gran Part.],C11,PPto[Ppto. Capex '[USD']]) -> 0 | K11: =J11+I11 -> 0
C12: Gasto | D12: 0 | F12: =SUMIF(PPto[Gran Part.],$C12,PPto[Ppto. OI '[DOP']2]) -> 0 | G12: =SUMIF(PPto[Gran Part.],$C12,PPto[Ppto. Capex '[DOP']]) -> 0 | H12: =G12+F12 -> 0 | I12: =SUMIF(PPto[Gran Part.],C12,PPto[Ppto. OI '[USD']]) -> 0 | J12: =SUMIF(PPto[Gran Part.],C12,PPto[Ppto. Capex '[USD']]) -> 0 | K12: =J12+I12 -> 0
C14: Área de la Localidad
C15: M² Construcción
C16: M² Sala de Ventas
C17: M² Terreno
F18: OI | G18: Capex | I18: OI | J18: Capex
A19: Part. | B19: Gran Part. | C19: Edificación, Instalaciones y Equipamientos | D19: Total [USD] | E19: Columna2 | F19: Ppto. OI [DOP]2 | G19: Ppto. Capex [DOP] | H19: Total [DOP] | I19: Ppto. OI [USD] | J19: Ppto. Capex [USD] | K19: Total [USD]2
A20: 1 | C20: 1.00 Estudios Preliminares | D20: =SUM(D21:D29) -> 0 | F20: =SUM(F21:F29) -> 0 | G20: =SUM(G21:G29) -> 0 | H20: =PPto[[#This Row],[Ppto. Capex '[DOP']]]+PPto[[#This Row],[Ppto. OI '[DOP']2]] -> 0 | I20: =SUM(I21:I29) -> 0 | J20: =SUM(J21:J29) -> 0 | K20: =PPto[[#This Row],[Ppto. Capex '[USD']]]+PPto[[#This Row],[Ppto. OI '[USD']]] -> 0
A21: 1.01 | B21: Edificación | C21: 1.01 Diseño arquitectónico | D21: 0 | F21: =SUMIFS(BD.PD[Ppto. Orden Interna '[DOP']],BD.PD[Pos],PPto[[#This Row],[Part.]],BD.PD[Tipo Ppto],F$18) -> 0 | G21: =SUMIFS(BD.PD[Ppto. Orden Interna '[DOP']],BD.PD[Pos],PPto[[#This Row],[Part.]],BD.PD[Tipo Ppto],G$18) -> 0 | H21: =PPto[[#This Row],[Ppto. Capex '[DOP']]]+PPto[[#This Row],[Ppto. OI '[DOP']2]] -> 0 | I21: =SUMIFS(BD.PD[Ppto. Orden Interna '[USD']],BD.PD[Pos],PPto[[#This Row],[Part.]],BD.PD[Tipo Ppto],I$18) -> 0 | J21: =SUMIFS(BD.PD[Ppto. Orden Interna '[USD']],BD.PD[Pos],PPto[[#This Row],[Part.]],BD.PD[Tipo Ppto],J$18) -> 0 | K21: =PPto[[#This Row],[Ppto. Capex '[USD']]]+PPto[[#This Row],[Ppto. OI '[USD']]] -> 0
A22: 1.02 | B22: Edificación | C22: 1.02 Diseño estructural | D22: 0 | F22: =SUMIFS(BD.PD[Ppto. Orden Interna '[DOP']],BD.PD[Pos],PPto[[#This Row],[Part.]],BD.PD[Tipo Ppto],F$18) -> 0 | G22: =SUMIFS(BD.PD[Ppto. Orden Interna '[DOP']],BD.PD[Pos],PPto[[#This Row],[Part.]],BD.PD[Tipo Ppto],G$18) -> 0 | H22: =PPto[[#This Row],[Ppto. Capex '[DOP']]]+PPto[[#This Row],[Ppto. OI '[DOP']2]] -> 0 | I22: =SUMIFS(BD.PD[Ppto. Orden Interna '[USD']],BD.PD[Pos],PPto[[#This Row],[Part.]],BD.PD[Tipo Ppto],I$18) -> 0 | J22: =SUMIFS(BD.PD[Ppto. Orden Interna '[USD']],BD.PD[Pos],PPto[[#This Row],[Part.]],BD.PD[Tipo Ppto],J$18) -> 0 | K22: =PPto[[#This Row],[Ppto. Capex '[USD']]]+PPto[[#This Row],[Ppto. OI '[USD']]] -> 0
A23: 1.03 | B23: Edificación | C23: 1.03 Diseño electromecánico | D23: 0 | F23: =SUMIFS(BD.PD[Ppto. Orden Interna '[DOP']],BD.PD[Pos],PPto[[#This Row],[Part.]],BD.PD[Tipo Ppto],F$18) -> 0 | G23: =SUMIFS(BD.PD[Ppto. Orden Interna '[DOP']],BD.PD[Pos],PPto[[#This Row],[Part.]],BD.PD[Tipo Ppto],G$18) -> 0 | H23: =PPto[[#This Row],[Ppto. Capex '[DOP']]]+PPto[[#This Row],[Ppto. OI '[DOP']2]] -> 0 | I23: =SUMIFS(BD.PD[Ppto. Orden Interna '[USD']],BD.PD[Pos],PPto[[#This Row],[Part.]],BD.PD[Tipo Ppto],I$18) -> 0 | J23: =SUMIFS(BD.PD[Ppto. Orden Interna '[USD']],BD.PD[Pos],PPto[[#This Row],[Part.]],BD.PD[Tipo Ppto],J$18) -> 0 | K23: =PPto[[#This Row],[Ppto. Capex '[USD']]]+PPto[[#This Row],[Ppto. OI '[USD']]] -> 0
A24: 1.04 | B24: Edificación | C24: 1.04 Diseño sanitario | D24: 0 | F24: =SUMIFS(BD.PD[Ppto. Orden Interna '[DOP']],BD.PD[Pos],PPto[[#This Row],[Part.]],BD.PD[Tipo Ppto],F$18) -> 0 | G24: =SUMIFS(BD.PD[Ppto. Orden Interna '[DOP']],BD.PD[Pos],PPto[[#This Row],[Part.]],BD.PD[Tipo Ppto],G$18) -> 0 | H24: =PPto[[#This Row],[Ppto. Capex '[DOP']]]+PPto[[#This Row],[Ppto. OI '[DOP']2]] -> 0 | I24: =SUMIFS(BD.PD[Ppto. Orden Interna '[USD']],BD.PD[Pos],PPto[[#This Row],[Part.]],BD.PD[Tipo Ppto],I$18) -> 0 | J24: =SUMIFS(BD.PD[Ppto. Orden Interna '[USD']],BD.PD[Pos],PPto[[#This Row],[Part.]],BD.PD[Tipo Ppto],J$18) -> 0 | K24: =PPto[[#This Row],[Ppto. Capex '[USD']]]+PPto[[#This Row],[Ppto. OI '[USD']]] -> 0
A25: 1.05 | B25: Edificación | C25: 1.05 Estudio Geotécnico | D25: 0 | F25: =SUMIFS(BD.PD[Ppto. Orden Interna '[DOP']],BD.PD[Pos],PPto[[#This Row],[Part.]],BD.PD[Tipo Ppto],F$18) -> 0 | G25: =SUMIFS(BD.PD[Ppto. Orden Interna '[DOP']],BD.PD[Pos],PPto[[#This Row],[Part.]],BD.PD[Tipo Ppto],G$18) -> 0 | H25: =PPto[[#This Row],[Ppto. Capex '[DOP']]]+PPto[[#This Row],[Ppto. OI '[DOP']2]] -> 0 | I25: =SUMIFS(BD.PD[Ppto. Orden Interna '[USD']],BD.PD[Pos],PPto[[#This Row],[Part.]],BD.PD[Tipo Ppto],I$18) -> 0 | J25: =SUMIFS(BD.PD[Ppto. Orden Interna '[USD']],BD.PD[Pos],PPto[[#This Row],[Part.]],BD.PD[Tipo Ppto],J$18) -> 0 | K25: =PPto[[#This Row],[Ppto. Capex '[USD']]]+PPto[[#This Row],[Ppto. OI '[USD']]] -> 0
A26: 1.06 | B26: Edificación | C26: 1.06 Levantamiento topográfico | D26: 0 | F26: =SUMIFS(BD.PD[Ppto. Orden Interna '[DOP']],BD.PD[Pos],PPto[[#This Row],[Part.]],BD.PD[Tipo Ppto],F$18) -> 0 | G26: =SUMIFS(BD.PD[Ppto. Orden Interna '[DOP']],BD.PD[Pos],PPto[[#This Row],[Part.]],BD.PD[Tipo Ppto],G$18) -> 0 | H26: =PPto[[#This Row],[Ppto. Capex '[DOP']]]+PPto[[#This Row],[Ppto. OI '[DOP']2]] -> 0 | I26: =SUMIFS(BD.PD[Ppto. Orden Interna '[USD']],BD.PD[Pos],PPto[[#This Row],[Part.]],BD.PD[Tipo Ppto],I$18) -> 0 | J26: =SUMIFS(BD.PD[Ppto. Orden Interna '[USD']],BD.PD[Pos],PPto[[#This Row],[Part.]],BD.PD[Tipo Ppto],J$18) -> 0 | K26: =PPto[[#This Row],[Ppto. Capex '[USD']]]+PPto[[#This Row],[Ppto. OI '[USD']]] -> 0
A27: 1.07 | B27: Edificación | C27: 1.07 Permisos | D27: 0 | F27: =SUMIFS(BD.PD[Ppto. Orden Interna '[DOP']],BD.PD[Pos],PPto[[#This Row],[Part.]],BD.PD[Tipo Ppto],F$18) -> 0 | G27: =SUMIFS(BD.PD[Ppto. Orden Interna '[DOP']],BD.PD[Pos],PPto[[#This Row],[Part.]],BD.PD[Tipo Ppto],G$18) -> 0 | H27: =PPto[[#This Row],[Ppto. Capex '[DOP']]]+PPto[[#This Row],[Ppto. OI '[DOP']2]] -> 0 | I27: =SUMIFS(BD.PD[Ppto. Orden Interna '[USD']],BD.PD[Pos],PPto[[#This Row],[Part.]],BD.PD[Tipo Ppto],I$18) -> 0 | J27: =SUMIFS(BD.PD[Ppto. Orden Interna '[USD']],BD.PD[Pos],PPto[[#This Row],[Part.]],BD.PD[Tipo Ppto],J$18) -> 0 | K27: =PPto[[#This Row],[Ppto. Capex '[USD']]]+PPto[[#This Row],[Ppto. OI '[USD']]] -> 0
A28: 1.08 | B28: Edificación | C28: 1.08 Diseño sistema contra incendios | D28: 0 | F28: =SUMIFS(BD.PD[Ppto. Orden Interna '[DOP']],BD.PD[Pos],PPto[[#This Row],[Part.]],BD.PD[Tipo Ppto],F$18) -> 0 | G28: =SUMIFS(BD.PD[Ppto. Orden Interna '[DOP']],BD.PD[Pos],PPto[[#This Row],[Part.]],BD.PD[Tipo Ppto],G$18) -> 0 | H28: =PPto[[#This Row],[Ppto. Capex '[DOP']]]+PPto[[#This Row],[Ppto. OI '[DOP']2]] -> 0 | I28: =SUMIFS(BD.PD[Ppto. Orden Interna '[USD']],BD.PD[Pos],PPto[[#This Row],[Part.]],BD.PD[Tipo Ppto],I$18) -> 0 | J28: =SUMIFS(BD.PD[Ppto. Orden Interna '[USD']],BD.PD[Pos],PPto[[#This Row],[Part.]],BD.PD[Tipo Ppto],J$18) -> 0 | K28: =PPto[[#This Row],[Ppto. Capex '[USD']]]+PPto[[#This Row],[Ppto. OI '[USD']]] -> 0
A29: 1.09 | B29: Edificación | C29: 1.09 Diseño sistema gas | D29: 0 | F29: =SUMIFS(BD.PD[Ppto. Orden Interna '[DOP']],BD.PD[Pos],PPto[[#This Row],[Part.]],BD.PD[Tipo Ppto],F$18) -> 0 | G29: =SUMIFS(BD.PD[Ppto. Orden Interna '[DOP']],BD.PD[Pos],PPto[[#This Row],[Part.]],BD.PD[Tipo Ppto],G$18) -> 0 | H29: =PPto[[#This Row],[Ppto. Capex '[DOP']]]+PPto[[#This Row],[Ppto. OI '[DOP']2]] -> 0 | I29: =SUMIFS(BD.PD[Ppto. Orden Interna '[USD']],BD.PD[Pos],PPto[[#This Row],[Part.]],BD.PD[Tipo Ppto],I$18) -> 0 | J29: =SUMIFS(BD.PD[Ppto. Orden Interna '[USD']],BD.PD[Pos],PPto[[#This Row],[Part.]],BD.PD[Tipo Ppto],J$18) -> 0 | K29: =PPto[[#This Row],[Ppto. Capex '[USD']]]+PPto[[#This Row],[Ppto. OI '[USD']]] -> 0
A30: 2 | C30: 2.00 Obra Civil | D30: =PPto[[#This Row],[Ppto. Capex '[DOP']]]+PPto[[#This Row],[Ppto. OI '[DOP']2]] -> 29340263 | F30: =SUM(F31:F41) -> 29340263 | G30: =SUM(G31:G41) -> 0 | H30: =PPto[[#This Row],[Ppto. Capex '[DOP']]]+PPto[[#This Row],[Ppto. OI '[DOP']2]] -> 29340263 | I30: =SUM(I31:I41) -> 480987.92 | J30: =SUM(J31:J41) -> 0 | K30: =PPto[[#This Row],[Ppto. Capex '[USD']]]+PPto[[#This Row],[Ppto. OI '[USD']]] -> 480987.92
A31: 2.01 | B31: Edificación | C31: 2.01 Edificación - Obra Civil | D31: =PPto[[#This Row],[Ppto. Capex '[DOP']]]+PPto[[#This Row],[Ppto. OI '[DOP']2]] -> 7081344.5 | F31: =SUMIFS(BD.PD[Ppto. Orden Interna '[DOP']],BD.PD[Pos],PPto[[#This Row],[Part.]],BD.PD[Tipo Ppto],F$18) -> 7081344.5 | G31: =SUMIFS(BD.PD[Ppto. Orden Interna '[DOP']],BD.PD[Pos],PPto[[#This Row],[Part.]],BD.PD[Tipo Ppto],G$18) -> 0 | H31: =PPto[[#This Row],[Ppto. Capex '[DOP']]]+PPto[[#This Row],[Ppto. OI '[DOP']2]] -> 7081344.5 | I31: =SUMIFS(BD.PD[Ppto. Orden Interna '[USD']],BD.PD[Pos],PPto[[#This Row],[Part.]],BD.PD[Tipo Ppto],I$18) -> 116087.61 | J31: =SUMIFS(BD.PD[Ppto. Orden Interna '[USD']],BD.PD[Pos],PPto[[#This Row],[Part.]],BD.PD[Tipo Ppto],J$18) -> 0 | K31: =PPto[[#This Row],[Ppto. Capex '[USD']]]+PPto[[#This Row],[Ppto. OI '[USD']]] -> 116087.61
A32: 2.02 | B32: Edificación | C32: 2.02 Edificación - Estructura Metálica | D32: 0 | F32: =SUMIFS(BD.PD[Ppto. Orden Interna '[DOP']],BD.PD[Pos],PPto[[#This Row],[Part.]],BD.PD[Tipo Ppto],F$18) -> 0 | G32: =SUMIFS(BD.PD[Ppto. Orden Interna '[DOP']],BD.PD[Pos],PPto[[#This Row],[Part.]],BD.PD[Tipo Ppto],G$18) -> 0 | H32: =PPto[[#This Row],[Ppto. Capex '[DOP']]]+PPto[[#This Row],[Ppto. OI '[DOP']2]] -> 0 | I32: =SUMIFS(BD.PD[Ppto. Orden Interna '[USD']],BD.PD[Pos],PPto[[#This Row],[Part.]],BD.PD[Tipo Ppto],I$18) -> 0 | J32: =SUMIFS(BD.PD[Ppto. Orden Interna '[USD']],BD.PD[Pos],PPto[[#This Row],[Part.]],BD.PD[Tipo Ppto],J$18) -> 0 | K32: =PPto[[#This Row],[Ppto. Capex '[USD']]]+PPto[[#This Row],[Ppto. OI '[USD']]] -> 0
A33: 2.03 | B33: Edificación | C33: 2.03 Edificación - Techo S.S. y Cerramientos Multipanel | D33: 0 | F33: =SUMIFS(BD.PD[Ppto. Orden Interna '[DOP']],BD.PD[Pos],PPto[[#This Row],[Part.]],BD.PD[Tipo Ppto],F$18) -> 0 | G33: =SUMIFS(BD.PD[Ppto. Orden Interna '[DOP']],BD.PD[Pos],PPto[[#This Row],[Part.]],BD.PD[Tipo Ppto],G$18) -> 0 | H33: =PPto[[#This Row],[Ppto. Capex '[DOP']]]+PPto[[#This Row],[Ppto. OI '[DOP']2]] -> 0 | I33: =SUMIFS(BD.PD[Ppto. Orden Interna '[USD']],BD.PD[Pos],PPto[[#This Row],[Part.]],BD.PD[Tipo Ppto],I$18) -> 0 | J33: =SUMIFS(BD.PD[Ppto. Orden Interna '[USD']],BD.PD[Pos],PPto[[#This Row],[Part.]],BD.PD[Tipo Ppto],J$18) -> 0 | K33: =PPto[[#This Row],[Ppto. Capex '[USD']]]+PPto[[#This Row],[Ppto. OI '[USD']]] -> 0
A34: 2.04 | B34: Edificación | C34: 2.04 Edificación - Tragaluces "Skylights" | D34: 0 | F34: =SUMIFS(BD.PD[Ppto. Orden Interna '[DOP']],BD.PD[Pos],PPto[[#This Row],[Part.]],BD.PD[Tipo Ppto],F$18) -> 0 | G34: =SUMIFS(BD.PD[Ppto. Orden Interna '[DOP']],BD.PD[Pos],PPto[[#This Row],[Part.]],BD.PD[Tipo Ppto],G$18) -> 0 | H34: =PPto[[#This Row],[Ppto. Capex '[DOP']]]+PPto[[#This Row],[Ppto. OI '[DOP']2]] -> 0 | I34: =SUMIFS(BD.PD[Ppto. Orden Interna '[USD']],BD.PD[Pos],PPto[[#This Row],[Part.]],BD.PD[Tipo Ppto],I$18) -> 0 | J34: =SUMIFS(BD.PD[Ppto. Orden Interna '[USD']],BD.PD[Pos],PPto[[#This Row],[Part.]],BD.PD[Tipo Ppto],J$18) -> 0 | K34: =PPto[[#This Row],[Ppto. Capex '[USD']]]+PPto[[#This Row],[Ppto. OI '[USD']]] -> 0
A35: 2.05 | B35: Equipamiento | C35: 2.05 Instalaciones Sanitarias | D35: =PPto[[#This Row],[Ppto. Capex '[DOP']]]+PPto[[#This Row],[Ppto. OI '[DOP']2]] -> 945223.71 | F35: =SUMIFS(BD.PD[Ppto. Orden Interna '[DOP']],BD.PD[Pos],PPto[[#This Row],[Part.]],BD.PD[Tipo Ppto],F$18) -> 945223.71 | G35: =SUMIFS(BD.PD[Ppto. Orden Interna '[DOP']],BD.PD[Pos],PPto[[#This Row],[Part.]],BD.PD[Tipo Ppto],G$18) -> 0 | H35: =PPto[[#This Row],[Ppto. Capex '[DOP']]]+PPto[[#This Row],[Ppto. OI '[DOP']2]] -> 945223.71 | I35: =SUMIFS(BD.PD[Ppto. Orden Interna '[USD']],BD.PD[Pos],PPto[[#This Row],[Part.]],BD.PD[Tipo Ppto],I$18) -> 15495.471 | J35: =SUMIFS(BD.PD[Ppto. Orden Interna '[USD']],BD.PD[Pos],PPto[[#This Row],[Part.]],BD.PD[Tipo Ppto],J$18) -> 0 | K35: =PPto[[#This Row],[Ppto. Capex '[USD']]]+PPto[[#This Row],[Ppto. OI '[USD']]] -> 15495.471
A36: 2.06 | B36: Equipamiento | C36: 2.06 Instalación de Gas | D36: =PPto[[#This Row],[Ppto. Capex '[DOP']]]+PPto[[#This Row],[Ppto. OI '[DOP']2]] -> 668846.99 | F36: =SUMIFS(BD.PD[Ppto. Orden Interna '[DOP']],BD.PD[Pos],PPto[[#This Row],[Part.]],BD.PD[Tipo Ppto],F$18) -> 668846.99 | G36: =SUMIFS(BD.PD[Ppto. Orden Interna '[DOP']],BD.PD[Pos],PPto[[#This Row],[Part.]],BD.PD[Tipo Ppto],G$18) -> 0 | H36: =PPto[[#This Row],[Ppto. Capex '[DOP']]]+PPto[[#This Row],[Ppto. OI '[DOP']2]] -> 668846.99 | I36: =SUMIFS(BD.PD[Ppto. Orden Interna '[USD']],BD.PD[Pos],PPto[[#This Row],[Part.]],BD.PD[Tipo Ppto],I$18) -> 10964.705 | J36: =SUMIFS(BD.PD[Ppto. Orden Interna '[USD']],BD.PD[Pos],PPto[[#This Row],[Part.]],BD.PD[Tipo Ppto],J$18) -> 0 | K36: =PPto[[#This Row],[Ppto. Capex '[USD']]]+PPto[[#This Row],[Ppto. OI '[USD']]] -> 10964.705
A37: 2.07 | B37: Equipamiento | C37: 2.07 Sistema Contra Incendios | D37: =PPto[[#This Row],[Ppto. Capex '[DOP']]]+PPto[[#This Row],[Ppto. OI '[DOP']2]] -> 5676792 | F37: =SUMIFS(BD.PD[Ppto. Orden Interna '[DOP']],BD.PD[Pos],PPto[[#This Row],[Part.]],BD.PD[Tipo Ppto],F$18) -> 5676792 | G37: =SUMIFS(BD.PD[Ppto. Orden Interna '[DOP']],BD.PD[Pos],PPto[[#This Row],[Part.]],BD.PD[Tipo Ppto],G$18) -> 0 | H37: =PPto[[#This Row],[Ppto. Capex '[DOP']]]+PPto[[#This Row],[Ppto. OI '[DOP']2]] -> 5676792 | I37: =SUMIFS(BD.PD[Ppto. Orden Interna '[USD']],BD.PD[Pos],PPto[[#This Row],[Part.]],BD.PD[Tipo Ppto],I$18) -> 93062.165 | J37: =SUMIFS(BD.PD[Ppto. Orden Interna '[USD']],BD.PD[Pos],PPto[[#This Row],[Part.]],BD.PD[Tipo Ppto],J$18) -> 0 | K37: =PPto[[#This Row],[Ppto. Capex '[USD']]]+PPto[[#This Row],[Ppto. OI '[USD']]] -> 93062.165
A38: 2.08 | B38: Equipamiento | C38: 2.08 Instalaciones Mecánicas | D38: =PPto[[#This Row],[Ppto. Capex '[DOP']]]+PPto[[#This Row],[Ppto. OI '[DOP']2]] -> 14306511 | F38: =SUMIFS(BD.PD[Ppto. Orden Interna '[DOP']],BD.PD[Pos],PPto[[#This Row],[Part.]],BD.PD[Tipo Ppto],F$18) -> 14306511 | G38: =SUMIFS(BD.PD[Ppto. Orden Interna '[DOP']],BD.PD[Pos],PPto[[#This Row],[Part.]],BD.PD[Tipo Ppto],G$18) -> 0 | H38: =PPto[[#This Row],[Ppto. Capex '[DOP']]]+PPto[[#This Row],[Ppto. OI '[DOP']2]] -> 14306511 | I38: =SUMIFS(BD.PD[Ppto. Orden Interna '[USD']],BD.PD[Pos],PPto[[#This Row],[Part.]],BD.PD[Tipo Ppto],I$18) -> 234532.97 | J38: =SUMIFS(BD.PD[Ppto. Orden Interna '[USD']],BD.PD[Pos],PPto[[#This Row],[Part.]],BD.PD[Tipo Ppto],J$18) -> 0 | K38: =PPto[[#This Row],[Ppto. Capex '[USD']]]+PPto[[#This Row],[Ppto. OI '[USD']]] -> 234532.97
A39: 2.09 | B39: Equipamiento | C39: 2.09 Rejillas y Sumideros | D39: =PPto[[#This Row],[Ppto. Capex '[DOP']]]+PPto[[#This Row],[Ppto. OI '[DOP']2]] -> 661544.36 | F39: =SUMIFS(BD.PD[Ppto. Orden Interna '[DOP']],BD.PD[Pos],PPto[[#This Row],[Part.]],BD.PD[Tipo Ppto],F$18) -> 661544.36 | G39: =SUMIFS(BD.PD[Ppto. Orden Interna '[DOP']],BD.PD[Pos],PPto[[#This Row],[Part.]],BD.PD[Tipo Ppto],G$18) -> 0 | H39: =PPto[[#This Row],[Ppto. Capex '[DOP']]]+PPto[[#This Row],[Ppto. OI '[DOP']2]] -> 661544.36 | I39: =SUMIFS(BD.PD[Ppto. Orden Interna '[USD']],BD.PD[Pos],PPto[[#This Row],[Part.]],BD.PD[Tipo Ppto],I$18) -> 10844.99 | J39: =SUMIFS(BD.PD[Ppto. Orden Interna '[USD']],BD.PD[Pos],PPto[[#This Row],[Part.]],BD.PD[Tipo Ppto],J$18) -> 0 | K39: =PPto[[#This Row],[Ppto. Capex '[USD']]]+PPto[[#This Row],[Ppto. OI '[USD']]] -> 10844.99
A40: 2.1 | B40: Edificación | C40: 2.10 Supervisión Civil y Sanitaria | D40: 0 | F40: =SUMIFS(BD.PD[Ppto. Orden Interna '[DOP']],BD.PD[Pos],PPto[[#This Row],[Part.]],BD.PD[Tipo Ppto],F$18) -> 0 | G40: =SUMIFS(BD.PD[Ppto. Orden Interna '[DOP']],BD.PD[Pos],PPto[[#This Row],[Part.]],BD.PD[Tipo Ppto],G$18) -> 0 | H40: =PPto[[#This Row],[Ppto. Capex '[DOP']]]+PPto[[#This Row],[Ppto. OI '[DOP']2]] -> 0 | I40: =SUMIFS(BD.PD[Ppto. Orden Interna '[USD']],BD.PD[Pos],PPto[[#This Row],[Part.]],BD.PD[Tipo Ppto],I$18) -> 0 | J40: =SUMIFS(BD.PD[Ppto. Orden Interna '[USD']],BD.PD[Pos],PPto[[#This Row],[Part.]],BD.PD[Tipo Ppto],J$18) -> 0 | K40: =PPto[[#This Row],[Ppto. Capex '[USD']]]+PPto[[#This Row],[Ppto. OI '[USD']]] -> 0
A41: 2.11 | B41: Edificación | C41: 2.11 Supervisión Arquitectónica | D41: 0 | F41: =SUMIFS(BD.PD[Ppto. Orden Interna '[DOP']],BD.PD[Pos],PPto[[#This Row],[Part.]],BD.PD[Tipo Ppto],F$18) -> 0 | G41: =SUMIFS(BD.PD[Ppto. Orden Interna '[DOP']],BD.PD[Pos],PPto[[#This Row],[Part.]],BD.PD[Tipo Ppto],G$18) -> 0 | H41: =PPto[[#This Row],[Ppto. Capex '[DOP']]]+PPto[[#This Row],[Ppto. OI '[DOP']2]] -> 0 | I41: =SUMIFS(BD.PD[Ppto. Orden Interna '[USD']],BD.PD[Pos],PPto[[#This Row],[Part.]],BD.PD[Tipo Ppto],I$18) -> 0 | J41: =SUMIFS(BD.PD[Ppto. Orden Interna '[USD']],BD.PD[Pos],PPto[[#This Row],[Part.]],BD.PD[Tipo Ppto],J$18) -> 0 | K41: =PPto[[#This Row],[Ppto. Capex '[USD']]]+PPto[[#This Row],[Ppto. OI '[USD']]] -> 0
A42: 3 | C42: 3.00 Sistema Eléctrico | D42: =PPto[[#This Row],[Ppto. Capex '[DOP']]]+PPto[[#This Row],[Ppto. OI '[DOP']2]] -> 27317363 | F42: =SUM(F43:F46) -> 27317363 | G42: =SUM(G43:G46) -> 0 | H42: =PPto[[#This Row],[Ppto. Capex '[DOP']]]+PPto[[#This Row],[Ppto. OI '[DOP']2]] -> 27317363 | I42: =SUM(I43:I46) -> 447825.63 | J42: =SUM(J43:J46) -> 0 | K42: =PPto[[#This Row],[Ppto. Capex '[USD']]]+PPto[[#This Row],[Ppto. OI '[USD']]] -> 447825.63
...

Sheet Presupuesto
B3: Presupuesto Las Terrenas
B5: 60 | G5: N/A
G6: Presupuesto
B7: TOTAL GENERAL ESTIMADO | G7: =SUM(G10:G12) -> 3776925.1
B9: Resumen de Partidas
B10: EDIFICACION | G10: =SUMIF($C$18:$C$102,"2",$G$18:$G$102) -> 810851.33
B11: EQUIPAMIENTO | G11: =SUMIF($C$18:$C$102,"1",$G$18:$G$102) -> 2966073.8
B12: TERRENO | G12: 0
B13: Área de la Localidad
B14: M2 Construccion
B15: M2 Sala de Ventas
B16: M2 Terreno
B17: Edificación, Instalaciones y Equipamientos
A18: 1 | B18: Estudios Preliminares | G18: =SUM(G19:G27) -> 0
A19: 1.01 | B19: Diseño arquitectónico | C19: 2 | D19: USD | E19: =IF(D19="USD",1,$B$5) -> 1 | F19: 0 | G19: =IF(D19="DOP",F19/E19,F19) -> 0
A20: 1.02 | B20: Diseño estructural | C20: 2 | D20: USD | E20: =IF(D20="USD",1,$B$5) -> 1 | F20: 0 | G20: =IF(D20="DOP",F20/E20,F20) -> 0
A21: 1.03 | B21: Diseño electromecánico | C21: 2 | D21: USD | E21: =IF(D21="USD",1,$B$5) -> 1 | F21: 0 | G21: =IF(D21="DOP",F21/E21,F21) -> 0
A22: 1.04 | B22: Diseño sanitario | C22: 2 | D22: USD | E22: =IF(D22="USD",1,$B$5) -> 1 | F22: 0 | G22: =IF(D22="DOP",F22/E22,F22) -> 0
A23: 1.08 | B23: Diseño sistema contra incendios | C23: 2 | D23: USD | E23: =IF(D23="USD",1,$B$5) -> 1 | F23: 0 | G23: =IF(D23="DOP",F23/E23,F23) -> 0
A24: 1.09 | B24: Diseño sistema gas | C24: 2 | D24: USD | E24: =IF(D24="USD",1,$B$5) -> 1 | F24: 0 | G24: =IF(D24="DOP",F24/E24,F24) -> 0
A25: 1.05 | B25: Estudio Geotécnico | C25: 2 | D25: USD | E25: =IF(D25="USD",1,$B$5) -> 1 | F25: 0 | G25: =IF(D25="DOP",F25/E25,F25) -> 0
A26: 1.06 | B26: Levantamiento topográfico | C26: 2 | D26: USD | E26: =IF(D26="USD",1,$B$5) -> 1 | F26: 0 | G26: =IF(D26="DOP",F26/E26,F26) -> 0
A27: 1.07 | B27: Permisos | C27: 2 | D27: USD | E27: =IF(D27="USD",1,$B$5) -> 1 | F27: 0 | G27: =IF(D27="DOP",F27/E27,F27) -> 0
A29: 2 | B29: Obra Civil | G29: =SUM(G30:G41) -> 287553.13
A30: 2.01 | B30: Edificación - Obra Civil | C30: 2 | D30: USD | E30: =IF(D30="USD",1,$B$5) -> 1 | F30: 0 | G30: 18449.15
A31: 2.02 | B31: Edificación - Estructura Metálica | C31: 2 | D31: dop | E31: =IF(D31="USD",1,$B$5) -> 60 | F31: 0 | G31: 0
A32: 2.03 | B32: Edificación - Techo S.S. y Cerramientos Multipanel | C32: 2 | D32: dop | E32: =IF(D32="USD",1,$B$5) -> 60 | F32: 0 | G32: 0
A33: 2.04 | B33: Edificación - Tragaluces "Skylights" | C33: 2 | D33: dop | E33: =IF(D33="USD",1,$B$5) -> 60 | F33: 0 | G33: 0
A34: 2.05 | B34: Instalaciones Sanitarias | C34: 2 | D34: dop | E34: =IF(D34="USD",1,$B$5) -> 60 | F34: 0 | G34: 25100
A35: 2.06 | B35: Instalación de Gas | C35: 2 | D35: dop | E35: =IF(D35="USD",1,$B$5) -> 60 | F35: 0 | G35: 7500
A36: 2.07 | B36: Sistema Contra Incendios | C36: 2 | D36: dop | E36: =IF(D36="USD",1,$B$5) -> 60 | F36: 0 | G36: 113206.86
A37: 2.08 | B37: Instalaciones Mecánicas | C37: 2 | D37: dop | E37: =IF(D37="USD",1,$B$5) -> 60 | F37: 0 | G37: 112643.09
A38: 2.09 | B38: Rejillas y Sumideros | C38: 2 | D38: dop | E38: =IF(D38="USD",1,$B$5) -> 60 | F38: 0 | G38: 10654.035
A39: 2.1 | B39: Supervisión Civil y Sanitaria | C39: 2 | D39: dop | E39: =IF(D39="USD",1,$B$5) -> 60 | F39: 0 | G39: 0
A40: 2.11 | B40: Supervisión Arquitectónica | C40: 2 | D40: dop | E40: =IF(D40="USD",1,$B$5) -> 60 | F40: 0 | G40: 0
A42: 3 | B42: Sistema Eléctrico | G42: =SUBTOTAL(9,G43:G47) -> 235851.53
A43: 3.01 | B43: Instalaciones Eléctricas | C43: 2 | D43: USD | E43: =IF(D43="USD",1,$B$5) -> 1 | F43: 0 | G43: 0
A44: 3.02 | B44: Supervisión Eléctrica | C44: 2 | D44: dop | E44: =IF(D44="USD",1,$B$5) -> 60 | F44: 0 | G44: 0
A45: 3.03 | B45: Generadores | C45: 2 | D45: dop | E45: =IF(D45="USD",1,$B$5) -> 60 | F45: 0 | G45: 220508.5
A46: 3.04 | B46: Inversor y UPS | C46: 2 | D46: dop | E46: =IF(D46="USD",1,$B$5) -> 60 | F46: 0 | G46: 15343.026
...

Sheet Presupuesto vs Real
B3: Presupuesto Terrenas MC33
K4: Optimización del presupuesto
B5: 60 | G5: N/A | H5: N/A | K5: =+I7*59 -> 1.3872683e+10
G6: Presupuestado | H6: Real | I6: Diferencia
B7: TOTAL GENERAL ESTIMADO | G7: 2.3889382e+08 | H7: =SUM(H10:H12) -> 3763601.6 | I7: =+G7-H7 -> 2.3513022e+08
B9: Resumen de Partidas
B10: EDIFICACION | G10: 2.3796806e+08 | H10: =SUMIF($C$18:$C$100,"2",H18:H94) -> 1222167.5
B11: EQUIPAMIENTO | G11: 925759.13 | H11: =SUMIF($C$18:$C$100,"1",H18:H94) -> 2541434.1
B12: TERRENO | G12: 0 | H12: 0
B13: Área de la Localidad
B14: M2 Construccion
B15: M2 Sala de Ventas
B16: M2 Terreno
B17: Edificación, Instalaciones y Equipamientos
A18: 1 | B18: Estudios Preliminares | G18: =SUM(G19:G27) -> 0 | H18: =SUM(H19:H27) -> 0 | I18: =SUM(I19:I27) -> 0
A19: 1.01 | B19: Diseño arquitectónico | C19: 2 | D19: USD | E19: =IF(D19="USD",1,$B$5) -> 1 | F19: 0 | G19: =IF(D19="DOP",F19/E19,F19) -> 0 | H19: =IF(E19="DOP",G19/F19,G19) -> 0 | I19: =IF(F19="DOP",H19/G19,H19) -> 0
A20: 1.02 | B20: Diseño estructural | C20: 2 | D20: USD | E20: =IF(D20="USD",1,$B$5) -> 1 | F20: 0 | G20: =IF(D20="DOP",F20/E20,F20) -> 0 | H20: =IF(E20="DOP",G20/F20,G20) -> 0 | I20: =IF(F20="DOP",H20/G20,H20) -> 0
A21: 1.03 | B21: Diseño electromecánico | C21: 2 | D21: USD | E21: =IF(D21="USD",1,$B$5) -> 1 | F21: 0 | G21: =IF(D21="DOP",F21/E21,F21) -> 0 | H21: =IF(E21="DOP",G21/F21,G21) -> 0 | I21: =IF(F21="DOP",H21/G21,H21) -> 0
A22: 1.04 | B22: Diseño sanitario | C22: 2 | D22: USD | E22: =IF(D22="USD",1,$B$5) -> 1 | F22: 0 | G22: =IF(D22="DOP",F22/E22,F22) -> 0 | H22: =IF(E22="DOP",G22/F22,G22) -> 0 | I22: =IF(F22="DOP",H22/G22,H22) -> 0
A23: 1.08 | B23: Diseño sistema contra incendios | C23: 2 | D23: USD | E23: =IF(D23="USD",1,$B$5) -> 1 | F23: 0 | G23: =IF(D23="DOP",F23/E23,F23) -> 0 | H23: =IF(E23="DOP",G23/F23,G23) -> 0 | I23: =IF(F23="DOP",H23/G23,H23) -> 0
A24: 1.09 | B24: Diseño sistema gas | C24: 2 | D24: USD | E24: =IF(D24="USD",1,$B$5) -> 1 | F24: 0 | G24: =IF(D24="DOP",F24/E24,F24) -> 0 | H24: =IF(E24="DOP",G24/F24,G24) -> 0 | I24: =IF(F24="DOP",H24/G24,H24) -> 0
A25: 1.05 | B25: Estudio Geotécnico | C25: 2 | D25: USD | E25: =IF(D25="USD",1,$B$5) -> 1 | F25: 0 | G25: =IF(D25="DOP",F25/E25,F25) -> 0 | H25: =IF(E25="DOP",G25/F25,G25) -> 0 | I25: =IF(F25="DOP",H25/G25,H25) -> 0
A26: 1.06 | B26: Levantamiento topográfico | C26: 2 | D26: USD | E26: =IF(D26="USD",1,$B$5) -> 1 | F26: 0 | G26: =IF(D26="DOP",F26/E26,F26) -> 0 | H26: =IF(E26="DOP",G26/F26,G26) -> 0 | I26: =IF(F26="DOP",H26/G26,H26) -> 0
A27: 1.07 | B27: Permisos | C27: 2 | D27: USD | E27: =IF(D27="USD",1,$B$5) -> 1 | F27: 0 | G27: =IF(D27="DOP",F27/E27,F27) -> 0 | H27: =IF(E27="DOP",G27/F27,G27) -> 0 | I27: =IF(F27="DOP",H27/G27,H27) -> 0
I28: =IF(F28="DOP",H28/G28,H28) -> 0
A29: 2 | B29: Obra Civil | G29: =SUM(G30:G41) -> 18750294 | H29: =SUM(H30:H41) -> 480987.92
A30: 2.01 | B30: Edificación - Obra Civil | C30: 2 | D30: USD | E30: =IF(D30="USD",1,$B$5) -> 1 | F30: 20484.94 | G30: 925759.13 | H30: 116087.61 | I30: =+G30-H30 -> 809671.52
A31: 2.02 | B31: Edificación - Estructura Metálica | C31: 2 | D31: USD | E31: =IF(D31="USD",1,$B$5) -> 1 | F31: 0 | G31: =IF(D31="DOP",F31/E31,F31) -> 0 | H31: 0 | I31: =+G31-H31 -> 0
A32: 2.03 | B32: Edificación - Techo S.S. y Cerramientos Multipanel | C32: 2 | D32: USD | E32: =IF(D32="USD",1,$B$5) -> 1 | F32: 0 | G32: =IF(D32="DOP",F32/E32,F32) -> 0 | H32: 0 | I32: =+G32-H32 -> 0
A33: 2.04 | B33: Edificación - Tragaluces "Skylights" | C33: 2 | D33: USD | E33: =IF(D33="USD",1,$B$5) -> 1 | F33: 0 | G33: =IF(D33="DOP",F33/E33,F33) -> 0 | H33: 0 | I33: =+G33-H33 -> 0
A34: 2.05 | B34: Instalaciones Sanitarias | C34: 2 | D34: USD | E34: =IF(D34="USD",1,$B$5) -> 1 | F34: 25100 | G34: 945223.71 | H34: 15495.471 | I34: =+G34-H34 -> 929728.24
A35: 2.06 | B35: Instalación de Gas | C35: 2 | D35: USD | E35: =IF(D35="USD",1,$B$5) -> 1 | F35: 7330.6452 | G35: 550000 | H35: 10964.705 | I35: =+G35-H35 -> 539035.3
A36: 2.07 | B36: Sistema Contra Incendios | C36: 2 | D36: USD | E36: =IF(D36="USD",1,$B$5) -> 1 | F36: 114712.49 | G36: 7031433.7 | H36: 93062.165 | I36: =+G36-H36 -> 6938371.6
A37: 2.08 | B37: Instalaciones Mecánicas | C37: 2 | D37: USD | E37: =IF(D37="USD",1,$B$5) -> 1 | F37: 80483.865 | G37: 8626672.8 | H37: 234532.97 | I37: =+G37-H37 -> 8392139.8
A38: 2.09 | B38: Rejillas y Sumideros | C38: 2 | D38: USD | E38: =IF(D38="USD",1,$B$5) -> 1 | F38: 12639.2 | G38: 671204.2 | H38: 10844.99 | I38: =+G38-H38 -> 660359.21
A39: 2.1 | B39: Supervisión Civil y Sanitaria | C39: 2 | D39: USD | E39: =IF(D39="USD",1,$B$5) -> 1 | F39: 0 | G39: =IF(D39="DOP",F39/E39,F39) -> 0 | H39: 0 | I39: =+G39-H39 -> 0
A40: 2.11 | B40: Supervisión Arquitectónica | C40: 2 | D40: USD | E40: =IF(D40="USD",1,$B$5) -> 1 | F40: 0 | G40: =IF(D40="DOP",F40/E40,F40) -> 0 | H40: 0 | I40: =+G40-H40 -> 0
I41: =+G41-H41 -> 0
A42: 3 | B42: Sistema Eléctrico | G42: =SUBTOTAL(9,G43:G47) -> 15163842 | H42: =SUBTOTAL(9,H43:H47) -> 447825.63
A43: 3.01 | B43: Instalaciones Eléctricas | C43: 2 | D43: USD | E43: =IF(D43="USD",1,$B$5) -> 1 | F43: 0 | G43: =IF(D43="DOP",F43/E43,F43) -> 0 | H43: 259705.61 | I43: =+G43-H43 -> -259705.61
...

Sheet BD Plan Detallado
A1: Plan Detallado: Iniciativa Las Terrenas | K1: USD | L1: EUR | R1: Capex | W1: *** Per.P es igual al numero de mes, iniciando en Mayo 2023 como el mes (1) | AL1: Rojo: La sumatoria de pagos no coincide con Ppto.
A2: 46302 | J2: Tasa | K2: 61 | L2: 72 | R2: OI | W2: Planificación de Pagos por Partida
D3: OI / Capex | P3: =SUBTOTAL(109,BD.PD[Ppto. Orden Interna '[DOP']]) -> 2.3665605e+08 | Q3: =SUBTOTAL(109,BD.PD[Ppto. Orden Interna '[USD']]) -> 3879607.3 | W3: 1er Pago | Z3: 2do Pago | AC3: 3er Pago | AF3: 4to Pago | AI3: 5to Pago
A4: Pos | B4: . | C4: Partidas | D4: Tipo Ppto | E4: Plan | F4: Item | G4: Etapa | H4: Orden de compra | I4: Comentarios | J4: Fecha | K4: Cant. | L4: Mon | M4: Tasa | N4: Precio Und. | O4: Valor Neto [DOP] | P4: Liquid. [%] | Q4: Ppto. Orden Interna [DOP] | R4: Ppto. Orden Interna [USD] | S4: Comentario | T4: Notas | U4: Orden Interna | V4: AFeC | W4: Proveedor | X4: Per.P1 | Y4: Av.P1 [%] | Z4: Pago 1 | AA4: Per.P2 | AB4: Av.P2 [%] | AC4: Pago 2 | AD4: Per.P3 | AE4: Av.P3 [%] | AF4: Pago 3 | AG4: Per.P4 | AH4: Av.P4 [%] | AI4: Pago 4 | AJ4: Per.P5 | AK4: Av.P5 [%] | AL4: Pago 5 | AM4: Total Flujo Caja | AN4: Formato | AO4: Tienda | AP4: Nomenclatura | AQ4: Closter | AR4: Iniciativa | AS4: Status
A5: 1.01 | B5: * | C5: =VLOOKUP(BD.PD[[#This Row],[Pos]],PPto[],3,FALSE) -> 1.01 Diseño arquitectónico | D5: * | E5: =IF(BD.PD[[#This Row],[.]]="*",VLOOKUP(BD.PD[[#This Row],[Pos]],Presupuesto!A:H,7,FALSE),"") -> 0 | K5: 1 | L5: USD | M5: =IF(BD.PD[[#This Row],[Mon]]="DOP",1,HLOOKUP(BD.PD[[#This Row],[Mon]],$K$1:$L$2,2,FALSE)) -> 61 | N5: 0 | O5: =BD.PD[[#This Row],[Cant.]]*BD.PD[[#This Row],[ Tasa ]]*BD.PD[[#This Row],[ Precio Und.]] -> 0 | P5: 0 | Q5: =IF(BD.PD[[#This Row],[Liquid. '[%']]]<>0,(BD.PD[[#This Row],[Valor Neto '[DOP']]]*BD.PD[[#This Row],[Liquid. '[%']]])+BD.PD[[#This Row],[Valor Neto '[DOP']]],BD.PD[[#This Row],[Valor Neto '[DOP']]]) -> 0 | R5: =BD.PD[[#This Row],[Ppto. Orden Interna '[DOP']]]/HLOOKUP("USD",$K$1:$L$2,2,FALSE) -> 0 | Z5: =BD.PD[[#This Row],[Av.P1 '[%']]]*BD.PD[[#This Row],[Ppto. Orden Interna '[DOP']]] -> 0 | AC5: =BD.PD[[#This Row],[Av.P2 '[%']]]*BD.PD[[#This Row],[Ppto. Orden Interna '[DOP']]] -> 0 | AF5: =BD.PD[[#This Row],[Av.P3 '[%']]]*BD.PD[[#This Row],[Ppto. Orden Interna '[DOP']]] -> 0 | AM5: =BD.PD[[#This Row],[Pago 3]]+BD.PD[[#This Row],[Pago 2]]+BD.PD[[#This Row],[Pago 1]] -> 0
A6: 1.02 | B6: * | C6: =VLOOKUP(BD.PD[[#This Row],[Pos]],PPto[],3,FALSE) -> 1.02 Diseño estructural | D6: * | E6: =IF(BD.PD[[#This Row],[.]]="*",VLOOKUP(BD.PD[[#This Row],[Pos]],Presupuesto!A:H,7,FALSE),"") -> 0 | K6: 1 | L6: USD | M6: =IF(BD.PD[[#This Row],[Mon]]="DOP",1,HLOOKUP(BD.PD[[#This Row],[Mon]],$K$1:$L$2,2,FALSE)) -> 61 | N6: 0 | O6: =BD.PD[[#This Row],[Cant.]]*BD.PD[[#This Row],[ Tasa ]]*BD.PD[[#This Row],[ Precio Und.]] -> 0 | P6: 0 | Q6: =IF(BD.PD[[#This Row],[Liquid. '[%']]]<>0,(BD.PD[[#This Row],[Valor Neto '[DOP']]]*BD.PD[[#This Row],[Liquid. '[%']]])+BD.PD[[#This Row],[Valor Neto '[DOP']]],BD.PD[[#This Row],[Valor Neto '[DOP']]]) -> 0 | R6: =BD.PD[[#This Row],[Ppto. Orden Interna '[DOP']]]/HLOOKUP("USD",$K$1:$L$2,2,FALSE) -> 0 | Z6: =BD.PD[[#This Row],[Av.P1 '[%']]]*BD.PD[[#This Row],[Ppto. Orden Interna '[DOP']]] -> 0 | AC6: =BD.PD[[#This Row],[Av.P2 '[%']]]*BD.PD[[#This Row],[Ppto. Orden Interna '[DOP']]] -> 0 | AF6: =BD.PD[[#This Row],[Av.P3 '[%']]]*BD.PD[[#This Row],[Ppto. Orden Interna '[DOP']]] -> 0 | AM6: =BD.PD[[#This Row],[Pago 3]]+BD.PD[[#This Row],[Pago 2]]+BD.PD[[#This Row],[Pago 1]] -> 0
A7: 1.03 | B7: * | C7: =VLOOKUP(BD.PD[[#This Row],[Pos]],PPto[],3,FALSE) -> 1.03 Diseño electromecánico | D7: * | E7: =IF(BD.PD[[#This Row],[.]]="*",VLOOKUP(BD.PD[[#This Row],[Pos]],Presupuesto!A:H,7,FALSE),"") -> 0 | K7: 1 | L7: USD | M7: =IF(BD.PD[[#This Row],[Mon]]="DOP",1,HLOOKUP(BD.PD[[#This Row],[Mon]],$K$1:$L$2,2,FALSE)) -> 61 | N7: 0 | O7: =BD.PD[[#This Row],[Cant.]]*BD.PD[[#This Row],[ Tasa ]]*BD.PD[[#This Row],[ Precio Und.]] -> 0 | P7: 0 | Q7: =IF(BD.PD[[#This Row],[Liquid. '[%']]]<>0,(BD.PD[[#This Row],[Valor Neto '[DOP']]]*BD.PD[[#This Row],[Liquid. '[%']]])+BD.PD[[#This Row],[Valor Neto '[DOP']]],BD.PD[[#This Row],[Valor Neto '[DOP']]]) -> 0 | R7: =BD.PD[[#This Row],[Ppto. Orden Interna '[DOP']]]/HLOOKUP("USD",$K$1:$L$2,2,FALSE) -> 0 | Z7: =BD.PD[[#This Row],[Av.P1 '[%']]]*BD.PD[[#This Row],[Ppto. Orden Interna '[DOP']]] -> 0 | AC7: =BD.PD[[#This Row],[Av.P2 '[%']]]*BD.PD[[#This Row],[Ppto. Orden Interna '[DOP']]] -> 0 | AF7: =BD.PD[[#This Row],[Av.P3 '[%']]]*BD.PD[[#This Row],[Ppto. Orden Interna '[DOP']]] -> 0 | AM7: =BD.PD[[#This Row],[Pago 3]]+BD.PD[[#This Row],[Pago 2]]+BD.PD[[#This Row],[Pago 1]] -> 0
A8: 1.04 | B8: * | C8: =VLOOKUP(BD.PD[[#This Row],[Pos]],PPto[],3,FALSE) -> 1.04 Diseño sanitario | D8: * | E8: =IF(BD.PD[[#This Row],[.]]="*",VLOOKUP(BD.PD[[#This Row],[Pos]],Presupuesto!A:H,7,FALSE),"") -> 0 | K8: 1 | L8: USD | M8: =IF(BD.PD[[#This Row],[Mon]]="DOP",1,HLOOKUP(BD.PD[[#This Row],[Mon]],$K$1:$L$2,2,FALSE)) -> 61 | N8: 0 | O8: =BD.PD[[#This Row],[Cant.]]*BD.PD[[#This Row],[ Tasa ]]*BD.PD[[#This Row],[ Precio Und.]] -> 0 | P8: 0 | Q8: =IF(BD.PD[[#This Row],[Liquid. '[%']]]<>0,(BD.PD[[#This Row],[Valor Neto '[DOP']]]*BD.PD[[#This Row],[Liquid. '[%']]])+BD.PD[[#This Row],[Valor Neto '[DOP']]],BD.PD[[#This Row],[Valor Neto '[DOP']]]) -> 0 | R8: =BD.PD[[#This Row],[Ppto. Orden Interna '[DOP']]]/HLOOKUP("USD",$K$1:$L$2,2,FALSE) -> 0 | Z8: =BD.PD[[#This Row],[Av.P1 '[%']]]*BD.PD[[#This Row],[Ppto. Orden Interna '[DOP']]] -> 0 | AC8: =BD.PD[[#This Row],[Av.P2 '[%']]]*BD.PD[[#This Row],[Ppto. Orden Interna '[DOP']]] -> 0 | AF8: =BD.PD[[#This Row],[Av.P3 '[%']]]*BD.PD[[#This Row],[Ppto. Orden Interna '[DOP']]] -> 0 | AM8: =BD.PD[[#This Row],[Pago 3]]+BD.PD[[#This Row],[Pago 2]]+BD.PD[[#This Row],[Pago 1]] -> 0
A9: 1.05 | B9: * | C9: =VLOOKUP(BD.PD[[#This Row],[Pos]],PPto[],3,FALSE) -> 1.05 Estudio Geotécnico | D9: * | E9: =IF(BD.PD[[#This Row],[.]]="*",VLOOKUP(BD.PD[[#This Row],[Pos]],Presupuesto!A:H,7,FALSE),"") -> 0 | K9: 1 | L9: USD | M9: =IF(BD.PD[[#This Row],[Mon]]="DOP",1,HLOOKUP(BD.PD[[#This Row],[Mon]],$K$1:$L$2,2,FALSE)) -> 61 | N9: 0 | O9: =BD.PD[[#This Row],[Cant.]]*BD.PD[[#This Row],[ Tasa ]]*BD.PD[[#This Row],[ Precio Und.]] -> 0 | P9: 0 | Q9: =IF(BD.PD[[#This Row],[Liquid. '[%']]]<>0,(BD.PD[[#This Row],[Valor Neto '[DOP']]]*BD.PD[[#This Row],[Liquid. '[%']]])+BD.PD[[#This Row],[Valor Neto '[DOP']]],BD.PD[[#This Row],[Valor Neto '[DOP']]]) -> 0 | R9: =BD.PD[[#This Row],[Ppto. Orden Interna '[DOP']]]/HLOOKUP("USD",$K$1:$L$2,2,FALSE) -> 0 | Z9: =BD.PD[[#This Row],[Av.P1 '[%']]]*BD.PD[[#This Row],[Ppto. Orden Interna '[DOP']]] -> 0 | AC9: =BD.PD[[#This Row],[Av.P2 '[%']]]*BD.PD[[#This Row],[Ppto. Orden Interna '[DOP']]] -> 0 | AF9: =BD.PD[[#This Row],[Av.P3 '[%']]]*BD.PD[[#This Row],[Ppto. Orden Interna '[DOP']]] -> 0 | AM9: =BD.PD[[#This Row],[Pago 3]]+BD.PD[[#This Row],[Pago 2]]+BD.PD[[#This Row],[Pago 1]] -> 0
A10: 1.06 | B10: * | C10: =VLOOKUP(BD.PD[[#This Row],[Pos]],PPto[],3,FALSE) -> 1.06 Levantamiento topográfico | D10: * | E10: =IF(BD.PD[[#This Row],[.]]="*",VLOOKUP(BD.PD[[#This Row],[Pos]],Presupuesto!A:H,7,FALSE),"") -> 0 | K10: 1 | L10: USD | M10: =IF(BD.PD[[#This Row],[Mon]]="DOP",1,HLOOKUP(BD.PD[[#This Row],[Mon]],$K$1:$L$2,2,FALSE)) -> 61 | N10: 0 | O10: =BD.PD[[#This Row],[Cant.]]*BD.PD[[#This Row],[ Tasa ]]*BD.PD[[#This Row],[ Precio Und.]] -> 0 | P10: 0 | Q10: =IF(BD.PD[[#This Row],[Liquid. '[%']]]<>0,(BD.PD[[#This Row],[Valor Neto '[DOP']]]*BD.PD[[#This Row],[Liquid. '[%']]])+BD.PD[[#This Row],[Valor Neto '[DOP']]],BD.PD[[#This Row],[Valor Neto '[DOP']]]) -> 0 | R10: =BD.PD[[#This Row],[Ppto. Orden Interna '[DOP']]]/HLOOKUP("USD",$K$1:$L$2,2,FALSE) -> 0 | Z10: =BD.PD[[#This Row],[Av.P1 '[%']]]*BD.PD[[#This Row],[Ppto. Orden Interna '[DOP']]] -> 0 | AC10: =BD.PD[[#This Row],[Av.P2 '[%']]]*BD.PD[[#This Row],[Ppto. Orden Interna '[DOP']]] -> 0 | AF10: =BD.PD[[#This Row],[Av.P3 '[%']]]*BD.PD[[#This Row],[Ppto. Orden Interna '[DOP']]] -> 0 | AM10: =BD.PD[[#This Row],[Pago 3]]+BD.PD[[#This Row],[Pago 2]]+BD.PD[[#This Row],[Pago 1]] -> 0
A11: 1.07 | B11: * | C11: =VLOOKUP(BD.PD[[#This Row],[Pos]],PPto[],3,FALSE) -> 1.07 Permisos | D11: * | E11: =IF(BD.PD[[#This Row],[.]]="*",VLOOKUP(BD.PD[[#This Row],[Pos]],Presupuesto!A:H,7,FALSE),"") -> 0 | K11: 1 | L11: USD | M11: =IF(BD.PD[[#This Row],[Mon]]="DOP",1,HLOOKUP(BD.PD[[#This Row],[Mon]],$K$1:$L$2,2,FALSE)) -> 61 | N11: 0 | O11: =BD.PD[[#This Row],[Cant.]]*BD.PD[[#This Row],[ Tasa ]]*BD.PD[[#This Row],[ Precio Und.]] -> 0 | P11: 0 | Q11: =IF(BD.PD[[#This Row],[Liquid. '[%']]]<>0,(BD.PD[[#This Row],[Valor Neto '[DOP']]]*BD.PD[[#This Row],[Liquid. '[%']]])+BD.PD[[#This Row],[Valor Neto '[DOP']]],BD.PD[[#This Row],[Valor Neto '[DOP']]]) -> 0 | R11: =BD.PD[[#This Row],[Ppto. Orden Interna '[DOP']]]/HLOOKUP("USD",$K$1:$L$2,2,FALSE) -> 0 | Z11: =BD.PD[[#This Row],[Av.P1 '[%']]]*BD.PD[[#This Row],[Ppto. Orden Interna '[DOP']]] -> 0 | AC11: =BD.PD[[#This Row],[Av.P2 '[%']]]*BD.PD[[#This Row],[Ppto. Orden Interna '[DOP']]] -> 0 | AF11: =BD.PD[[#This Row],[Av.P3 '[%']]]*BD.PD[[#This Row],[Ppto. Orden Interna '[DOP']]] -> 0 | AM11: =BD.PD[[#This Row],[Pago 3]]+BD.PD[[#This Row],[Pago 2]]+BD.PD[[#This Row],[Pago 1]] -> 0
A12: 1.08 | B12: * | C12: =VLOOKUP(BD.PD[[#This Row],[Pos]],PPto[],3,FALSE) -> 1.08 Diseño sistema contra incendios | D12: * | E12: =IF(BD.PD[[#This Row],[.]]="*",VLOOKUP(BD.PD[[#This Row],[Pos]],Presupuesto!A:H,7,FALSE),"") -> 0 | K12: 1 | L12: USD | M12: =IF(BD.PD[[#This Row],[Mon]]="DOP",1,HLOOKUP(BD.PD[[#This Row],[Mon]],$K$1:$L$2,2,FALSE)) -> 61 | N12: 0 | O12: =BD.PD[[#This Row],[Cant.]]*BD.PD[[#This Row],[ Tasa ]]*BD.PD[[#This Row],[ Precio Und.]] -> 0 | P12: 0 | Q12: =IF(BD.PD[[#This Row],[Liquid. '[%']]]<>0,(BD.PD[[#This Row],[Valor Neto '[DOP']]]*BD.PD[[#This Row],[Liquid. '[%']]])+BD.PD[[#This Row],[Valor Neto '[DOP']]],BD.PD[[#This Row],[Valor Neto '[DOP']]]) -> 0 | R12: =BD.PD[[#This Row],[Ppto. Orden Interna '[DOP']]]/HLOOKUP("USD",$K$1:$L$2,2,FALSE) -> 0 | Z12: =BD.PD[[#This Row],[Av.P1 '[%']]]*BD.PD[[#This Row],[Ppto. Orden Interna '[DOP']]] -> 0 | AC12: =BD.PD[[#This Row],[Av.P2 '[%']]]*BD.PD[[#This Row],[Ppto. Orden Interna '[DOP']]] -> 0 | AF12: =BD.PD[[#This Row],[Av.P3 '[%']]]*BD.PD[[#This Row],[Ppto. Orden Interna '[DOP']]] -> 0 | AM12: =BD.PD[[#This Row],[Pago 3]]+BD.PD[[#This Row],[Pago 2]]+BD.PD[[#This Row],[Pago 1]] -> 0
A13: 1.09 | B13: * | C13: =VLOOKUP(BD.PD[[#This Row],[Pos]],PPto[],3,FALSE) -> 1.09 Diseño sistema gas | D13: * | E13: =IF(BD.PD[[#This Row],[.]]="*",VLOOKUP(BD.PD[[#This Row],[Pos]],Presupuesto!A:H,7,FALSE),"") -> 0 | K13: 1 | L13: USD | M13: =IF(BD.PD[[#This Row],[Mon]]="DOP",1,HLOOKUP(BD.PD[[#This Row],[Mon]],$K$1:$L$2,2,FALSE)) -> 61 | N13: 0 | O13: =BD.PD[[#This Row],[Cant.]]*BD.PD[[#This Row],[ Tasa ]]*BD.PD[[#This Row],[ Precio Und.]] -> 0 | P13: 0 | Q13: =IF(BD.PD[[#This Row],[Liquid. '[%']]]<>0,(BD.PD[[#This Row],[Valor Neto '[DOP']]]*BD.PD[[#This Row],[Liquid. '[%']]])+BD.PD[[#This Row],[Valor Neto '[DOP']]],BD.PD[[#This Row],[Valor Neto '[DOP']]]) -> 0 | R13: =BD.PD[[#This Row],[Ppto. Orden Interna '[DOP']]]/HLOOKUP("USD",$K$1:$L$2,2,FALSE) -> 0 | Z13: =BD.PD[[#This Row],[Av.P1 '[%']]]*BD.PD[[#This Row],[Ppto. Orden Interna '[DOP']]] -> 0 | AC13: =BD.PD[[#This Row],[Av.P2 '[%']]]*BD.PD[[#This Row],[Ppto. Orden Interna '[DOP']]] -> 0 | AF13: =BD.PD[[#This Row],[Av.P3 '[%']]]*BD.PD[[#This Row],[Ppto. Orden Interna '[DOP']]] -> 0 | AM13: =BD.PD[[#This Row],[Pago 3]]+BD.PD[[#This Row],[Pago 2]]+BD.PD[[#This Row],[Pago 1]] -> 0
A14: 2.01 | B14: * | C14: =VLOOKUP(BD.PD[[#This Row],[Pos]],PPto[],3,FALSE) -> 2.01 Edificación - Obra Civil | D14: * | E14: =IF(BD.PD[[#This Row],[.]]="*",VLOOKUP(BD.PD[[#This Row],[Pos]],Presupuesto!A:H,7,FALSE),"") -> 18449.15 | K14: 1 | L14: USD | M14: =IF(BD.PD[[#This Row],[Mon]]="DOP",1,HLOOKUP(BD.PD[[#This Row],[Mon]],$K$1:$L$2,2,FALSE)) -> 61 | N14: 0 | O14: =BD.PD[[#This Row],[Cant.]]*BD.PD[[#This Row],[ Tasa ]]*BD.PD[[#This Row],[ Precio Und.]] -> 0 | P14: 0 | Q14: =IF(BD.PD[[#This Row],[Liquid. '[%']]]<>0,(BD.PD[[#This Row],[Valor Neto '[DOP']]]*BD.PD[[#This Row],[Liquid. '[%']]])+BD.PD[[#This Row],[Valor Neto '[DOP']]],BD.PD[[#This Row],[Valor Neto '[DOP']]]) -> 0 | R14: =BD.PD[[#This Row],[Ppto. Orden Interna '[DOP']]]/HLOOKUP("USD",$K$1:$L$2,2,FALSE) -> 0 | Z14: =BD.PD[[#This Row],[Av.P1 '[%']]]*BD.PD[[#This Row],[Ppto. Orden Interna '[DOP']]] -> 0 | AC14: =BD.PD[[#This Row],[Av.P2 '[%']]]*BD.PD[[#This Row],[Ppto. Orden Interna '[DOP']]] -> 0 | AF14: =BD.PD[[#This Row],[Av.P3 '[%']]]*BD.PD[[#This Row],[Ppto. Orden Interna '[DOP']]] -> 0 | AM14: =BD.PD[[#This Row],[Pago 3]]+BD.PD[[#This Row],[Pago 2]]+BD.PD[[#This Row],[Pago 1]] -> 0
A15: 2.01 | C15: =VLOOKUP(BD.PD[[#This Row],[Pos]],PPto[],3,FALSE) -> 2.01 Edificación - Obra Civil | D15: OI | E15: =IF(BD.PD[[#This Row],[.]]="*",VLOOKUP(BD.PD[[#This Row],[Pos]],Presupuesto!A:H,7,FALSE),"") | F15: MARAZZI SISTEM S PELTRO NAT 60X60 - SALA VENTAS | K15: 0 | L15: USD | M15: =IF(BD.PD[[#This Row],[Mon]]="DOP",1,HLOOKUP(BD.PD[[#This Row],[Mon]],$K$1:$L$2,2,FALSE)) -> 61 | N15: 33 | O15: =BD.PD[[#This Row],[Cant.]]*BD.PD[[#This Row],[ Tasa ]]*BD.PD[[#This Row],[ Precio Und.]] -> 0 | P15: 0 | Q15: =IF(BD.PD[[#This Row],[Liquid. '[%']]]<>0,(BD.PD[[#This Row],[Valor Neto '[DOP']]]*BD.PD[[#This Row],[Liquid. '[%']]])+BD.PD[[#This Row],[Valor Neto '[DOP']]],BD.PD[[#This Row],[Valor Neto '[DOP']]]) -> 0 | R15: =BD.PD[[#This Row],[Ppto. Orden Interna '[DOP']]]/HLOOKUP("USD",$K$1:$L$2,2,FALSE) -> 0 | S15: HORMIGON PULIDO | Z15: =BD.PD[[#This Row],[Av.P1 '[%']]]*BD.PD[[#This Row],[Ppto. Orden Interna '[DOP']]] -> 0 | AC15: =BD.PD[[#This Row],[Av.P2 '[%']]]*BD.PD[[#This Row],[Ppto. Orden Interna '[DOP']]] -> 0 | AF15: =BD.PD[[#This Row],[Av.P3 '[%']]]*BD.PD[[#This Row],[Ppto. Orden Interna '[DOP']]] -> 0 | AM15: =BD.PD[[#This Row],[Pago 3]]+BD.PD[[#This Row],[Pago 2]]+BD.PD[[#This Row],[Pago 1]] -> 0
A16: 2.01 | C16: =VLOOKUP(BD.PD[[#This Row],[Pos]],PPto[],3,FALSE) -> 2.01 Edificación - Obra Civil | D16: OI | E16: =IF(BD.PD[[#This Row],[.]]="*",VLOOKUP(BD.PD[[#This Row],[Pos]],Presupuesto!A:H,7,FALSE),"") | F16: MARAZZI SISTEM S PELTRO NAT 30X60 - OFICINA | K16: 0 | L16: USD | M16: =IF(BD.PD[[#This Row],[Mon]]="DOP",1,HLOOKUP(BD.PD[[#This Row],[Mon]],$K$1:$L$2,2,FALSE)) -> 61 | N16: 28 | O16: =BD.PD[[#This Row],[Cant.]]*BD.PD[[#This Row],[ Tasa ]]*BD.PD[[#This Row],[ Precio Und.]] -> 0 | P16: 0 | Q16: =IF(BD.PD[[#This Row],[Liquid. '[%']]]<>0,(BD.PD[[#This Row],[Valor Neto '[DOP']]]*BD.PD[[#This Row],[Liquid. '[%']]])+BD.PD[[#This Row],[Valor Neto '[DOP']]],BD.PD[[#This Row],[Valor Neto '[DOP']]]) -> 0 | R16: =BD.PD[[#This Row],[Ppto. Orden Interna '[DOP']]]/HLOOKUP("USD",$K$1:$L$2,2,FALSE) -> 0 | S16: HORMIGON PULIDO | Z16: =BD.PD[[#This Row],[Av.P1 '[%']]]*BD.PD[[#This Row],[Ppto. Orden Interna '[DOP']]] -> 0 | AC16: =BD.PD[[#This Row],[Av.P2 '[%']]]*BD.PD[[#This Row],[Ppto. Orden Interna '[DOP']]] -> 0 | AF16: =BD.PD[[#This Row],[Av.P3 '[%']]]*BD.PD[[#This Row],[Ppto. Orden Interna '[DOP']]] -> 0 | AM16: =BD.PD[[#This Row],[Pago 3]]+BD.PD[[#This Row],[Pago 2]]+BD.PD[[#This Row],[Pago 1]] -> 0
A17: 2.01 | C17: =VLOOKUP(BD.PD[[#This Row],[Pos]],PPto[],3,FALSE) -> 2.01 Edificación - Obra Civil | D17: OI | E17: =IF(BD.PD[[#This Row],[.]]="*",VLOOKUP(BD.PD[[#This Row],[Pos]],Presupuesto!A:H,7,FALSE),"") | F17: MARAZZI SISTEM S GRAFITTE NAT. 60X60 - SALA VENTAS | K17: 0 | L17: USD | M17: =IF(BD.PD[[#This Row],[Mon]]="DOP",1,HLOOKUP(BD.PD[[#This Row],[Mon]],$K$1:$L$2,2,FALSE)) -> 61 | N17: 42.35 | O17: =BD.PD[[#This Row],[Cant.]]*BD.PD[[#This Row],[ Tasa ]]*BD.PD[[#This Row],[ Precio Und.]] -> 0 | P17: 0 | Q17: =IF(BD.PD[[#This Row],[Liquid. '[%']]]<>0,(BD.PD[[#This Row],[Valor Neto '[DOP']]]*BD.PD[[#This Row],[Liquid. '[%']]])+BD.PD[[#This Row],[Valor Neto '[DOP']]],BD.PD[[#This Row],[Valor Neto '[DOP']]]) -> 0 | R17: =BD.PD[[#This Row],[Ppto. Orden Interna '[DOP']]]/HLOOKUP("USD",$K$1:$L$2,2,FALSE) -> 0 | S17: HORMIGON PULIDO | Z17: =BD.PD[[#This Row],[Av.P1 '[%']]]*BD.PD[[#This Row],[Ppto. Orden Interna '[DOP']]] -> 0 | AC17: =BD.PD[[#This Row],[Av.P2 '[%']]]*BD.PD[[#This Row],[Ppto. Orden Interna '[DOP']]] -> 0 | AF17: =BD.PD[[#This Row],[Av.P3 '[%']]]*BD.PD[[#This Row],[Ppto. Orden Interna '[DOP']]] -> 0 | AM17: =BD.PD[[#This Row],[Pago 3]]+BD.PD[[#This Row],[Pago 2]]+BD.PD[[#This Row],[Pago 1]] -> 0
A18: 2.01 | C18: =VLOOKUP(BD.PD[[#This Row],[Pos]],PPto[],3,FALSE) -> 2.01 Edificación - Obra Civil | D18: OI | E18: =IF(BD.PD[[#This Row],[.]]="*",VLOOKUP(BD.PD[[#This Row],[Pos]],Presupuesto!A:H,7,FALSE),"") | F18: MARAZZI REVESTIMIENTO EQUIPE SIN BISELADO 10X40CM LIGHT GREY | G18: Etapa 1 -D/IR | H18: 4512892255 | I18: Real | J18: 25.06.2026 | K18: 31 | L18: USD | M18: =IF(BD.PD[[#This Row],[Mon]]="DOP",1,HLOOKUP(BD.PD[[#This Row],[Mon]],$K$1:$L$2,2,FALSE)) -> 61 | N18: 28.8 | O18: =BD.PD[[#This Row],[Cant.]]*BD.PD[[#This Row],[ Tasa ]]*BD.PD[[#This Row],[ Precio Und.]] -> 54460.8 | P18: 0 | Q18: =IF(BD.PD[[#This Row],[Liquid. '[%']]]<>0,(BD.PD[[#This Row],[Valor Neto '[DOP']]]*BD.PD[[#This Row],[Liquid. '[%']]])+BD.PD[[#This Row],[Valor Neto '[DOP']]],BD.PD[[#This Row],[Valor Neto '[DOP']]]) -> 54460.8 | R18: =BD.PD[[#This Row],[Ppto. Orden Interna '[DOP']]]/HLOOKUP("USD",$K$1:$L$2,2,FALSE) -> 892.8 | S18: ASISTIDO CARNES | U18: NTCO011104 | V18: 801667 | W18: 75322 EQUIPOS Y MATERIALES SG S. A | X18: 20 | Y18: 1 | Z18: =BD.PD[[#This Row],[Av.P1 '[%']]]*BD.PD[[#This Row],[Ppto. Orden Interna '[DOP']]] -> 54460.8 | AC18: =BD.PD[[#This Row],[Av.P2 '[%']]]*BD.PD[[#This Row],[Ppto. Orden Interna '[DOP']]] -> 0 | AF18: =BD.PD[[#This Row],[Av.P3 '[%']]]*BD.PD[[#This Row],[Ppto. Orden Interna '[DOP']]] -> 0 | AM18: =BD.PD[[#This Row],[Pago 3]]+BD.PD[[#This Row],[Pago 2]]+BD.PD[[#This Row],[Pago 1]] -> 54460.8 | AN18: Sirena Compacta | AO18: Sirena Las Terrenas | AP18: MC33 | AQ18: Marrón | AR18: 594 | AS18: Orden Colocada
A19: 2.01 | C19: =VLOOKUP(BD.PD[[#This Row],[Pos]],PPto[],3,FALSE) -> 2.01 Edificación - Obra Civil | D19: OI | E19: =IF(BD.PD[[#This Row],[.]]="*",VLOOKUP(BD.PD[[#This Row],[Pos]],Presupuesto!A:H,7,FALSE),"") | F19: MARAZZI PISO ART ANTHRATICE 60X60CM | G19: Etapa 1 -D/IR | H19: 4512892255 | I19: Real | J19: 25.06.2026 | K19: 156.6 | L19: USD | M19: =IF(BD.PD[[#This Row],[Mon]]="DOP",1,HLOOKUP(BD.PD[[#This Row],[Mon]],$K$1:$L$2,2,FALSE)) -> 61 | N19: 25.45 | O19: =BD.PD[[#This Row],[Cant.]]*BD.PD[[#This Row],[ Tasa ]]*BD.PD[[#This Row],[ Precio Und.]] -> 243113.67 | P19: 0 | Q19: =IF(BD.PD[[#This Row],[Liquid. '[%']]]<>0,(BD.PD[[#This Row],[Valor Neto '[DOP']]]*BD.PD[[#This Row],[Liquid. '[%']]])+BD.PD[[#This Row],[Valor Neto '[DOP']]],BD.PD[[#This Row],[Valor Neto '[DOP']]]) -> 243113.67 | R19: =BD.PD[[#This Row],[Ppto. Orden Interna '[DOP']]]/HLOOKUP("USD",$K$1:$L$2,2,FALSE) -> 3985.47 | S19: PISO BAÑOS CLIENTES | U19: NTCO011104 | V19: 801667 | W19: 75322 EQUIPOS Y MATERIALES SG S. A | X19: 20 | Y19: 1 | Z19: =BD.PD[[#This Row],[Av.P1 '[%']]]*BD.PD[[#This Row],[Ppto. Orden Interna '[DOP']]] -> 243113.67 | AC19: =BD.PD[[#This Row],[Av.P2 '[%']]]*BD.PD[[#This Row],[Ppto. Orden Interna '[DOP']]] -> 0 | AF19: =BD.PD[[#This Row],[Av.P3 '[%']]]*BD.PD[[#This Row],[Ppto. Orden Interna '[DOP']]] -> 0 | AM19: =BD.PD[[#This Row],[Pago 3]]+BD.PD[[#This Row],[Pago 2]]+BD.PD[[#This Row],[Pago 1]] -> 243113.67 | AN19: Sirena Compacta | AO19: Sirena Las Terrenas | AP19: MC33 | AQ19: Marrón | AR19: 594 | AS19: Orden Colocada
A20: 2.01 | C20: =VLOOKUP(BD.PD[[#This Row],[Pos]],PPto[],3,FALSE) -> 2.01 Edificación - Obra Civil | D20: OI | E20: =IF(BD.PD[[#This Row],[.]]="*",VLOOKUP(BD.PD[[#This Row],[Pos]],Presupuesto!A:H,7,FALSE),"") | F20: MARAZZI REVESTIMIENTO ART ANTHARCITE 60X60CM | G20: Etapa 1 -D/IR | H20: 4512892255 | I20: Real | J20: 25.06.2026 | K20: 83.16 | L20: USD | M20: =IF(BD.PD[[#This Row],[Mon]]="DOP",1,HLOOKUP(BD.PD[[#This Row],[Mon]],$K$1:$L$2,2,FALSE)) -> 61 | N20: 25.45 | O20: =BD.PD[[#This Row],[Cant.]]*BD.PD[[#This Row],[ Tasa ]]*BD.PD[[#This Row],[ Precio Und.]] -> 129101.74 | P20: 0 | Q20: =IF(BD.PD[[#This Row],[Liquid. '[%']]]<>0,(BD.PD[[#This Row],[Valor Neto '[DOP']]]*BD.PD[[#This Row],[Liquid. '[%']]])+BD.PD[[#This Row],[Valor Neto '[DOP']]],BD.PD[[#This Row],[Valor Neto '[DOP']]]) -> 129101.74 | R20: =BD.PD[[#This Row],[Ppto. Orden Interna '[DOP']]]/HLOOKUP("USD",$K$1:$L$2,2,FALSE) -> 2116.422 | S20: REVESTIMIENTO PAREDES BAÑOS | U20: NTCO011104 | V20: 801667 | W20: 75322 EQUIPOS Y MATERIALES SG S. A | X20: 20 | Y20: 1 | Z20: =BD.PD[[#This Row],[Av.P1 '[%']]]*BD.PD[[#This Row],[Ppto. Orden Interna '[DOP']]] -> 129101.74 | AC20: =BD.PD[[#This Row],[Av.P2 '[%']]]*BD.PD[[#This Row],[Ppto. Orden Interna '[DOP']]] -> 0 | AF20: =BD.PD[[#This Row],[Av.P3 '[%']]]*BD.PD[[#This Row],[Ppto. Orden Interna '[DOP']]] -> 0 | AM20: =BD.PD[[#This Row],[Pago 3]]+BD.PD[[#This Row],[Pago 2]]+BD.PD[[#This Row],[Pago 1]] -> 129101.74 | AN20: Sirena Compacta | AO20: Sirena Las Terrenas | AP20: MC33 | AQ20: Marrón | AR20: 594 | AS20: Orden Colocada
A21: 2.01 | C21: =VLOOKUP(BD.PD[[#This Row],[Pos]],PPto[],3,FALSE) -> 2.01 Edificación - Obra Civil | D21: OI | E21: =IF(BD.PD[[#This Row],[.]]="*",VLOOKUP(BD.PD[[#This Row],[Pos]],Presupuesto!A:H,7,FALSE),"") | F21: MARAZZI REVESTIMIENTO PINCH WHITE 60X60CM | G21: Etapa 1 -D/IR | H21: 4512892255 | I21: Real | J21: 25.06.2026 | K21: 81 | L21: USD | M21: =IF(BD.PD[[#This Row],[Mon]]="DOP",1,HLOOKUP(BD.PD[[#This Row],[Mon]],$K$1:$L$2,2,FALSE)) -> 61 | N21: 25.45 | O21: =BD.PD[[#This Row],[Cant.]]*BD.PD[[#This Row],[ Tasa ]]*BD.PD[[#This Row],[ Precio Und.]] -> 125748.45 | P21: 0 | Q21: =IF(BD.PD[[#This Row],[Liquid. '[%']]]<>0,(BD.PD[[#This Row],[Valor Neto '[DOP']]]*BD.PD[[#This Row],[Liquid. '[%']]])+BD.PD[[#This Row],[Valor Neto '[DOP']]],BD.PD[[#This Row],[Valor Neto '[DOP']]]) -> 125748.45 | R21: =BD.PD[[#This Row],[Ppto. Orden Interna '[DOP']]]/HLOOKUP("USD",$K$1:$L$2,2,FALSE) -> 2061.45 | S21: REVESTIMIENTO PAREDES BAÑOS | U21: NTCO011104 | V21: 801667 | W21: 75322 EQUIPOS Y MATERIALES SG S. A | X21: 20 | Y21: 1 | Z21: =BD.PD[[#This Row],[Av.P1 '[%']]]*BD.PD[[#This Row],[Ppto. Orden Interna '[DOP']]] -> 125748.45 | AC21: =BD.PD[[#This Row],[Av.P2 '[%']]]*BD.PD[[#This Row],[Ppto. Orden Interna '[DOP']]] -> 0 | AF21: =BD.PD[[#This Row],[Av.P3 '[%']]]*BD.PD[[#This Row],[Ppto. Orden Interna '[DOP']]] -> 0 | AM21: =BD.PD[[#This Row],[Pago 3]]+BD.PD[[#This Row],[Pago 2]]+BD.PD[[#This Row],[Pago 1]] -> 125748.45 | AN21: Sirena Compacta | AO21: Sirena Las Terrenas | AP21: MC33 | AQ21: Marrón | AR21: 594 | AS21: Orden Colocada
A22: 2.01 | C22: =VLOOKUP(BD.PD[[#This Row],[Pos]],PPto[],3,FALSE) -> 2.01 Edificación - Obra Civil | D22: OI | E22: =IF(BD.PD[[#This Row],[.]]="*",VLOOKUP(BD.PD[[#This Row],[Pos]],Presupuesto!A:H,7,FALSE),"") | F22: MARAZZI PROGRESS ANTRACITE 60X60CM | G22: Etapa 1 -D/IR | H22: 4512892255 | I22: Real | J22: 25.06.2026 | K22: 57.24 | L22: USD | M22: =IF(BD.PD[[#This Row],[Mon]]="DOP",1,HLOOKUP(BD.PD[[#This Row],[Mon]],$K$1:$L$2,2,FALSE)) -> 61 | N22: 25.45 | O22: =BD.PD[[#This Row],[Cant.]]*BD.PD[[#This Row],[ Tasa ]]*BD.PD[[#This Row],[ Precio Und.]] -> 88862.238 | P22: 0 | Q22: =IF(BD.PD[[#This Row],[Liquid. '[%']]]<>0,(BD.PD[[#This Row],[Valor Neto '[DOP']]]*BD.PD[[#This Row],[Liquid. '[%']]])+BD.PD[[#This Row],[Valor Neto '[DOP']]],BD.PD[[#This Row],[Valor Neto '[DOP']]]) -> 88862.238 | R22: =BD.PD[[#This Row],[Ppto. Orden Interna '[DOP']]]/HLOOKUP("USD",$K$1:$L$2,2,FALSE) -> 1456.758 | S22: PISO BAÑOS CLIENTES GALERIA COMERCIAL | U22: NTCO011104 | V22: 801667 | W22: 75322 EQUIPOS Y MATERIALES SG S. A | X22: 20 | Y22: 1 | Z22: =BD.PD[[#This Row],[Av.P1 '[%']]]*BD.PD[[#This Row],[Ppto. Orden Interna '[DOP']]] -> 88862.238 | AC22: =BD.PD[[#This Row],[Av.P2 '[%']]]*BD.PD[[#This Row],[Ppto. Orden Interna '[DOP']]] -> 0 | AF22: =BD.PD[[#This Row],[Av.P3 '[%']]]*BD.PD[[#This Row],[Ppto. Orden Interna '[DOP']]] -> 0 | AM22: =BD.PD[[#This Row],[Pago 3]]+BD.PD[[#This Row],[Pago 2]]+BD.PD[[#This Row],[Pago 1]] -> 88862.238 | AN22: Sirena Compacta | AO22: Sirena Las Terrenas | AP22: MC33 | AQ22: Marrón | AR22: 594 | AS22: Orden Colocada
A23: 2.01 | C23: =VLOOKUP(BD.PD[[#This Row],[Pos]],PPto[],3,FALSE) -> 2.01 Edificación - Obra Civil | D23: OI | E23: =IF(BD.PD[[#This Row],[.]]="*",VLOOKUP(BD.PD[[#This Row],[Pos]],Presupuesto!A:H,7,FALSE),"") | F23: MARAZZI MATERIKA OFF WHITE SPATULA 3D | G23: Etapa 1 -D/IR | H23: 4512892255 | I23: Real | J23: 25.06.2026 | K23: 49.68 | L23: USD | M23: =IF(BD.PD[[#This Row],[Mon]]="DOP",1,HLOOKUP(BD.PD[[#This Row],[Mon]],$K$1:$L$2,2,FALSE)) -> 61 | N23: 34 | O23: =BD.PD[[#This Row],[Cant.]]*BD.PD[[#This Row],[ Tasa ]]*BD.PD[[#This Row],[ Precio Und.]] -> 103036.32 | P23: 0 | Q23: =IF(BD.PD[[#This Row],[Liquid. '[%']]]<>0,(BD.PD[[#This Row],[Valor Neto '[DOP']]]*BD.PD[[#This Row],[Liquid. '[%']]])+BD.PD[[#This Row],[Valor Neto '[DOP']]],BD.PD[[#This Row],[Valor Neto '[DOP']]]) -> 103036.32 | R23: =BD.PD[[#This Row],[Ppto. Orden Interna '[DOP']]]/HLOOKUP("USD",$K$1:$L$2,2,FALSE) -> 1689.12 | S23: REVESTIMIENTO PARED ESPEJO BAÑOS CLIENTES GALERIA COMERCIAL | U23: NTCO011104 | V23: 801667 | W23: 75322 EQUIPOS Y MATERIALES SG S. A | X23: 20 | Y23: 1 | Z23: =BD.PD[[#This Row],[Av.P1 '[%']]]*BD.PD[[#This Row],[Ppto. Orden Interna '[DOP']]] -> 103036.32 | AC23: =BD.PD[[#This Row],[Av.P2 '[%']]]*BD.PD[[#This Row],[Ppto. Orden Interna '[DOP']]] -> 0 | AF23: =BD.PD[[#This Row],[Av.P3 '[%']]]*BD.PD[[#This Row],[Ppto. Orden Interna '[DOP']]] -> 0 | AM23: =BD.PD[[#This Row],[Pago 3]]+BD.PD[[#This Row],[Pago 2]]+BD.PD[[#This Row],[Pago 1]] -> 103036.32 | AN23: Sirena Compacta | AO23: Sirena Las Terrenas | AP23: MC33 | AQ23: Marrón | AR23: 594 | AS23: Orden Colocada
A24: 2.01 | C24: =VLOOKUP(BD.PD[[#This Row],[Pos]],PPto[],3,FALSE) -> 2.01 Edificación - Obra Civil | D24: OI | E24: =IF(BD.PD[[#This Row],[.]]="*",VLOOKUP(BD.PD[[#This Row],[Pos]],Presupuesto!A:H,7,FALSE),"") | F24: RAGNO CONCEPT GRIGIO | G24: Etapa 1 -D/IR | H24: 4512892255 | I24: Real | J24: 25.06.2026 | K24: 90.72 | L24: USD | M24: =IF(BD.PD[[#This Row],[Mon]]="DOP",1,HLOOKUP(BD.PD[[#This Row],[Mon]],$K$1:$L$2,2,FALSE)) -> 61 | N24: 26.2 | O24: =BD.PD[[#This Row],[Cant.]]*BD.PD[[#This Row],[ Tasa ]]*BD.PD[[#This Row],[ Precio Und.]] -> 144988.7 | P24: 0 | Q24: =IF(BD.PD[[#This Row],[Liquid. '[%']]]<>0,(BD.PD[[#This Row],[Valor Neto '[DOP']]]*BD.PD[[#This Row],[Liquid. '[%']]])+BD.PD[[#This Row],[Valor Neto '[DOP']]],BD.PD[[#This Row],[Valor Neto '[DOP']]]) -> 144988.7 | R24: =BD.PD[[#This Row],[Ppto. Orden Interna '[DOP']]]/HLOOKUP("USD",$K$1:$L$2,2,FALSE) -> 2376.864 | S24: PISO BAÑOS CLIENTES GALERIA COMERCIAL | U24: NTCO011104 | V24: 801667 | W24: 75322 EQUIPOS Y MATERIALES SG S. A | X24: 20 | Y24: 1 | Z24: =BD.PD[[#This Row],[Av.P1 '[%']]]*BD.PD[[#This Row],[Ppto. Orden Interna '[DOP']]] -> 144988.7 | AC24: =BD.PD[[#This Row],[Av.P2 '[%']]]*BD.PD[[#This Row],[Ppto. Orden Interna '[DOP']]] -> 0 | AF24: =BD.PD[[#This Row],[Av.P3 '[%']]]*BD.PD[[#This Row],[Ppto. Orden Interna '[DOP']]] -> 0 | AM24: =BD.PD[[#This Row],[Pago 3]]+BD.PD[[#This Row],[Pago 2]]+BD.PD[[#This Row],[Pago 1]] -> 144988.7 | AN24: Sirena Compacta | AO24: Sirena Las Terrenas | AP24: MC33 | AQ24: Marrón | AR24: 594 | AS24: Orden Colocada
A25: 2.01 | C25: =VLOOKUP(BD.PD[[#This Row],[Pos]],PPto[],3,FALSE) -> 2.01 Edificación - Obra Civil | D25: OI | E25: =IF(BD.PD[[#This Row],[.]]="*",VLOOKUP(BD.PD[[#This Row],[Pos]],Presupuesto!A:H,7,FALSE),"") | F25: SUM Y COL. REVEST. ACM ISLA | G25: Etapa 2 -D/IR | H25: 4513048855 | J25: 03.08.2026 | K25: 0 | L25: DOP | M25: =IF(BD.PD[[#This Row],[Mon]]="DOP",1,HLOOKUP(BD.PD[[#This Row],[Mon]],$K$1:$L$2,2,FALSE)) -> 1 | N25: 1715871.4 | O25: =BD.PD[[#This Row],[Cant.]]*BD.PD[[#This Row],[ Tasa ]]*BD.PD[[#This Row],[ Precio Und.]] -> 0 | P25: 0 | Q25: =IF(BD.PD[[#This Row],[Liquid. '[%']]]<>0,(BD.PD[[#This Row],[Valor Neto '[DOP']]]*BD.PD[[#This Row],[Liquid. '[%']]])+BD.PD[[#This Row],[Valor Neto '[DOP']]],BD.PD[[#This Row],[Valor Neto '[DOP']]]) -> 0 | R25: =BD.PD[[#This Row],[Ppto. Orden Interna '[DOP']]]/HLOOKUP("USD",$K$1:$L$2,2,FALSE) -> 0 | S25: 76815 LIKECORP SRL | U25: NTCO011104 | V25: 801667 | W25: 76815 LIKECORP SRL | X25: 20 | Y25: 0.6 | Z25: =BD.PD[[#This Row],[Av.P1 '[%']]]*BD.PD[[#This Row],[Ppto. Orden Interna '[DOP']]] -> 0 | AA25: 21 | AB25: 0.4 | AC25: =BD.PD[[#This Row],[Av.P2 '[%']]]*BD.PD[[#This Row],[Ppto. Orden Interna '[DOP']]] -> 0 | AF25: =BD.PD[[#This Row],[Av.P3 '[%']]]*BD.PD[[#This Row],[Ppto. Orden Interna '[DOP']]] -> 0 | AM25: =BD.PD[[#This Row],[Pago 3]]+BD.PD[[#This Row],[Pago 2]]+BD.PD[[#This Row],[Pago 1]] -> 0
A26: 2.01 | C26: =VLOOKUP(BD.PD[[#This Row],[Pos]],PPto[],3,FALSE) -> 2.01 Edificación - Obra Civil | D26: OI | E26: =IF(BD.PD[[#This Row],[.]]="*",VLOOKUP(BD.PD[[#This Row],[Pos]],Presupuesto!A:H,7,FALSE),"") | F26: SUM Y COL. REVEST. ACM ISLA | G26: Etapa 2 -D/IR | H26: 4513048855 | J26: 03.08.2026 | K26: 0 | L26: DOP | M26: =IF(BD.PD[[#This Row],[Mon]]="DOP",1,HLOOKUP(BD.PD[[#This Row],[Mon]],$K$1:$L$2,2,FALSE)) -> 1 | N26: 374739.78 | O26: =BD.PD[[#This Row],[Cant.]]*BD.PD[[#This Row],[ Tasa ]]*BD.PD[[#This Row],[ Precio Und.]] -> 0 | P26: 0 | Q26: =IF(BD.PD[[#This Row],[Liquid. '[%']]]<>0,(BD.PD[[#This Row],[Valor Neto '[DOP']]]*BD.PD[[#This Row],[Liquid. '[%']]])+BD.PD[[#This Row],[Valor Neto '[DOP']]],BD.PD[[#This Row],[Valor Neto '[DOP']]]) -> 0 | R26: =BD.PD[[#This Row],[Ppto. Orden Interna '[DOP']]]/HLOOKUP("USD",$K$1:$L$2,2,FALSE) -> 0 | S26: 76815 LIKECORP SRL | U26: NTCO011104 | V26: 801667 | W26: 76815 LIKECORP SRL | X26: 20 | Y26: 0.6 | Z26: =BD.PD[[#This Row],[Av.P1 '[%']]]*BD.PD[[#This Row],[Ppto. Orden Interna '[DOP']]] -> 0 | AA26: 21 | AB26: 0.4 | AC26: =BD.PD[[#This Row],[Av.P2 '[%']]]*BD.PD[[#This Row],[Ppto. Orden Interna '[DOP']]] -> 0 | AF26: =BD.PD[[#This Row],[Av.P3 '[%']]]*BD.PD[[#This Row],[Ppto. Orden Interna '[DOP']]] -> 0 | AM26: =BD.PD[[#This Row],[Pago 3]]+BD.PD[[#This Row],[Pago 2]]+BD.PD[[#This Row],[Pago 1]] -> 0
